Workbook

Sheet Base
A1: Start Date | B1: 43646 | M1: Start Date | N1: 43646 | AW1: =+AVERAGE(AV7:AV2000) -> 7.5234393 | AX1: =+_xlfn.STDEV.S(AV7:AV2000) -> 3.2215582
A2: End Date | M2: End Date
B4: YPFD AR Equity | N4: PAMP AR Equity | Y4: COME AR Equity | AJ4: TGSU2 AR Equity
A5: Dates | B5: CURRENT_EV_TO_T12M_EBITDA | C5: RETURN_ON_INV_CAPITAL | D5: ROC_WACC_RATIO | E5: TOT_DEBT_TO_TOT_CAP | F5: NET_DEBT_TO_EBITDA | G5: TOTAL_PAYOUT_RATIO | H5: EBITDA_MARGIN | I5: TRAIL_12M_OPER_MARGIN | J5: PX_LAST | K5: CUR_MKT_CAP | M5: Dates | N5: CURRENT_EV_TO_T12M_EBITDA | O5: RETURN_ON_INV_CAPITAL | P5: ROC_WACC_RATIO | Q5: TOT_DEBT_TO_TOT_CAP | R5: NET_DEBT_TO_EBITDA | S5: TOTAL_PAYOUT_RATIO | T5: EBITDA_MARGIN | U5: TRAIL_12M_OPER_MARGIN | V5: PX_LAST | W5: CUR_MKT_CAP | Y5: CURRENT_EV_TO_T12M_EBITDA | Z5: RETURN_ON_INV_CAPITAL | AA5: ROC_WACC_RATIO | AB5: TOT_DEBT_TO_TOT_CAP | AC5: NET_DEBT_TO_EBITDA | AD5: TOTAL_PAYOUT_RATIO | AE5: EBITDA_MARGIN | AF5: TRAIL_12M_OPER_MARGIN | AG5: PX_LAST | AH5: CUR_MKT_CAP | AJ5: CURRENT_EV_TO_T12M_EBITDA | AK5: RETURN_ON_INV_CAPITAL | AL5: ROC_WACC_RATIO | AM5: TOT_DEBT_TO_TOT_CAP | AN5: NET_DEBT_TO_EBITDA | AO5: TOTAL_PAYOUT_RATIO | AP5: EBITDA_MARGIN | AQ5: TRAIL_12M_OPER_MARGIN | AR5: PX_LAST | AS5: CUR_MKT_CAP
A6: =_xll.BDH(B$4,B$5:K$5,$B1,$B2,"Dir=V","Per=CW","Days=A","Dts=S","cols=11;rows=380") -> 43651 | B6: 4.195 | C6: 2.5756 | D6: 0.9766 | E6: 51.3139 | F6: 2.2602 | G6: #N/A N/A | H6: 28.122 | I6: 7.61 | J6: 76.105 | K6: 299330.7 | M6: =_xll.BDH(N$4,N$5:W$5,$B1,$B2,"Dir=V","Per=CW","Days=A","Dts=S","cols=11;rows=380") -> 43651 | N6: 3.6787 | O6: 22.1402 | P6: 1.2657 | Q6: 44.1192 | R6: 1.379 | S6: #N/A N/A | T6: 34.2185 | U6: 24.5123 | V6: 56.95 | W6: 106749.05 | Y6: =_xll.BDH(Y$4,Y$5:AH$5,$B1,$B2,"Dir=V","Per=CW","Days=A","Dts=H","cols=10;rows=380") -> 1.9589 | Z6: 39.2209 | AA6: 2.4212 | AB6: 5.9088 | AC6: 0.0882 | AD6: #N/A N/A | AE6: 22.8938 | AF6: 17.7275 | AG6: 0.563 | AH6: 7921.5494 | AJ6: =_xll.BDH(AJ$4,AJ$5:AS$5,$B1,$B2,"Dir=V","Per=CW","Days=A","Dts=H","cols=10;rows=380") -> 3.8987 | AK6: 48.6061 | AL6: 2.1113 | AM6: 38.9348 | AN6: 0.4827 | AO6: 195.1108 | AP6: 49.3598 | AQ6: 42.2735 | AR6: 114.514 | AS6: 98795.488 | AV6: EV/EBITDA Sectorial | AW6: Z Score | AX6: Q90 | AY6: Q75 | AZ6: Q50 | BA6: Q25 | BB6: Q10
A7: 43658 | B7: 4.1974 | C7: 2.5756 | D7: 0.9766 | E7: 51.3139 | F7: 2.2602 | G7: #N/A N/A | H7: 28.122 | I7: 7.61 | J7: 76.2 | K7: 299704.35 | M7: 43658 | N7: 3.7868 | O7: 22.1402 | P7: 1.2657 | Q7: 44.1192 | R7: 1.379 | S7: #N/A N/A | T7: 34.2185 | U7: 24.5123 | V7: 59.6 | W7: 111716.3 | Y7: 1.989 | Z7: 39.2209 | AA7: 2.4212 | AB7: 5.9088 | AC7: 0.0882 | AD7: #N/A N/A | AE7: 22.8938 | AF7: 17.7275 | AG7: 0.572 | AH7: 8048.9055 | AJ7: 4.2133 | AK7: 48.6061 | AL7: 2.1113 | AM7: 38.9348 | AN7: 0.4827 | AO7: 195.1108 | AP7: 49.3598 | AQ7: 42.2735 | AR7: 125.059 | AS7: 107892.46 | AU7: =+A7 -> 43658 | AV7: =+(Y7*AH7+N7*W7+B7*K7+AJ7*AS7)/(K7+W7+AH7) -> 5.1293803 | AW7: =+(AV7-$AW$1)/$AX$1 -> -0.74313696
A8: 43665 | B8: 4.1292 | C8: 2.5756 | D8: 0.9766 | E8: 51.3139 | F8: 2.2602 | G8: #N/A N/A | H8: 28.122 | I8: 7.61 | J8: 73.48 | K8: 289006.24 | M8: 43665 | N8: 3.6114 | O8: 22.1402 | P8: 1.2657 | Q8: 44.1192 | R8: 1.379 | S8: #N/A N/A | T8: 34.2185 | U8: 24.5123 | V8: 56.6 | W8: 106093 | Y8: 1.8386 | Z8: 39.2209 | AA8: 2.4212 | AB8: 5.9088 | AC8: 0.0882 | AD8: #N/A N/A | AE8: 22.8938 | AF8: 17.7275 | AG8: 0.527 | AH8: 7412.125 | AJ8: 4.0388 | AK8: 48.6061 | AL8: 2.1113 | AM8: 38.9348 | AN8: 0.4827 | AO8: 195.1108 | AP8: 49.3598 | AQ8: 42.2735 | AR8: 119.211 | AS8: 102847.41 | AU8: =+A8 -> 43665 | AV8: =+(Y8*AH8+N8*W8+B8*K8+AJ8*AS8)/(K8+W8+AH8) -> 4.98251 | AW8: =+(AV8-$AW$1)/$AX$1 -> -0.78872681
A9: 43672 | B9: 4.1242 | C9: 2.5756 | D9: 0.9766 | E9: 51.3139 | F9: 2.2602 | G9: #N/A N/A | H9: 28.122 | I9: 7.61 | J9: 73.28 | K9: 288219.61 | M9: 43672 | N9: 3.586 | O9: 22.1402 | P9: 1.2657 | Q9: 44.1192 | R9: 1.379 | S9: #N/A N/A | T9: 34.2185 | U9: 24.5123 | V9: 58 | W9: 108717.21 | Y9: 1.8206 | Z9: 39.2209 | AA9: 2.4212 | AB9: 5.9088 | AC9: 0.0882 | AD9: #N/A N/A | AE9: 22.8938 | AF9: 17.7275 | AG9: 0.521 | AH9: 7335.7114 | AJ9: 4.146 | AK9: 48.6061 | AL9: 2.1113 | AM9: 38.9348 | AN9: 0.4827 | AO9: 195.1108 | AP9: 49.3598 | AQ9: 42.2735 | AR9: 122.802 | AS9: 105945.95 | AU9: =+A9 -> 43672 | AV9: =+(Y9*AH9+N9*W9+B9*K9+AJ9*AS9)/(K9+W9+AH9) -> 5.0241913 | AW9: =+(AV9-$AW$1)/$AX$1 -> -0.77578858
A10: 43679 | B10: 4.0745 | C10: 2.5756 | D10: 0.9766 | E10: 51.3139 | F10: 2.2602 | G10: #N/A N/A | H10: 28.122 | I10: 7.61 | J10: 71.295 | K10: 280412.36 | M10: 43679 | N10: 3.4672 | O10: 22.1402 | P10: 1.2657 | Q10: 44.1192 | R10: 1.379 | S10: #N/A N/A | T10: 34.2185 | U10: 24.5123 | V10: 57.65 | W10: 108061.15 | Y10: 1.983 | Z10: 39.2209 | AA10: 2.4212 | AB10: 5.9088 | AC10: 0.0882 | AD10: #N/A N/A | AE10: 22.8938 | AF10: 17.7275 | AG10: 0.57 | AH10: 8023.4343 | AJ10: 4.1405 | AK10: 48.6061 | AL10: 2.1113 | AM10: 38.9348 | AN10: 0.4827 | AO10: 195.1108 | AP10: 49.3598 | AQ10: 42.2735 | AR10: 122.618 | AS10: 105787.05 | AU10: =+A10 -> 43679 | AV10: =+(Y10*AH10+N10*W10+B10*K10+AJ10*AS10)/(K10+W10+AH10) -> 4.9713662 | AW10: =+(AV10-$AW$1)/$AX$1 -> -0.79218594
A11: 43686 | B11: 4.1924 | C11: 2.5756 | D11: 0.9766 | E11: 51.3139 | F11: 2.2602 | G11: #N/A N/A | H11: 28.122 | I11: 7.61 | J11: 76 | K11: 298917.72 | M11: 43686 | N11: 3.6008 | O11: 22.1402 | P11: 1.2657 | Q11: 44.1192 | R11: 1.379 | S11: #N/A N/A | T11: 34.2185 | U11: 24.5123 | V11: 63.5 | W11: 119026.6 | Y11: 1.1831 | Z11: 39.2209 | AA11: 2.4212 | AB11: 5.9088 | AC11: 0.0882 | AD11: #N/A N/A | AE11: 22.8938 | AF11: 17.7275 | AG11: 0.56 | AH11: 4635.762 | AJ11: 4.4152 | AK11: 48.6061 | AL11: 2.1113 | AM11: 38.9348 | AN11: 0.4827 | AO11: 195.1108 | AP11: 49.3598 | AQ11: 42.2735 | AR11: 131.827 | AS11: 113732 | AU11: =+A11 -> 43686 | AV11: =+(Y11*AH11+N11*W11+B11*K11+AJ11*AS11)/(K11+W11+AH11) -> 5.1810481 | AW11: =+(AV11-$AW$1)/$AX$1 -> -0.72709884
A12: 43693 | B12: 3.792 | C12: 2.5756 | D12: 0.9766 | E12: 51.3139 | F12: 2.2602 | G12: #N/A N/A | H12: 28.122 | I12: 7.61 | J12: 60.02 | K12: 236066.34 | M12: 43693 | N12: 2.281 | O12: 22.1402 | P12: 1.2657 | Q12: 44.1192 | R12: 1.379 | S12: #N/A N/A | T12: 34.2185 | U12: 24.5123 | V12: 39.55 | W12: 74133.888 | Y12: 0.9184 | Z12: 39.2209 | AA12: 2.4212 | AB12: 5.9088 | AC12: 0.0882 | AD12: #N/A N/A | AE12: 22.8938 | AF12: 17.7275 | AG12: 0.425 | AH12: 3515.0284 | AJ12: 3.4771 | AK12: 48.6061 | AL12: 2.1113 | AM12: 38.9348 | AN12: 0.4827 | AO12: 195.1108 | AP12: 49.3598 | AQ12: 42.2735 | AR12: 100.378 | AS12: 86599.985 | AU12: =+A12 -> 43693 | AV12: =+(Y12*AH12+N12*W12+B12*K12+AJ12*AS12)/(K12+W12+AH12) -> 4.3625802 | AW12: =+(AV12-$AW$1)/$AX$1 -> -0.98115847
A13: 43700 | B13: 3.629 | C13: 2.5756 | D13: 0.9766 | E13: 51.3139 | F13: 2.2602 | G13: #N/A N/A | H13: 28.122 | I13: 7.61 | J13: 53.515 | K13: 210481.34 | M13: 43700 | N13: 2.2128 | O13: 22.1402 | P13: 1.2657 | Q13: 44.1192 | R13: 1.379 | S13: #N/A N/A | T13: 34.2185 | U13: 24.5123 | V13: 35.35 | W13: 66261.262 | Y13: 0.8403 | Z13: 39.2209 | AA13: 2.4212 | AB13: 5.9088 | AC13: 0.0882 | AD13: #N/A N/A | AE13: 22.8938 | AF13: 17.7275 | AG13: 0.385 | AH13: 3183.9025 | AJ13: 3.1763 | AK13: 48.6061 | AL13: 2.1113 | AM13: 38.9348 | AN13: 0.4827 | AO13: 195.1108 | AP13: 49.3598 | AQ13: 42.2735 | AR13: 90.295 | AS13: 77900.262 | AU13: =+A13 -> 43700 | AV13: =+(Y13*AH13+N13*W13+B13*K13+AJ13*AS13)/(K13+W13+AH13) -> 4.1459802 | AW13: =+(AV13-$AW$1)/$AX$1 -> -1.048393
A14: 43707 | B14: 3.6753 | C14: 2.5756 | D14: 0.9766 | E14: 51.3139 | F14: 2.2602 | G14: #N/A N/A | H14: 28.122 | I14: 7.61 | J14: 55.365 | K14: 217757.63 | M14: 43707 | N14: 2.0099 | O14: 22.1402 | P14: 1.2657 | Q14: 44.1192 | R14: 1.379 | S14: #N/A N/A | T14: 34.2185 | U14: 24.5123 | V14: 32.6 | W14: 61106.567 | Y14: 0.7681 | Z14: 39.2209 | AA14: 2.4212 | AB14: 5.9088 | AC14: 0.0882 | AD14: #N/A N/A | AE14: 22.8938 | AF14: 17.7275 | AG14: 0.348 | AH14: 2878.2479 | AJ14: 3.0774 | AK14: 48.6061 | AL14: 2.1113 | AM14: 38.9348 | AN14: 0.4827 | AO14: 195.1108 | AP14: 49.3598 | AQ14: 42.2735 | AR14: 86.979 | AS14: 75040.079 | AU14: =+A14 -> 43707 | AV14: =+(Y14*AH14+N14*W14+B14*K14+AJ14*AS14)/(K14+W14+AH14) -> 4.1040385 | AW14: =+(AV14-$AW$1)/$AX$1 -> -1.0614121
A15: 43714 | B15: 3.8123 | C15: 2.5756 | D15: 0.9766 | E15: 51.3139 | F15: 2.2602 | G15: #N/A N/A | H15: 28.122 | I15: 7.61 | J15: 60.83 | K15: 239252.17 | M15: 43714 | N15: 2.2865 | O15: 22.1402 | P15: 1.2657 | Q15: 44.1192 | R15: 1.379 | S15: #N/A N/A | T15: 34.2185 | U15: 24.5123 | V15: 39.2 | W15: 73477.836 | Y15: 0.8523 | Z15: 39.2209 | AA15: 2.4212 | AB15: 5.9088 | AC15: 0.0882 | AD15: #N/A N/A | AE15: 22.8938 | AF15: 17.7275 | AG15: 0.391 | AH15: 3234.8449 | AJ15: 3.3274 | AK15: 48.6061 | AL15: 2.1113 | AM15: 38.9348 | AN15: 0.4827 | AO15: 195.1108 | AP15: 49.3598 | AQ15: 42.2735 | AR15: 95.36 | AS15: 82269.986 | AU15: =+A15 -> 43714 | AV15: =+(Y15*AH15+N15*W15+B15*K15+AJ15*AS15)/(K15+W15+AH15) -> 4.2935482 | AW15: =+(AV15-$AW$1)/$AX$1 -> -1.0025866
A16: 43721 | B16: 3.8625 | C16: 2.5756 | D16: 0.9766 | E16: 51.3139 | F16: 2.2602 | G16: #N/A N/A | H16: 28.122 | I16: 7.61 | J16: 62.835 | K16: 247138.09 | M16: 43721 | N16: 2.3811 | O16: 22.1402 | P16: 1.2657 | Q16: 44.1192 | R16: 1.379 | S16: #N/A N/A | T16: 34.2185 | U16: 24.5123 | V16: 43.05 | W16: 80694.409 | Y16: 1.0267 | Z16: 39.2209 | AA16: 2.4212 | AB16: 5.9088 | AC16: 0.0882 | AD16: #N/A N/A | AE16: 22.8938 | AF16: 17.7275 | AG16: 0.48 | AH16: 3973.5103 | AJ16: 3.5636 | AK16: 48.6061 | AL16: 2.1113 | AM16: 38.9348 | AN16: 0.4827 | AO16: 195.1108 | AP16: 49.3598 | AQ16: 42.2735 | AR16: 103.279 | AS16: 89102.645 | AU16: =+A16 -> 43721 | AV16: =+(Y16*AH16+N16*W16+B16*K16+AJ16*AS16)/(K16+W16+AH16) -> 4.4252306 | AW16: =+(AV16-$AW$1)/$AX$1 -> -0.96171123
A17: 43728 | B17: 3.8795 | C17: 2.5756 | D17: 0.9766 | E17: 51.3139 | F17: 2.2602 | G17: #N/A N/A | H17: 28.122 | I17: 7.61 | J17: 63.515 | K17: 249812.62 | M17: 43728 | N17: 2.3848 | O17: 22.1402 | P17: 1.2657 | Q17: 44.1192 | R17: 1.379 | S17: #N/A N/A | T17: 34.2185 | U17: 24.5123 | V17: 44.05 | W17: 82568.843 | Y17: 1.1289 | Z17: 39.2209 | AA17: 2.4212 | AB17: 5.9088 | AC17: 0.0882 | AD17: #N/A N/A | AE17: 22.8938 | AF17: 17.7275 | AG17: 0.532 | AH17: 4406.5211 | AJ17: 3.6968 | AK17: 48.6061 | AL17: 2.1113 | AM17: 38.9348 | AN17: 0.4827 | AO17: 195.1108 | AP17: 49.3598 | AQ17: 42.2735 | AR17: 107.746 | AS17: 92955.948 | AU17: =+A17 -> 43728 | AV17: =+(Y17*AH17+N17*W17+B17*K17+AJ17*AS17)/(K17+W17+AH17) -> 4.497406 | AW17: =+(AV17-$AW$1)/$AX$1 -> -0.93930736
A18: 43735 | B18: 3.7967 | C18: 2.5756 | D18: 0.9766 | E18: 51.3139 | F18: 2.2602 | G18: #N/A N/A | H18: 28.122 | I18: 7.61 | J18: 60.21 | K18: 236813.63 | M18: 43735 | N18: 2.3167 | O18: 22.1402 | P18: 1.2657 | Q18: 44.1192 | R18: 1.379 | S18: #N/A N/A | T18: 34.2185 | U18: 24.5123 | V18: 42.55 | W18: 79757.191 | Y18: 1.0508 | Z18: 39.2209 | AA18: 2.4212 | AB18: 5.9088 | AC18: 0.0882 | AD18: #N/A N/A | AE18: 22.8938 | AF18: 17.7275 | AG18: 0.492 | AH18: 4075.3952 | AJ18: 3.4729 | AK18: 48.6061 | AL18: 2.1113 | AM18: 38.9348 | AN18: 0.4827 | AO18: 195.1108 | AP18: 49.3598 | AQ18: 42.2735 | AR18: 100.24 | AS18: 86480.811 | AU18: =+A18 -> 43735 | AV18: =+(Y18*AH18+N18*W18+B18*K18+AJ18*AS18)/(K18+W18+AH18) -> 4.3303347 | AW18: =+(AV18-$AW$1)/$AX$1 -> -0.99116777
... A44: 43917 | B44: 4.7448 | C44: -1.2175 | D44: -0.3094 | E44: 51.779 | F44: 3.7315 | G44: #N/A N/A | H44: 20.3015 | I44: -3.0964 | J44: 34.08 | K44: 134041 | M44: 43917 | N44: 2.3908 | O44: 14.9734 | P44: 0.7909 | Q44: 44.6986 | R44: 1.5668 | S44: #N/A N/A | T44: 32.5224 | U44: 23.4287 | V44: 35.45 | W44: 56588.417 | Y44: 2.6568 | Z44: 4.5961 | AA44: 0.523 | AB44: 11.6861 | AC44: 0.778 | AD44: #N/A N/A | AE44: 8.2242 | AF44: 5.6235 | AG44: 0.385 | AH44: 3183.9025 | AJ44: 2.8966 | AK44: 20.1847 | AL44: 1.0202 | AM44: 41.122 | AN44: 1.0149 | AO44: 195.1108 | AP44: 48.5151 | AQ44: 40.5247 | AR44: 69.393 | AS44: 57481.734 | AU44: =+A44 -> 43917 | AV44: =+(Y44*AH44+N44*W44+B44*K44+AJ44*AS44)/(K44+W44+AH44) -> 4.8822749 | AW44: =+(AV44-$AW$1)/$AX$1 -> -0.81984067
A45: 43924 | B45: 4.4534 | C45: 0.4011 | D45: -0.253 | E45: 51.3173 | F45: 3.4632 | G45: 0 | H45: 22.2103 | I45: -2.3319 | J45: 38.835 | K45: 152743.02 | M45: 43924 | N45: 3.0239 | O45: 11.8338 | P45: 1.0633 | Q45: 42.9396 | R45: 1.7733 | S45: #N/A N/A | T45: 33.3065 | U45: 22.9975 | V45: 38.5 | W45: 61457.096 | Y45: 3.2911 | Z45: 2.4854 | AA45: 0.6857 | AB45: 12.639 | AC45: 0.805 | AD45: #N/A N/A | AE45: 6.1387 | AF45: 3.4724 | AG45: 0.428 | AH45: 3540.4996 | AJ45: 2.7648 | AK45: 27.0126 | AL45: 1.5952 | AM45: 39.0886 | AN45: 0.7317 | AO45: 195.1108 | AP45: 49.1292 | AQ45: 40.4781 | AR45: 80.375 | AS45: 66578.705 | AU45: =+A45 -> 43924 | AV45: =+(Y45*AH45+N45*W45+B45*K45+AJ45*AS45)/(K45+W45+AH45) -> 4.8764206 | AW45: =+(AV45-$AW$1)/$AX$1 -> -0.8216579
A46: 43931 | B46: 4.492 | C46: 0.4011 | D46: -0.253 | E46: 51.3173 | F46: 3.4632 | G46: 0 | H46: 22.2103 | I46: -2.3319 | J46: 40.41 | K46: 158937.7 | M46: 43931 | N46: 3.0939 | O46: 11.8338 | P46: 1.0633 | Q46: 42.9396 | R46: 1.7733 | S46: #N/A N/A | T46: 33.3065 | U46: 22.9975 | V46: 41.5 | W46: 66245.961 | Y46: 3.4504 | Z46: 2.4854 | AA46: 0.6857 | AB46: 12.639 | AC46: 0.805 | AD46: #N/A N/A | AE46: 6.1387 | AF46: 3.4724 | AG46: 0.465 | AH46: 3846.1542 | AJ46: 2.9322 | AK46: 27.0126 | AL46: 1.5952 | AM46: 39.0886 | AN46: 0.7317 | AO46: 195.1108 | AP46: 49.1292 | AQ46: 40.4781 | AR46: 86.993 | AS46: 72060.722 | AU46: =+A46 -> 43931 | AV46: =+(Y46*AH46+N46*W46+B46*K46+AJ46*AS46)/(K46+W46+AH46) -> 4.9926851 | AW46: =+(AV46-$AW$1)/$AX$1 -> -0.78556837
A47: 43938 | B47: 4.4865 | C47: 0.4011 | D47: -0.253 | E47: 51.3173 | F47: 3.4632 | G47: 0 | H47: 22.2103 | I47: -2.3319 | J47: 40.185 | K47: 158052.75 | M47: 43938 | N47: 3.0669 | O47: 11.8338 | P47: 1.0633 | Q47: 42.9396 | R47: 1.7733 | S47: #N/A N/A | T47: 33.3065 | U47: 22.9975 | V47: 41.7 | W47: 66565.219 | Y47: 3.583 | Z47: 2.4854 | AA47: 0.6857 | AB47: 12.639 | AC47: 0.805 | AD47: #N/A N/A | AE47: 6.1387 | AF47: 3.4724 | AG47: 0.495 | AH47: 4100.8664 | AJ47: 2.9213 | AK47: 27.0126 | AL47: 1.5952 | AM47: 39.0886 | AN47: 0.7317 | AO47: 195.1108 | AP47: 49.1292 | AQ47: 40.4781 | AR47: 86.561 | AS47: 71703.199 | AU47: =+A47 -> 43938 | AV47: =+(Y47*AH47+N47*W47+B47*K47+AJ47*AS47)/(K47+W47+AH47) -> 4.9729726 | AW47: =+(AV47-$AW$1)/$AX$1 -> -0.79168731
A48: 43945 | B48: 4.4091 | C48: 0.4011 | D48: -0.253 | E48: 51.3173 | F48: 3.4632 | G48: 0 | H48: 22.2103 | I48: -2.3319 | J48: 37.03 | K48: 145643.73 | M48: 43945 | N48: 3.0607 | O48: 11.8338 | P48: 1.0633 | Q48: 42.9396 | R48: 1.7733 | S48: #N/A N/A | T48: 33.3065 | U48: 22.9975 | V48: 42.45 | W48: 67762.435 | Y48: 3.8617 | Z48: 2.4854 | AA48: 0.6857 | AB48: 12.639 | AC48: 0.805 | AD48: #N/A N/A | AE48: 6.1387 | AF48: 3.4724 | AG48: 0.56 | AH48: 4635.762 | AJ48: 3.005 | AK48: 27.0126 | AL48: 1.5952 | AM48: 39.0886 | AN48: 0.7317 | AO48: 195.1108 | AP48: 49.1292 | AQ48: 40.4781 | AR48: 89.87 | AS48: 74444.208 | AU48: =+A48 -> 43945 | AV48: =+(Y48*AH48+N48*W48+B48*K48+AJ48*AS48)/(K48+W48+AH48) -> 5.0043817 | AW48: =+(AV48-$AW$1)/$AX$1 -> -0.78193765
A49: 43952 | B49: 4.5641 | C49: 0.4011 | D49: -0.253 | E49: 51.3173 | F49: 3.4632 | G49: 0 | H49: 22.2103 | I49: -2.3319 | J49: 43.35 | K49: 170501.1 | M49: 43952 | N49: 3.1374 | O49: 11.8338 | P49: 1.0633 | Q49: 42.9396 | R49: 1.7733 | S49: #N/A N/A | T49: 33.3065 | U49: 22.9975 | V49: 46.05 | W49: 73509.072 | Y49: 4.1536 | Z49: 2.4854 | AA49: 0.6857 | AB49: 12.639 | AC49: 0.805 | AD49: #N/A N/A | AE49: 6.1387 | AF49: 3.4724 | AG49: 0.628 | AH49: 5196.1289 | AJ49: 3.2015 | AK49: 27.0126 | AL49: 1.5952 | AM49: 39.0886 | AN49: 0.7317 | AO49: 195.1108 | AP49: 49.1292 | AQ49: 40.4781 | AR49: 97.639 | AS49: 80879.62 | AU49: =+A49 -> 43952 | AV49: =+(Y49*AH49+N49*W49+B49*K49+AJ49*AS49)/(K49+W49+AH49) -> 5.1737463 | AW49: =+(AV49-$AW$1)/$AX$1 -> -0.72936538
A50: 43959 | B50: 4.6727 | C50: 0.4011 | D50: -0.253 | E50: 51.3173 | F50: 3.4632 | G50: 0 | H50: 22.2103 | I50: -2.3319 | J50: 47.78 | K50: 187924.85 | M50: 43959 | N50: 3.299 | O50: 11.8338 | P50: 1.0633 | Q50: 42.9396 | R50: 1.7733 | S50: #N/A N/A | T50: 33.3065 | U50: 22.9975 | V50: 50.4 | W50: 84526.447 | Y50: 4.5516 | Z50: 2.4854 | AA50: 0.6857 | AB50: 12.639 | AC50: 0.805 | AD50: #N/A N/A | AE50: 6.1387 | AF50: 3.4724 | AG50: 0.72 | AH50: 5960.2655 | AJ50: 3.4114 | AK50: 27.0126 | AL50: 1.5952 | AM50: 39.0886 | AN50: 0.7317 | AO50: 195.1108 | AP50: 49.1292 | AQ50: 40.4781 | AR50: 105.935 | AS50: 87752.004 | AU50: =+A50 -> 43959 | AV50: =+(Y50*AH50+N50*W50+B50*K50+AJ50*AS50)/(K50+W50+AH50) -> 5.3282813 | AW50: =+(AV50-$AW$1)/$AX$1 -> -0.68139636
A51: 43966 | B51: 4.7539 | C51: 0.4011 | D51: -0.253 | E51: 51.3173 | F51: 3.4632 | G51: 0 | H51: 22.2103 | I51: -2.3319 | J51: 51.095 | K51: 200963.17 | M51: 43966 | N51: 3.3682 | O51: 11.8338 | P51: 1.0633 | Q51: 42.9396 | R51: 1.7733 | S51: #N/A N/A | T51: 33.3065 | U51: 22.9975 | V51: 53.7 | W51: 90060.917 | Y51: 4.5649 | Z51: 2.4854 | AA51: 0.6857 | AB51: 12.639 | AC51: 0.805 | AD51: #N/A N/A | AE51: 6.1387 | AF51: 3.4724 | AG51: 0.723 | AH51: 5985.7367 | AJ51: 3.8081 | AK51: 27.0126 | AL51: 1.5952 | AM51: 39.0886 | AN51: 0.7317 | AO51: 195.1108 | AP51: 49.1292 | AQ51: 40.4781 | AR51: 121.617 | AS51: 100742 | AU51: =+A51 -> 43966 | AV51: =+(Y51*AH51+N51*W51+B51*K51+AJ51*AS51)/(K51+W51+AH51) -> 5.6215713 | AW51: =+(AV51-$AW$1)/$AX$1 -> -0.59035656
A52: 43973 | B52: 4.8462 | C52: 0.4011 | D52: -0.253 | E52: 51.3173 | F52: 3.4632 | G52: 0 | H52: 22.2103 | I52: -2.3319 | J52: 54.86 | K52: 215771.4 | M52: 43973 | N52: 3.3634 | O52: 11.8338 | P52: 1.0633 | Q52: 42.9396 | R52: 1.7733 | S52: #N/A N/A | T52: 33.3065 | U52: 22.9975 | V52: 54.3 | W52: 91067.184 | Y52: 6.0541 | Z52: 2.4854 | AA52: 0.6857 | AB52: 12.639 | AC52: 0.805 | AD52: #N/A N/A | AE52: 6.1387 | AF52: 3.4724 | AG52: 0.865 | AH52: 8844.7044 | AJ52: 3.8918 | AK52: 27.0126 | AL52: 1.5952 | AM52: 39.0886 | AN52: 0.7317 | AO52: 195.1108 | AP52: 49.1292 | AQ52: 40.4781 | AR52: 124.926 | AS52: 103483.01 | AU52: =+A52 -> 43973 | AV52: =+(Y52*AH52+N52*W52+B52*K52+AJ52*AS52)/(K52+W52+AH52) -> 5.7280467 | AW52: =+(AV52-$AW$1)/$AX$1 -> -0.55730565
A53: 43980 | B53: 4.8776 | C53: 0.4011 | D53: -0.253 | E53: 51.3173 | F53: 3.4632 | G53: 0 | H53: 22.2103 | I53: -2.3319 | J53: 56.14 | K53: 220805.8 | M53: 43980 | N53: 3.162 | O53: 11.8338 | P53: 1.0633 | Q53: 42.9396 | R53: 1.7733 | S53: #N/A N/A | T53: 33.3065 | U53: 22.9975 | V53: 47.6 | W53: 79830.533 | Y53: 5.4966 | Z53: 2.4854 | AA53: 0.6857 | AB53: 12.639 | AC53: 0.805 | AD53: #N/A N/A | AE53: 6.1387 | AF53: 3.4724 | AG53: 0.76 | AH53: 7774.5267 | AJ53: 3.6795 | AK53: 27.0126 | AL53: 1.5952 | AM53: 39.0886 | AN53: 0.7317 | AO53: 195.1108 | AP53: 49.1292 | AQ53: 40.4781 | AR53: 116.534 | AS53: 96531.177 | AU53: =+A53 -> 43980 | AV53: =+(Y53*AH53+N53*W53+B53*K53+AJ53*AS53)/(K53+W53+AH53) -> 5.6007964 | AW53: =+(AV53-$AW$1)/$AX$1 -> -0.59680526
A54: 43987 | B54: 5.1576 | C54: 0.4011 | D54: -0.253 | E54: 51.3173 | F54: 3.4632 | G54: 0 | H54: 22.2103 | I54: -2.3319 | J54: 67.56 | K54: 265722.12 | M54: 43987 | N54: 3.3066 | O54: 11.8338 | P54: 1.0633 | Q54: 42.9396 | R54: 1.7733 | S54: #N/A N/A | T54: 33.3065 | U54: 22.9975 | V54: 53.7 | W54: 90060.917 | Y54: 5.6606 | Z54: 2.4854 | AA54: 0.6857 | AB54: 12.639 | AC54: 0.805 | AD54: #N/A N/A | AE54: 6.1387 | AF54: 3.4724 | AG54: 0.791 | AH54: 8089.2848 | AJ54: 4.1199 | AK54: 27.0126 | AL54: 1.5952 | AM54: 39.0886 | AN54: 0.7317 | AO54: 195.1108 | AP54: 49.1292 | AQ54: 40.4781 | AR54: 133.942 | AS54: 110951.27 | AU54: =+A54 -> 43987 | AV54: =+(Y54*AH54+N54*W54+B54*K54+AJ54*AS54)/(K54+W54+AH54) -> 5.9668791 | AW54: =+(AV54-$AW$1)/$AX$1 -> -0.48316998
A55: 43994 | B55: 5.1431 | C55: 0.4011 | D55: -0.253 | E55: 51.3173 | F55: 3.4632 | G55: 0 | H55: 22.2103 | I55: -2.3319 | J55: 66.97 | K55: 263401.58 | M55: 43994 | N55: 3.1656 | O55: 11.8338 | P55: 1.0633 | Q55: 42.9396 | R55: 1.7733 | S55: #N/A N/A | T55: 33.3065 | U55: 22.9975 | V55: 49.15 | W55: 82430.057 | Y55: 5.513 | Z55: 2.4854 | AA55: 0.6857 | AB55: 12.639 | AC55: 0.805 | AD55: #N/A N/A | AE55: 6.1387 | AF55: 3.4724 | AG55: 0.763 | AH55: 7806.0025 | AJ55: 3.8324 | AK55: 27.0126 | AL55: 1.5952 | AM55: 39.0886 | AN55: 0.7317 | AO55: 195.1108 | AP55: 49.1292 | AQ55: 40.4781 | AR55: 122.576 | AS55: 101536.5 | AU55: =+A55 -> 43994 | AV55: =+(Y55*AH55+N55*W55+B55*K55+AJ55*AS55)/(K55+W55+AH55) -> 5.7906851 | AW55: =+(AV55-$AW$1)/$AX$1 -> -0.53786214
A56: 44001 | B56: 5.0258 | C56: 0.4011 | D56: -0.253 | E56: 51.3173 | F56: 3.4632 | G56: 0 | H56: 22.2103 | I56: -2.3319 | J56: 62.185 | K56: 244581.56 | M56: 44001 | N56: 2.9801 | O56: 11.8338 | P56: 1.0633 | Q56: 42.9396 | R56: 1.7733 | S56: #N/A N/A | T56: 33.3065 | U56: 22.9975 | V56: 45.75 | W56: 71969.288 | Y56: 5.1523 | Z56: 2.4854 | AA56: 0.6857 | AB56: 12.639 | AC56: 0.805 | AD56: #N/A N/A | AE56: 6.1387 | AF56: 3.4724 | AG56: 0.695 | AH56: 7113.5345 | AJ56: 3.6346 | AK56: 27.0126 | AL56: 1.5952 | AM56: 39.0886 | AN56: 0.7317 | AO56: 195.1108 | AP56: 49.1292 | AQ56: 40.4781 | AR56: 114.759 | AS56: 95061.361 | AU56: =+A56 -> 44001 | AV56: =+(Y56*AH56+N56*W56+B56*K56+AJ56*AS56)/(K56+W56+AH56) -> 5.6411977 | AW56: =+(AV56-$AW$1)/$AX$1 -> -0.58426436
... A58: 44015 | B58: 11.8464 | C58: -7.5981 | D58: -1.0952 | E58: 54.3772 | F58: 8.2751 | G58: 0 | H58: 10.1836 | I58: -16.886 | J58: 62.79 | K58: 246961.1 | M58: 44015 | N58: 5.166 | O58: 4.0209 | P58: 0.3674 | Q58: 43.0931 | R58: 2.8022 | S58: #N/A N/A | T58: 25.2993 | U58: 13.041 | V58: 47.45 | W58: 73516.252 | Y58: 10.106 | Z58: -2.0121 | AA58: 0.2603 | AB58: 10.6599 | AC58: 0.3536 | AD58: #N/A N/A | AE58: 2.7592 | AF58: -0.0999 | AG58: 0.686 | AH58: 7019.1071 | AJ58: 3.4066 | AK58: 26.1046 | AL58: 1.1527 | AM58: 38.7698 | AN58: 0.6282 | AO58: 195.1108 | AP58: 49.4033 | AQ58: 39.5251 | AR58: 113.129 | AS58: 93710.719 | AU58: =+A58 -> 44015 | AV58: =+(Y58*AH58+N58*W58+B58*K58+AJ58*AS58)/(K58+W58+AH58) -> 11.284259 | AW58: =+(AV58-$AW$1)/$AX$1 -> 1.1673916
A59: 44022 | B59: 12.0796 | C59: -7.5981 | D59: -1.0952 | E59: 54.3772 | F59: 8.2751 | G59: 0 | H59: 10.1836 | I59: -16.886 | J59: 66.99 | K59: 263480.24 | M59: 44022 | N59: 5.2877 | O59: 4.0209 | P59: 0.3674 | Q59: 43.0931 | R59: 2.8022 | S59: #N/A N/A | T59: 25.2993 | U59: 13.041 | V59: 50.9 | W59: 78861.48 | Y59: 11.1422 | Z59: -2.0121 | AA59: 0.2603 | AB59: 10.6599 | AC59: 0.3536 | AD59: #N/A N/A | AE59: 2.7592 | AF59: -0.0999 | AG59: 0.772 | AH59: 7900.4299 | AJ59: 3.714 | AK59: 26.1046 | AL59: 1.1527 | AM59: 38.7698 | AN59: 0.6282 | AO59: 195.1108 | AP59: 49.4033 | AQ59: 39.5251 | AR59: 125.645 | AS59: 104078.88 | AU59: =+A59 -> 44022 | AV59: =+(Y59*AH59+N59*W59+B59*K59+AJ59*AS59)/(K59+W59+AH59) -> 11.632834 | AW59: =+(AV59-$AW$1)/$AX$1 -> 1.2755924 | AX59: =+_xlfn.PERCENTILE.INC(OFFSET(AW59,-52,0,52,1),0.9) -> -0.40168474 | AY59: =+_xlfn.PERCENTILE.INC(OFFSET(AW59,-52,0,52,1),0.75) -> -0.45102138 | AZ59: =+_xlfn.PERCENTILE.INC(OFFSET(AW59,-52,0,52,1),0.5) -> -0.570785 | BA59: =+_xlfn.PERCENTILE.INC(OFFSET(AW59,-52,0,52,1),0.25) -> -0.78635798 | BB59: =+_xlfn.PERCENTILE.INC(OFFSET(AW59,-52,0,52,1),0.1) -> -0.95947084
A60: 44029 | B60: 12.5002 | C60: -7.5981 | D60: -1.0952 | E60: 54.3772 | F60: 8.2751 | G60: 0 | H60: 10.1836 | I60: -16.886 | J60: 74.565 | K60: 293273.68 | M60: 44029 | N60: 5.2811 | O60: 4.0209 | P60: 0.3674 | Q60: 43.0931 | R60: 2.8022 | S60: #N/A N/A | T60: 25.2993 | U60: 13.041 | V60: 51.7 | W60: 80100.953 | Y60: 11.9564 | Z60: -2.0121 | AA60: 0.2603 | AB60: 10.6599 | AC60: 0.3536 | AD60: #N/A N/A | AE60: 2.7592 | AF60: -0.0999 | AG60: 0.84 | AH60: 8592.8979 | AJ60: 3.661 | AK60: 26.1046 | AL60: 1.1527 | AM60: 38.7698 | AN60: 0.6282 | AO60: 195.1108 | AP60: 49.4033 | AQ60: 39.5251 | AR60: 123.487 | AS60: 102291.27 | AU60: =+A60 -> 44029 | AV60: =+(Y60*AH60+N60*W60+B60*K60+AJ60*AS60)/(K60+W60+AH60) -> 11.954496 | AW60: =+(AV60-$AW$1)/$AX$1 -> 1.3754389 | AX60: =+_xlfn.PERCENTILE.INC(OFFSET(AW60,-52,0,52,1),0.9) -> -0.39821602 | AY60: =+_xlfn.PERCENTILE.INC(OFFSET(AW60,-52,0,52,1),0.75) -> -0.44741383 | AZ60: =+_xlfn.PERCENTILE.INC(OFFSET(AW60,-52,0,52,1),0.5) -> -0.55567467 | BA60: =+_xlfn.PERCENTILE.INC(OFFSET(AW60,-52,0,52,1),0.25) -> -0.78635798 | BB60: =+_xlfn.PERCENTILE.INC(OFFSET(AW60,-52,0,52,1),0.1) -> -0.95947084
A61: 44036 | B61: 12.6182 | C61: -7.5981 | D61: -1.0952 | E61: 54.3772 | F61: 8.2751 | G61: 0 | H61: 10.1836 | I61: -16.886 | J61: 76.69 | K61: 301631.58 | M61: 44036 | N61: 5.4829 | O61: 4.0209 | P61: 0.3674 | Q61: 43.0931 | R61: 2.8022 | S61: #N/A N/A | T61: 25.2993 | U61: 13.041 | V61: 57.35 | W61: 88854.732 | Y61: 11.9194 | Z61: -2.0121 | AA61: 0.2603 | AB61: 10.6599 | AC61: 0.3536 | AD61: #N/A N/A | AE61: 2.7592 | AF61: -0.0999 | AG61: 0.837 | AH61: 8561.4221 | AJ61: 4.0191 | AK61: 26.1046 | AL61: 1.1527 | AM61: 38.7698 | AN61: 0.6282 | AO61: 195.1108 | AP61: 49.4033 | AQ61: 39.5251 | AR61: 138.066 | AS61: 114367.6 | AU61: =+A61 -> 44036 | AV61: =+(Y61*AH61+N61*W61+B61*K61+AJ61*AS61)/(K61+W61+AH61) -> 12.166291 | AW61: =+(AV61-$AW$1)/$AX$1 -> 1.4411821 | AX61: =+_xlfn.PERCENTILE.INC(OFFSET(AW61,-52,0,52,1),0.9) -> -0.39182454 | AY61: =+_xlfn.PERCENTILE.INC(OFFSET(AW61,-52,0,52,1),0.75) -> -0.44340414 | AZ61: =+_xlfn.PERCENTILE.INC(OFFSET(AW61,-52,0,52,1),0.5) -> -0.54595291 | BA61: =+_xlfn.PERCENTILE.INC(OFFSET(AW61,-52,0,52,1),0.25) -> -0.78284533 | BB61: =+_xlfn.PERCENTILE.INC(OFFSET(AW61,-52,0,52,1),0.1) -> -0.95947084
A62: 44043 | B62: 12.5812 | C62: -7.5981 | D62: -1.0952 | E62: 54.3772 | F62: 8.2751 | G62: 0 | H62: 10.1836 | I62: -16.886 | J62: 76.025 | K62: 299016.05 | M62: 44043 | N62: 5.3226 | O62: 4.0209 | P62: 0.3674 | Q62: 43.0931 | R62: 2.8022 | S62: #N/A N/A | T62: 25.2993 | U62: 13.041 | V62: 54.2 | W62: 83974.307 | Y62: 13.0667 | Z62: -2.0121 | AA62: 0.2603 | AB62: 10.6599 | AC62: 0.3536 | AD62: #N/A N/A | AE62: 2.7592 | AF62: -0.0999 | AG62: 0.932 | AH62: 9537.1724 | AJ62: 3.9578 | AK62: 26.1046 | AL62: 1.1527 | AM62: 38.7698 | AN62: 0.6282 | AO62: 195.1108 | AP62: 49.4033 | AQ62: 39.5251 | AR62: 135.572 | AS62: 112301.91 | AU62: =+A62 -> 44043 | AV62: =+(Y62*AH62+N62*W62+B62*K62+AJ62*AS62)/(K62+W62+AH62) -> 12.172472 | AW62: =+(AV62-$AW$1)/$AX$1 -> 1.4431006 | AX62: =+_xlfn.PERCENTILE.INC(OFFSET(AW62,-52,0,52,1),0.9) -> -0.38426492 | AY62: =+_xlfn.PERCENTILE.INC(OFFSET(AW62,-52,0,52,1),0.75) -> -0.43633942 | AZ62: =+_xlfn.PERCENTILE.INC(OFFSET(AW62,-52,0,52,1),0.5) -> -0.53212545 | BA62: =+_xlfn.PERCENTILE.INC(OFFSET(AW62,-52,0,52,1),0.25) -> -0.78284533 | BB62: =+_xlfn.PERCENTILE.INC(OFFSET(AW62,-52,0,52,1),0.1) -> -0.95947084
A63: 44050 | B63: 12.8502 | C63: -7.5981 | D63: -1.0952 | E63: 54.3772 | F63: 8.2751 | G63: 0 | H63: 10.1836 | I63: -16.886 | J63: 80.87 | K63: 318072.06 | M63: 44050 | N63: 5.4779 | O63: 4.0209 | P63: 0.3674 | Q63: 43.0931 | R63: 2.8022 | S63: #N/A N/A | T63: 25.2993 | U63: 13.041 | V63: 58.85 | W63: 91178.745 | Y63: 14.362 | Z63: -2.0121 | AA63: 0.2603 | AB63: 10.6599 | AC63: 0.3536 | AD63: #N/A N/A | AE63: 2.7592 | AF63: -0.0999 | AG63: 1.04 | AH63: 10638.826 | AJ63: 4.2075 | AK63: 26.1046 | AL63: 1.1527 | AM63: 38.7698 | AN63: 0.6282 | AO63: 195.1108 | AP63: 49.4033 | AQ63: 39.5251 | AR63: 145.739 | AS63: 120723.56 | AU63: =+A63 -> 44050 | AV63: =+(Y63*AH63+N63*W63+B63*K63+AJ63*AS63)/(K63+W63+AH63) -> 12.497324 | AW63: =+(AV63-$AW$1)/$AX$1 -> 1.5439376 | AX63: =+_xlfn.PERCENTILE.INC(OFFSET(AW63,-52,0,52,1),0.9) -> -0.36784263 | AY63: =+_xlfn.PERCENTILE.INC(OFFSET(AW63,-52,0,52,1),0.75) -> -0.43515156 | AZ63: =+_xlfn.PERCENTILE.INC(OFFSET(AW63,-52,0,52,1),0.5) -> -0.52478749 | BA63: =+_xlfn.PERCENTILE.INC(OFFSET(AW63,-52,0,52,1),0.25) -> -0.7564079 | BB63: =+_xlfn.PERCENTILE.INC(OFFSET(AW63,-52,0,52,1),0.1) -> -0.95947084
A64: 44057 | B64: 12.3791 | C64: -7.5981 | D64: -1.0952 | E64: 54.3772 | F64: 8.2751 | G64: 0 | H64: 10.1836 | I64: -16.886 | J64: 72.385 | K64: 284699.47 | M64: 44057 | N64: 5.3785 | O64: 4.0209 | P64: 0.3674 | Q64: 43.0931 | R64: 2.8022 | S64: #N/A N/A | T64: 25.2993 | U64: 13.041 | V64: 57.1 | W64: 88467.397 | Y64: 13.2517 | Z64: -2.0121 | AA64: 0.2603 | AB64: 10.6599 | AC64: 0.3536 | AD64: #N/A N/A | AE64: 2.7592 | AF64: -0.0999 | AG64: 0.948 | AH64: 9694.5515 | AJ64: 3.8 | AK64: 26.1046 | AL64: 1.1527 | AM64: 38.7698 | AN64: 0.6282 | AO64: 195.1108 | AP64: 49.4033 | AQ64: 39.5251 | AR64: 129.146 | AS64: 106978.79 | AU64: =+A64 -> 44057 | AV64: =+(Y64*AH64+N64*W64+B64*K64+AJ64*AS64)/(K64+W64+AH64) -> 11.845366 | AW64: =+(AV64-$AW$1)/$AX$1 -> 1.3415642 | AX64: =+_xlfn.PERCENTILE.INC(OFFSET(AW64,-52,0,52,1),0.9) -> 1.0140422 | AY64: =+_xlfn.PERCENTILE.INC(OFFSET(AW64,-52,0,52,1),0.75) -> -0.42984518 | AZ64: =+_xlfn.PERCENTILE.INC(OFFSET(AW64,-52,0,52,1),0.5) -> -0.52197936 | BA64: =+_xlfn.PERCENTILE.INC(OFFSET(AW64,-52,0,52,1),0.25) -> -0.7564079 | BB64: =+_xlfn.PERCENTILE.INC(OFFSET(AW64,-52,0,52,1),0.1) -> -0.95947084
A65: 44064 | B65: 12.3311 | C65: -7.5981 | D65: -1.0952 | E65: 54.3772 | F65: 8.2751 | G65: 0 | H65: 10.1836 | I65: -16.886 | J65: 71.52 | K65: 281297.31 | M65: 44064 | N65: 5.4088 | O65: 4.0209 | P65: 0.3674 | Q65: 43.0931 | R65: 2.8022 | S65: #N/A N/A | T65: 25.2993 | U65: 13.041 | V65: 58.9 | W65: 90810.9 | Y65: 14.473 | Z65: -2.0121 | AA65: 0.2603 | AB65: 10.6599 | AC65: 0.3536 | AD65: #N/A N/A | AE65: 2.7592 | AF65: -0.0999 | AG65: 1.049 | AH65: 10733.253 | AJ65: 3.7058 | AK65: 26.1046 | AL65: 1.1527 | AM65: 38.7698 | AN65: 0.6282 | AO65: 195.1108 | AP65: 49.4033 | AQ65: 39.5251 | AR65: 125.31 | AS65: 103800.81 | AU65: =+A65 -> 44064 | AV65: =+(Y65*AH65+N65*W65+B65*K65+AJ65*AS65)/(K65+W65+AH65) -> 11.753927 | AW65: =+(AV65-$AW$1)/$AX$1 -> 1.3131806 | AX65: =+_xlfn.PERCENTILE.INC(OFFSET(AW65,-52,0,52,1),0.9) -> 1.2647723 | AY65: =+_xlfn.PERCENTILE.INC(OFFSET(AW65,-52,0,52,1),0.75) -> -0.41737456 | AZ65: =+_xlfn.PERCENTILE.INC(OFFSET(AW65,-52,0,52,1),0.5) -> -0.50610004 | BA65: =+_xlfn.PERCENTILE.INC(OFFSET(AW65,-52,0,52,1),0.25) -> -0.73399853 | BB65: =+_xlfn.PERCENTILE.INC(OFFSET(AW65,-52,0,52,1),0.1) -> -0.92999974
A66: 44071 | B66: 12.3086 | C66: -7.5981 | D66: -1.0952 | E66: 54.3772 | F66: 8.2751 | G66: 0 | H66: 10.1836 | I66: -16.886 | J66: 71.115 | K66: 279704.39 | M66: 44071 | N66: 5.4014 | O66: 4.0209 | P66: 0.3674 | Q66: 43.0931 | R66: 2.8022 | S66: #N/A N/A | T66: 25.2993 | U66: 13.041 | V66: 59.5 | W66: 91735.968 | Y66: 12.8446 | Z66: -2.0121 | AA66: 0.2603 | AB66: 10.6599 | AC66: 0.3536 | AD66: #N/A N/A | AE66: 2.7592 | AF66: -0.0999 | AG66: 1.132 | AH66: 9348.3175 | AJ66: 3.4761 | AK66: 26.1046 | AL66: 1.1527 | AM66: 38.7698 | AN66: 0.6282 | AO66: 195.1108 | AP66: 49.4033 | AQ66: 39.5251 | AR66: 115.958 | AS66: 96054.48 | AU66: =+A66 -> 44071 | AV66: =+(Y66*AH66+N66*W66+B66*K66+AJ66*AS66)/(K66+W66+AH66) -> 11.534593 | AW66: =+(AV66-$AW$1)/$AX$1 -> 1.2450975 | AX66: =+_xlfn.PERCENTILE.INC(OFFSET(AW66,-52,0,52,1),0.9) -> 1.3094218 | AY66: =+_xlfn.PERCENTILE.INC(OFFSET(AW66,-52,0,52,1),0.75) -> -0.40458557 | AZ66: =+_xlfn.PERCENTILE.INC(OFFSET(AW66,-52,0,52,1),0.5) -> -0.48995033 | BA66: =+_xlfn.PERCENTILE.INC(OFFSET(AW66,-52,0,52,1),0.25) -> -0.69338861 | BB66: =+_xlfn.PERCENTILE.INC(OFFSET(AW66,-52,0,52,1),0.1) -> -0.84377387
A67: 44078 | B67: 12.0926 | C67: -7.5981 | D67: -1.0952 | E67: 54.3772 | F67: 8.2751 | G67: 0 | H67: 10.1836 | I67: -16.886 | J67: 67.225 | K67: 264404.53 | M67: 44078 | N67: 5.3536 | O67: 4.0209 | P67: 0.3674 | Q67: 43.0931 | R67: 2.8022 | S67: #N/A N/A | T67: 25.2993 | U67: 13.041 | V67: 59.1 | W67: 91119.256 | Y67: 13.0297 | Z67: -2.0121 | AA67: 0.2603 | AB67: 10.6599 | AC67: 0.3536 | AD67: #N/A N/A | AE67: 2.7592 | AF67: -0.0999 | AG67: 1.151 | AH67: 9505.6966 | AJ67: 3.4879 | AK67: 26.1046 | AL67: 1.1527 | AM67: 38.7698 | AN67: 0.6282 | AO67: 195.1108 | AP67: 49.4033 | AQ67: 39.5251 | AR67: 116.438 | AS67: 96451.727 | AU67: =+A67 -> 44078 | AV67: =+(Y67*AH67+N67*W67+B67*K67+AJ67*AS67)/(K67+W67+AH67) -> 11.35641 | AW67: =+(AV67-$AW$1)/$AX$1 -> 1.189788 | AX67: =+_xlfn.PERCENTILE.INC(OFFSET(AW67,-52,0,52,1),0.9) -> 1.3094218 | AY67: =+_xlfn.PERCENTILE.INC(OFFSET(AW67,-52,0,52,1),0.75) -> -0.40039889 | AZ67: =+_xlfn.PERCENTILE.INC(OFFSET(AW67,-52,0,52,1),0.5) -> -0.48582152 | BA67: =+_xlfn.PERCENTILE.INC(OFFSET(AW67,-52,0,52,1),0.25) -> -0.61795304 | BB67: =+_xlfn.PERCENTILE.INC(OFFSET(AW67,-52,0,52,1),0.1) -> -0.82147618
...

Sheet Indice
B2: Start Date | C2: 38718
B3: End Date
I4: Retornos | O4: Ret EW | Q4: Indice EW | T4: Oil / Merval | V4: Mkt Cap | AC4: Ret MktCap W | AE4: Indice MktCap W | AH4: Ratio y percentiles
B5: Dates | C5: YPFD AR Equity | D5: PAMP AR Equity | E5: COME AR Equity | F5: TGSU2 AR EQUITY | G5: MERVAL Index | I5: =+C5 -> YPFD AR Equity | J5: =+D5 -> PAMP AR Equity | K5: =+E5 -> COME AR Equity | L5: =+F5 -> TGSU2 AR EQUITY | M5: =+G5 -> MERVAL Index | Q5: Indice | R5: Merval | V5: Dates | W5: =+I5 -> YPFD AR Equity | X5: =+J5 -> PAMP AR Equity | Y5: =+K5 -> COME AR Equity | Z5: =+L5 -> TGSU2 AR EQUITY | AE5: Indice | AF5: Merval | AH5: Fecha | AI5: Ratio | AJ5: Q10 | AK5: Q25 | AL5: Q50 | AM5: Q75 | AN5: Q90
B6: =_xll.BDH(C$5,"PX_LAST",$C2,$C3,"Dir=V","Per=W","Days=A","Dts=S","cols=2;rows=1084") -> 38723 | C6: 10.118 | D6: =_xll.BDH(D$5,"PX_LAST",$C2,$C3,"Dir=V","Per=W","Days=A","Dts=H","cols=1;rows=1084") -> 3.222 | E6: =_xll.BDH(E$5,"PX_LAST",$C2,$C3,"Dir=V","Per=W","Days=A","Dts=H","cols=1;rows=1084") -> 0.097 | F6: =_xll.BDH(F$5,"PX_LAST",$C2,$C3,"Dir=V","Per=W","Days=A","Dts=H","cols=1;rows=1084") -> 1.667 | G6: =_xll.BDH(G$5,"PX_LAST",$C2,$C3,"Dir=V","Per=W","Days=A","Dts=H","cols=1;rows=1084") -> 1616.29 | Q6: 100 | R6: 100 | T6: =+Q6/R6 -> 1 | V6: =_xll.BDH(W$5,"CUR_MKT_CAP",$C2,$C3,"Dir=V","Per=W","Days=A","Dts=S","cols=2;rows=1084") -> 38723 | W6: 68829.747 | X6: =_xll.BDH(X$5,"CUR_MKT_CAP",$C2,$C3,"Dir=V","Per=W","Days=A","Dts=H","cols=1;rows=1084") -> 20.4 | Y6: =_xll.BDH(Y$5,"CUR_MKT_CAP",$C2,$C3,"Dir=V","Per=W","Days=A","Dts=H","cols=1;rows=1084") -> 15.7349 | Z6: =_xll.BDH(Z$5,"CUR_MKT_CAP",$C2,$C3,"Dir=V","Per=W","Days=A","Dts=H","cols=1;rows=1084") -> 2860.1831 | AE6: 100 | AF6: 100 | AH6: =+B6 -> 38723 | AI6: =+(AE6/$AE$6)/(AF6/$AF$6) -> 1
B7: 38730 | C7: 9.627 | D7: 2.606 | E7: 0.097 | F7: 1.56 | G7: 1645.24 | I7: =+C7/C6-1 -> -0.048527377 | J7: =+D7/D6-1 -> -0.1911856 | K7: =+E7/E6-1 -> 0 | L7: =+F7/F6-1 -> -0.064187163 | M7: =+G7/G6-1 -> 0.01791139 | O7: =+AVERAGE(I7:L7) -> -0.075975035 | Q7: =+Q6*(1+O7) -> 92.402497 | R7: =+R6*(1+M7) -> 101.79114 | T7: =+Q7/R7 -> 0.90776562 | V7: 38730 | W7: 65486.588 | X7: 16.5 | Y7: 15.6828 | Z7: 2677.4492 | AC7: =+SUMPRODUCT(I7:L7,W6:Z6)/SUM(W6:AA6) -> -0.049181763 | AE7: =+AE6*(1+AC7) -> 95.081824 | AF7: =+AF6*(1+M7) -> 101.79114 | AH7: =+B7 -> 38730 | AI7: =+(AE7/$AE$6)/(AF7/$AF$6) -> 0.93408743
B8: 38737 | C8: 9.974 | D8: 2.795 | E8: 0.103 | F8: 1.574 | G8: 1701.88 | I8: =+C8/C7-1 -> 0.036044458 | J8: =+D8/D7-1 -> 0.072524942 | K8: =+E8/E7-1 -> 0.06185567 | L8: =+F8/F7-1 -> 0.008974359 | M8: =+G8/G7-1 -> 0.034426588 | O8: =+AVERAGE(I8:L8) -> 0.044849857 | Q8: =+Q7*(1+O8) -> 96.546735 | R8: =+R7*(1+M8) -> 105.29546 | T8: =+Q8/R8 -> 0.91691261 | V8: 38737 | W8: 67846.465 | X8: 17.7 | Y8: 16.7249 | Z8: 2701.284 | AC8: =+SUMPRODUCT(I8:L8,W7:Z7)/SUM(W7:AA7) -> 0.034996422 | AE8: =+AE7*(1+AC8) -> 98.409347 | AF8: =+AF7*(1+M8) -> 105.29546 | AH8: =+B8 -> 38737 | AI8: =+(AE8/$AE$6)/(AF8/$AF$6) -> 0.93460199
B9: 38744 | C9: 9.818 | D9: 2.843 | E9: 0.103 | F9: 1.505 | G9: 1739.83 | I9: =+C9/C8-1 -> -0.015640666 | J9: =+D9/D8-1 -> 0.017173524 | K9: =+E9/E8-1 -> 0 | L9: =+F9/F8-1 -> -0.043837357 | M9: =+G9/G8-1 -> 0.022298869 | O9: =+AVERAGE(I9:L9) -> -0.010576125 | Q9: =+Q8*(1+O9) -> 95.525645 | R9: =+R8*(1+M9) -> 107.64343 | T9: =+Q9/R9 -> 0.88742662 | V9: 38744 | W9: 66784.521 | X9: 18 | Y9: 16.6467 | Z9: 2582.1097 | AC9: =+SUMPRODUCT(I9:L9,W8:Z8)/SUM(W8:AA8) -> -0.01670786 | AE9: =+AE8*(1+AC9) -> 96.765138 | AF9: =+AF8*(1+M9) -> 107.64343 | AH9: =+B9 -> 38744 | AI9: =+(AE9/$AE$6)/(AF9/$AF$6) -> 0.89894142
B10: 38751 | C10: 9.309 | D10: 2.843 | E10: 0.109 | F10: 1.486 | G10: 1703.33 | I10: =+C10/C9-1 -> -0.051843553 | J10: =+D10/D9-1 -> 0 | K10: =+E10/E9-1 -> 0.058252427 | L10: =+F10/F9-1 -> -0.012624585 | M10: =+G10/G9-1 -> -0.020979061 | O10: =+AVERAGE(I10:L10) -> -0.0015539275 | Q10: =+Q9*(1+O10) -> 95.377205 | R10: =+R9*(1+M10) -> 105.38517 | T10: =+Q10/R10 -> 0.90503439 | V10: 38751 | W10: 63323.368 | X10: 18 | Y10: 17.6367 | Z10: 2550.3299 | AC10: =+SUMPRODUCT(I10:L10,W9:Z9)/SUM(W9:AA9) -> -0.050344537 | AE10: =+AE9*(1+AC10) -> 91.893542 | AF10: =+AF9*(1+M10) -> 105.38517 | AH10: =+B10 -> 38751 | AI10: =+(AE10/$AE$6)/(AF10/$AF$6) -> 0.87197791
B11: 38758 | C11: 9.338 | D11: 2.843 | E11: 0.11 | F11: 1.505 | G11: 1695.48 | I11: =+C11/C10-1 -> 0.0031152648 | J11: =+D11/D10-1 -> 0 | K11: =+E11/E10-1 -> 0.0091743119 | L11: =+F11/F10-1 -> 0.012786003 | M11: =+G11/G10-1 -> -0.0046086196 | O11: =+AVERAGE(I11:L11) -> 0.0062688949 | Q11: =+Q10*(1+O11) -> 95.975115 | R11: =+R10*(1+M11) -> 104.89949 | T11: =+Q11/R11 -> 0.91492449 | V11: 38758 | W11: 63520.024 | X11: 18 | Y11: 17.8451 | Z11: 2582.1097 | AC11: =+SUMPRODUCT(I11:L11,W10:Z10)/SUM(W10:AA10) -> 0.0034902399 | AE11: =+AE10*(1+AC11) -> 92.214272 | AF11: =+AF10*(1+M11) -> 104.89949 | AH11: =+B11 -> 38758 | AI11: =+(AE11/$AE$6)/(AF11/$AF$6) -> 0.87907263
B12: 38765 | C12: 9.309 | D12: 2.653 | E12: 0.107 | F12: 1.444 | G12: 1699.49 | I12: =+C12/C11-1 -> -0.0031055901 | J12: =+D12/D11-1 -> -0.066830813 | K12: =+E12/E11-1 -> -0.027272727 | L12: =+F12/F11-1 -> -0.040531561 | M12: =+G12/G11-1 -> 0.0023651119 | O12: =+AVERAGE(I12:L12) -> -0.034435173 | Q12: =+Q11*(1+O12) -> 92.670195 | R12: =+R11*(1+M12) -> 105.14759 | T12: =+Q12/R12 -> 0.88133446 | V12: 38765 | W12: 63323.368 | X12: 16.8 | Y12: 17.298 | Z12: 2478.8253 | AC12: =+SUMPRODUCT(I12:L12,W11:Z11)/SUM(W11:AA11) -> -0.004590611 | AE12: =+AE11*(1+AC12) -> 91.790952 | AF12: =+AF11*(1+M12) -> 105.14759 | AH12: =+B12 -> 38765 | AI12: =+(AE12/$AE$6)/(AF12/$AF$6) -> 0.87297247
B13: 38772 | C13: 9.517 | D13: 2.653 | E13: 0.11 | F13: 1.482 | G13: 1726.65 | I13: =+C13/C12-1 -> 0.022343968 | J13: =+D13/D12-1 -> 0 | K13: =+E13/E12-1 -> 0.028037383 | L13: =+F13/F12-1 -> 0.026315789 | M13: =+G13/G12-1 -> 0.015981265 | O13: =+AVERAGE(I13:L13) -> 0.019174285 | Q13: =+Q12*(1+O13) -> 94.44708 | R13: =+R12*(1+M13) -> 106.82798 | T13: =+Q13/R13 -> 0.88410431 | V13: 38772 | W13: 64739.294 | X13: 16.8 | Y13: 17.7669 | Z13: 2542.385 | AC13: =+SUMPRODUCT(I13:L13,W12:Z12)/SUM(W12:AA12) -> 0.022489307 | AE13: =+AE12*(1+AC13) -> 93.855267 | AF13: =+AF12*(1+M13) -> 106.82798 | AH13: =+B13 -> 38772 | AI13: =+(AE13/$AE$6)/(AF13/$AF$6) -> 0.87856445
B14: 38779 | C14: 9.829 | D14: 1.706 | E14: 0.106 | F14: 1.468 | G14: 1823.56 | I14: =+C14/C13-1 -> 0.03278344 | J14: =+D14/D13-1 -> -0.35695439 | K14: =+E14/E13-1 -> -0.036363636 | L14: =+F14/F13-1 -> -0.0094466937 | M14: =+G14/G13-1 -> 0.056126024 | O14: =+AVERAGE(I14:L14) -> -0.09249532 | Q14: =+Q13*(1+O14) -> 85.711167 | R14: =+R13*(1+M14) -> 112.82381 | T14: =+Q14/R14 -> 0.7596904 | V14: 38779 | W14: 66863.183 | X14: 10.8 | Y14: 17.1938 | Z14: 2518.5501 | AC14: =+SUMPRODUCT(I14:L14,W13:Z13)/SUM(W13:AA13) -> 0.031072986 | AE14: =+AE13*(1+AC14) -> 96.771631 | AF14: =+AF13*(1+M14) -> 112.82381 | AH14: =+B14 -> 38779 | AI14: =+(AE14/$AE$6)/(AF14/$AF$6) -> 0.85772346
B15: 38786 | C15: 9.829 | D15: 1.421 | E15: 0.101 | F15: 1.407 | G15: 1762.56 | I15: =+C15/C14-1 -> 0 | J15: =+D15/D14-1 -> -0.16705744 | K15: =+E15/E14-1 -> -0.047169811 | L15: =+F15/F14-1 -> -0.041553134 | M15: =+G15/G14-1 -> -0.033451052 | O15: =+AVERAGE(I15:L15) -> -0.063945097 | Q15: =+Q14*(1+O15) -> 80.230358 | R15: =+R14*(1+M15) -> 109.04974 | T15: =+Q15/R15 -> 0.73572262 | V15: 38786 | W15: 66863.183 | X15: 9 | Y15: 16.3341 | Z15: 2415.2657 | AC15: =+SUMPRODUCT(I15:L15,W14:Z14)/SUM(W14:AA14) -> -0.0015454447 | AE15: =+AE14*(1+AC15) -> 96.622075 | AF15: =+AF14*(1+M15) -> 109.04974 | AH15: =+B15 -> 38786 | AI15: =+(AE15/$AE$6)/(AF15/$AF$6) -> 0.88603676
B16: 38793 | C16: 9.743 | D16: 1.374 | E16: 0.1 | F16: 1.421 | G16: 1810.63 | I16: =+C16/C15-1 -> -0.0087496185 | J16: =+D16/D15-1 -> -0.033075299 | K16: =+E16/E15-1 -> -0.0099009901 | L16: =+F16/F15-1 -> 0.0099502488 | M16: =+G16/G15-1 -> 0.02727283 | O16: =+AVERAGE(I16:L16) -> -0.010443915 | Q16: =+Q15*(1+O16) -> 79.392439 | R16: =+R15*(1+M16) -> 112.02383 | T16: =+Q16/R16 -> 0.70871026 | V16: 38793 | W16: 66273.214 | X16: 8.7 | Y16: 16.282 | Z16: 2439.1006 | AC16: =+SUMPRODUCT(I16:L16,W15:Z15)/SUM(W15:AA15) -> -0.0081013507 | AE16: =+AE15*(1+AC16) -> 95.839306 | AF16: =+AF15*(1+M16) -> 112.02383 | AH16: =+B16 -> 38793 | AI16: =+(AE16/$AE$6)/(AF16/$AF$6) -> 0.85552604
B17: 38800 | C17: 9.251 | D17: 1.327 | E17: 0.1 | F17: 1.375 | G17: 1794.12 | I17: =+C17/C16-1 -> -0.050497793 | J17: =+D17/D16-1 -> -0.034206696 | K17: =+E17/E16-1 -> 0 | L17: =+F17/F16-1 -> -0.032371569 | M17: =+G17/G16-1 -> -0.0091183732 | O17: =+AVERAGE(I17:L17) -> -0.029269015 | Q17: =+Q16*(1+O17) -> 77.068701 | R17: =+R16*(1+M17) -> 111.00236 | T17: =+Q17/R17 -> 0.69429787 | V17: 38800 | W17: 62930.055 | X17: 8.4 | Y17: 16.2038 | Z17: 2359.651 | AC17: =+SUMPRODUCT(I17:L17,W16:Z16)/SUM(W16:AA16) -> -0.049840572 | AE17: =+AE16*(1+AC17) -> 91.06262 | AF17: =+AF16*(1+M17) -> 111.00236 | AH17: =+B17 -> 38800 | AI17: =+(AE17/$AE$6)/(AF17/$AF$6) -> 0.82036655
B18: 38807 | C18: 9.251 | D18: 1.308 | E18: 0.098 | F18: 1.477 | G18: 1800.58 | I18: =+C18/C17-1 -> 0 | J18: =+D18/D17-1 -> -0.014318011 | K18: =+E18/E17-1 -> -0.02 | L18: =+F18/F17-1 -> 0.074181818 | M18: =+G18/G17-1 -> 0.003600651 | O18: =+AVERAGE(I18:L18) -> 0.0099659519 | Q18: =+Q17*(1+O18) -> 77.836764 | R18: =+R17*(1+M18) -> 111.40204 | T18: =+Q18/R18 -> 0.69870143 | V18: 38807 | W18: 62930.055 | X18: 8.28 | Y18: 15.8912 | Z18: 2534.44 | AC18: =+SUMPRODUCT(I18:L18,W17:Z17)/SUM(W17:AA17) -> 0.0026732098 | AE18: =+AE17*(1+AC18) -> 91.30605 | AF18: =+AF17*(1+M18) -> 111.40204 | AH18: =+B18 -> 38807 | AI18: =+(AE18/$AE$6)/(AF18/$AF$6) -> 0.81960843
... B57: 39080 | C57: 8.726 | D57: 2.179 | E57: 0.085 | F57: 1.94 | G57: 2090.46 | I57: =+C57/C56-1 -> 0.0069236095 | J57: =+D57/D56-1 -> 0.084619214 | K57: =+E57/E56-1 -> 0.1038961 | L57: =+F57/F56-1 -> 0.047516199 | M57: =+G57/G56-1 -> 0.016014503 | O57: =+AVERAGE(I57:L57) -> 0.060738781 | Q57: =+Q56*(1+O57) -> 102.11911 | R57: =+R56*(1+M57) -> 129.33694 | T57: =+Q57/R57 -> 0.78955876 | V57: 39080 | W57: 57030.362 | X57: 1025.8 | Y57: 13.8071 | Z57: 3328.9353 | AC57: =+SUMPRODUCT(I57:L57,W56:Z56)/SUM(W56:AA56) -> 0.010274979 | AE57: =+AE56*(1+AC57) -> 88.02287 | AF57: =+AF56*(1+M57) -> 129.33694 | AH57: =+B57 -> 39080 | AI57: =+(AE57/$AE$6)/(AF57/$AF$6) -> 0.68057023
B58: 39087 | C58: 8.425 | D58: 2.208 | E58: 0.085 | F58: 1.935 | G58: 2063.88 | I58: =+C58/C57-1 -> -0.034494614 | J58: =+D58/D57-1 -> 0.013308857 | K58: =+E58/E57-1 -> 0 | L58: =+F58/F57-1 -> -0.0025773196 | M58: =+G58/G57-1 -> -0.012714905 | O58: =+AVERAGE(I58:L58) -> -0.005940769 | Q58: =+Q57*(1+O58) -> 101.51245 | R58: =+R57*(1+M58) -> 127.69243 | T58: =+Q58/R58 -> 0.79497622 | V58: 39087 | W58: 55063.798 | X58: 1039.18 | Y58: 13.755 | Z58: 3320.9904 | AC58: =+SUMPRODUCT(I58:L58,W57:Z57)/SUM(W57:AA57) -> -0.031957701 | AE58: =+AE57*(1+AC58) -> 85.209861 | AF58: =+AF57*(1+M58) -> 127.69243 | AH58: =+B58 -> 39087 | AI58: =+(AE58/$AE$6)/(AF58/$AF$6) -> 0.6673055 | AJ58: =+_xlfn.PERCENTILE.INC(OFFSET(AI58,-52,0,52,1),0.1) -> 0.71001223 | AK58: =+_xlfn.PERCENTILE.INC(OFFSET(AI58,-52,0,52,1),0.25) -> 0.74192072 | AL58: =+_xlfn.PERCENTILE.INC(OFFSET(AI58,-52,0,52,1),0.5) -> 0.78237478 | AM58: =+_xlfn.PERCENTILE.INC(OFFSET(AI58,-52,0,52,1),0.75) -> 0.83320049 | AN58: =+_xlfn.PERCENTILE.INC(OFFSET(AI58,-52,0,52,1),0.9) -> 0.87902181
B59: 39094 | C59: 8.245 | D59: 2.189 | E59: 0.083 | F59: 1.972 | G59: 2072.62 | I59: =+C59/C58-1 -> -0.021364985 | J59: =+D59/D58-1 -> -0.0086050725 | K59: =+E59/E58-1 -> -0.023529412 | L59: =+F59/F58-1 -> 0.019121447 | M59: =+G59/G58-1 -> 0.0042347423 | O59: =+AVERAGE(I59:L59) -> -0.0085945056 | Q59: =+Q58*(1+O59) -> 100.64 | R59: =+R58*(1+M59) -> 128.23318 | T59: =+Q59/R59 -> 0.78482028 | V59: 39094 | W59: 53883.859 | X59: 1030.26 | Y59: 13.4164 | Z59: 3384.55 | AC59: =+SUMPRODUCT(I59:L59,W58:Z58)/SUM(W58:AA58) -> -0.018880282 | AE59: =+AE58*(1+AC59) -> 83.601075 | AF59: =+AF58*(1+M59) -> 128.23318 | AH59: =+B59 -> 39094 | AI59: =+(AE59/$AE$6)/(AF59/$AF$6) -> 0.65194576 | AJ59: =+_xlfn.PERCENTILE.INC(OFFSET(AI59,-52,0,52,1),0.1) -> 0.70576683 | AK59: =+_xlfn.PERCENTILE.INC(OFFSET(AI59,-52,0,52,1),0.25) -> 0.73891562 | AL59: =+_xlfn.PERCENTILE.INC(OFFSET(AI59,-52,0,52,1),0.5) -> 0.7775169 | AM59: =+_xlfn.PERCENTILE.INC(OFFSET(AI59,-52,0,52,1),0.75) -> 0.82309572 | AN59: =+_xlfn.PERCENTILE.INC(OFFSET(AI59,-52,0,52,1),0.9) -> 0.87800525
B60: 39101 | C60: 7.583 | D60: 2.113 | E60: 0.083 | F60: 1.944 | G60: 2037.32 | I60: =+C60/C59-1 -> -0.080291086 | J60: =+D60/D59-1 -> -0.03471905 | K60: =+E60/E59-1 -> 0 | L60: =+F60/F59-1 -> -0.014198783 | M60: =+G60/G59-1 -> -0.017031583 | O60: =+AVERAGE(I60:L60) -> -0.03230223 | Q60: =+Q59*(1+O60) -> 97.389101 | R60: =+R59*(1+M60) -> 126.04916 | T60: =+Q60/R60 -> 0.77262792 | V60: 39101 | W60: 49557.418 | X60: 994.58 | Y60: 13.4424 | Z60: 3336.8803 | AC60: =+SUMPRODUCT(I60:L60,W59:Z59)/SUM(W59:AA59) -> -0.075631315 | AE60: =+AE59*(1+AC60) -> 77.278216 | AF60: =+AF59*(1+M60) -> 126.04916 | AH60: =+B60 -> 39101 | AI60: =+(AE60/$AE$6)/(AF60/$AF$6) -> 0.61307997 | AJ60: =+_xlfn.PERCENTILE.INC(OFFSET(AI60,-52,0,52,1),0.1) -> 0.69982751 | AK60: =+_xlfn.PERCENTILE.INC(OFFSET(AI60,-52,0,52,1),0.25) -> 0.7307288 | AL60: =+_xlfn.PERCENTILE.INC(OFFSET(AI60,-52,0,52,1),0.5) -> 0.77320636 | AM60: =+_xlfn.PERCENTILE.INC(OFFSET(AI60,-52,0,52,1),0.75) -> 0.81979796 | AN60: =+_xlfn.PERCENTILE.INC(OFFSET(AI60,-52,0,52,1),0.9) -> 0.87287301
B61: 39108 | C61: 8.546 | D61: 2.244 | E61: 0.083 | F61: 1.898 | G61: 2039.46 | I61: =+C61/C60-1 -> 0.12699459 | J61: =+D61/D60-1 -> 0.06199716 | K61: =+E61/E60-1 -> 0 | L61: =+F61/F60-1 -> -0.023662551 | M61: =+G61/G60-1 -> 0.0010503995 | O61: =+AVERAGE(I61:L61) -> 0.041332301 | Q61: =+Q60*(1+O61) -> 101.41442 | R61: =+R60*(1+M61) -> 126.18156 | T61: =+Q61/R61 -> 0.80371818 | V61: 39108 | W61: 55850.424 | X61: 1030.26 | Y61: 13.4685 | Z61: 3257.4307 | AC61: =+SUMPRODUCT(I61:L61,W60:Z60)/SUM(W60:AA60) -> 0.11643703 | AE61: =+AE60*(1+AC61) -> 86.276262 | AF61: =+AF60*(1+M61) -> 126.18156 | AH61: =+B61 -> 39108 | AI61: =+(AE61/$AE$6)/(AF61/$AF$6) -> 0.68374697 | AJ61: =+_xlfn.PERCENTILE.INC(OFFSET(AI61,-52,0,52,1),0.1) -> 0.68591414 | AK61: =+_xlfn.PERCENTILE.INC(OFFSET(AI61,-52,0,52,1),0.25) -> 0.72895601 | AL61: =+_xlfn.PERCENTILE.INC(OFFSET(AI61,-52,0,52,1),0.5) -> 0.77269357 | AM61: =+_xlfn.PERCENTILE.INC(OFFSET(AI61,-52,0,52,1),0.75) -> 0.81382712 | AN61: =+_xlfn.PERCENTILE.INC(OFFSET(AI61,-52,0,52,1),0.9) -> 0.87055246
B62: 39115 | C62: 8.877 | D62: 2.254 | E62: 0.09 | F62: 1.88 | G62: 2081.27 | I62: =+C62/C61-1 -> 0.03873157 | J62: =+D62/D61-1 -> 0.004456328 | K62: =+E62/E61-1 -> 0.084337349 | L62: =+F62/F61-1 -> -0.009483667 | M62: =+G62/G61-1 -> 0.020500525 | O62: =+AVERAGE(I62:L62) -> 0.029510395 | Q62: =+Q61*(1+O62) -> 104.4072 | R62: =+R61*(1+M62) -> 128.76835 | T62: =+Q62/R62 -> 0.81081411 | V62: 39115 | W62: 58013.644 | X62: 1034.72 | Y62: 14.5887 | Z62: 3225.6509 | AC62: =+SUMPRODUCT(I62:L62,W61:Z61)/SUM(W61:AA61) -> 0.035543691 | AE62: =+AE61*(1+AC62) -> 89.342839 | AF62: =+AF61*(1+M62) -> 128.76835 | AH62: =+B62 -> 39115 | AI62: =+(AE62/$AE$6)/(AF62/$AF$6) -> 0.69382606 | AJ62: =+_xlfn.PERCENTILE.INC(OFFSET(AI62,-52,0,52,1),0.1) -> 0.68381594 | AK62: =+_xlfn.PERCENTILE.INC(OFFSET(AI62,-52,0,52,1),0.25) -> 0.72680631 | AL62: =+_xlfn.PERCENTILE.INC(OFFSET(AI62,-52,0,52,1),0.5) -> 0.76986176 | AM62: =+_xlfn.PERCENTILE.INC(OFFSET(AI62,-52,0,52,1),0.75) -> 0.80938704 | AN62: =+_xlfn.PERCENTILE.INC(OFFSET(AI62,-52,0,52,1),0.9) -> 0.85750372
B63: 39122 | C63: 8.413 | D63: 2.283 | E63: 0.085 | F63: 1.833 | G63: 2100.24 | I63: =+C63/C62-1 -> -0.052269911 | J63: =+D63/D62-1 -> 0.012866016 | K63: =+E63/E62-1 -> -0.055555556 | L63: =+F63/F62-1 -> -0.025 | M63: =+G63/G62-1 -> 0.0091146271 | O63: =+AVERAGE(I63:L63) -> -0.029989863 | Q63: =+Q62*(1+O63) -> 101.27604 | R63: =+R62*(1+M63) -> 129.94203 | T63: =+Q63/R63 -> 0.77939402 | V63: 39122 | W63: 54985.135 | X63: 1048.1 | Y63: 13.8592 | Z63: 3146.2014 | AC63: =+SUMPRODUCT(I63:L63,W62:Z62)/SUM(W62:AA62) -> -0.049776474 | AE63: =+AE62*(1+AC63) -> 84.895667 | AF63: =+AF62*(1+M63) -> 129.94203 | AH63: =+B63 -> 39122 | AI63: =+(AE63/$AE$6)/(AF63/$AF$6) -> 0.65333494 | AJ63: =+_xlfn.PERCENTILE.INC(OFFSET(AI63,-52,0,52,1),0.1) -> 0.68381594 | AK63: =+_xlfn.PERCENTILE.INC(OFFSET(AI63,-52,0,52,1),0.25) -> 0.72409201 | AL63: =+_xlfn.PERCENTILE.INC(OFFSET(AI63,-52,0,52,1),0.5) -> 0.76706529 | AM63: =+_xlfn.PERCENTILE.INC(OFFSET(AI63,-52,0,52,1),0.75) -> 0.80535672 | AN63: =+_xlfn.PERCENTILE.INC(OFFSET(AI63,-52,0,52,1),0.9) -> 0.85448317
B64: 39129 | C64: 8.154 | D64: 2.273 | E64: 0.089 | F64: 1.921 | G64: 2145.49 | I64: =+C64/C63-1 -> -0.030785689 | J64: =+D64/D63-1 -> -0.0043802015 | K64: =+E64/E63-1 -> 0.047058824 | L64: =+F64/F63-1 -> 0.048008729 | M64: =+G64/G63-1 -> 0.021545157 | O64: =+AVERAGE(I64:L64) -> 0.014975416 | Q64: =+Q63*(1+O64) -> 102.79269 | R64: =+R63*(1+M64) -> 132.74165 | T64: =+Q64/R64 -> 0.77438159 | V64: 39129 | W64: 53293.89 | X64: 2447.64 | Y64: 14.4584 | Z64: 3297.1555 | AC64: =+SUMPRODUCT(I64:L64,W63:Z63)/SUM(W63:AA63) -> -0.02611189 | AE64: =+AE63*(1+AC64) -> 82.678881 | AF64: =+AF63*(1+M64) -> 132.74165 | AH64: =+B64 -> 39129 | AI64: =+(AE64/$AE$6)/(AF64/$AF$6) -> 0.62285561 | AJ64: =+_xlfn.PERCENTILE.INC(OFFSET(AI64,-52,0,52,1),0.1) -> 0.6808879 | AK64: =+_xlfn.PERCENTILE.INC(OFFSET(AI64,-52,0,52,1),0.25) -> 0.72098353 | AL64: =+_xlfn.PERCENTILE.INC(OFFSET(AI64,-52,0,52,1),0.5) -> 0.7657852 | AM64: =+_xlfn.PERCENTILE.INC(OFFSET(AI64,-52,0,52,1),0.75) -> 0.80359265 | AN64: =+_xlfn.PERCENTILE.INC(OFFSET(AI64,-52,0,52,1),0.9) -> 0.84448277
B65: 39136 | C65: 8.124 | D65: 2.497 | E65: 0.092 | F65: 1.907 | G65: 2202.45 | I65: =+C65/C64-1 -> -0.0036791759 | J65: =+D65/D64-1 -> 0.098548174 | K65: =+E65/E64-1 -> 0.033707865 | L65: =+F65/F64-1 -> -0.0072878709 | M65: =+G65/G64-1 -> 0.026548714 | O65: =+AVERAGE(I65:L65) -> 0.030322248 | Q65: =+Q64*(1+O65) -> 105.9096 | R65: =+R64*(1+M65) -> 136.26577 | T65: =+Q65/R65 -> 0.77722818 | V65: 39136 | W65: 53097.234 | X65: 2688.22 | Y65: 14.9273 | Z65: 3273.3206 | AC65: =+SUMPRODUCT(I65:L65,W64:Z64)/SUM(W64:AA64) -> 0.00036561943 | AE65: =+AE64*(1+AC65) -> 82.70911 | AF65: =+AF64*(1+M65) -> 136.26577 | AH65: =+B65 -> 39136 | AI65: =+(AE65/$AE$6)/(AF65/$AF$6) -> 0.60696909 | AJ65: =+_xlfn.PERCENTILE.INC(OFFSET(AI65,-52,0,52,1),0.1) -> 0.68034907 | AK65: =+_xlfn.PERCENTILE.INC(OFFSET(AI65,-52,0,52,1),0.25) -> 0.71448068 | AL65: =+_xlfn.PERCENTILE.INC(OFFSET(AI65,-52,0,52,1),0.5) -> 0.76142799 | AM65: =+_xlfn.PERCENTILE.INC(OFFSET(AI65,-52,0,52,1),0.75) -> 0.80252106 | AN65: =+_xlfn.PERCENTILE.INC(OFFSET(AI65,-52,0,52,1),0.9) -> 0.83818537
B66: 39143 | C66: 7.974 | D66: 2.264 | E66: 0.081 | F66: 1.829 | G66: 1997.64 | I66: =+C66/C65-1 -> -0.018463811 | J66: =+D66/D65-1 -> -0.093311974 | K66: =+E66/E65-1 -> -0.11956522 | L66: =+F66/F65-1 -> -0.04090194 | M66: =+G66/G65-1 -> -0.092991895 | O66: =+AVERAGE(I66:L66) -> -0.068060736 | Q66: =+Q65*(1+O66) -> 98.70131 | R66: =+R65*(1+M66) -> 123.59416 | T66: =+Q66/R66 -> 0.79859204 | V66: 39143 | W66: 52113.952 | X66: 2437.18 | Y66: 13.208 | Z66: 3138.2564 | AC66: =+SUMPRODUCT(I66:L66,W65:Z65)/SUM(W65:AA65) -> -0.023138729 | AE66: =+AE65*(1+AC66) -> 80.795326 | AF66: =+AF65*(1+M66) -> 123.59416 | AH66: =+B66 -> 39143 | AI66: =+(AE66/$AE$6)/(AF66/$AF$6) -> 0.65371477 | AJ66: =+_xlfn.PERCENTILE.INC(OFFSET(AI66,-52,0,52,1),0.1) -> 0.6686074 | AK66: =+_xlfn.PERCENTILE.INC(OFFSET(AI66,-52,0,52,1),0.25) -> 0.70833646 | AL66: =+_xlfn.PERCENTILE.INC(OFFSET(AI66,-52,0,52,1),0.5) -> 0.75821839 | AM66: =+_xlfn.PERCENTILE.INC(OFFSET(AI66,-52,0,52,1),0.75) -> 0.80062194 | AN66: =+_xlfn.PERCENTILE.INC(OFFSET(AI66,-52,0,52,1),0.9) -> 0.83019156
B67: 39150 | C67: 8.365 | D67: 2.312 | E67: 0.08 | F67: 1.829 | G67: 2036.46 | I67: =+C67/C66-1 -> 0.049034362 | J67: =+D67/D66-1 -> 0.021201413 | K67: =+E67/E66-1 -> -0.012345679 | L67: =+F67/F66-1 -> 0 | M67: =+G67/G66-1 -> 0.019432931 | O67: =+AVERAGE(I67:L67) -> 0.014472524 | Q67: =+Q66*(1+O67) -> 100.12977 | R67: =+R66*(1+M67) -> 125.99595 | T67: =+Q67/R67 -> 0.79470621 | V67: 39150 | W67: 54670.485 | X67: 2489.48 | Y67: 12.9214 | Z67: 3138.2564 | AC67: =+SUMPRODUCT(I67:L67,W66:Z66)/SUM(W66:AA66) -> 0.045177915 | AE67: =+AE66*(1+AC67) -> 84.445491 | AF67: =+AF66*(1+M67) -> 125.99595 | AH67: =+B67 -> 39150 | AI67: =+(AE67/$AE$6)/(AF67/$AF$6) -> 0.67022383 | AJ67: =+_xlfn.PERCENTILE.INC(OFFSET(AI67,-52,0,52,1),0.1) -> 0.65507385 | AK67: =+_xlfn.PERCENTILE.INC(OFFSET(AI67,-52,0,52,1),0.25) -> 0.70383151 | AL67: =+_xlfn.PERCENTILE.INC(OFFSET(AI67,-52,0,52,1),0.5) -> 0.75789882 | AM67: =+_xlfn.PERCENTILE.INC(OFFSET(AI67,-52,0,52,1),0.75) -> 0.79831046 | AN67: =+_xlfn.PERCENTILE.INC(OFFSET(AI67,-52,0,52,1),0.9) -> 0.82029073
B68: 39157 | C68: 7.991 | D68: 2.234 | E68: 0.085 | F68: 1.759 | G68: 1985.79 | I68: =+C68/C67-1 -> -0.044710102 | J68: =+D68/D67-1 -> -0.033737024 | K68: =+E68/E67-1 -> 0.0625 | L68: =+F68/F67-1 -> -0.03827228 | M68: =+G68/G67-1 -> -0.024881412 | O68: =+AVERAGE(I68:L68) -> -0.013554851 | Q68: =+Q67*(1+O68) -> 98.772523 | R68: =+R67*(1+M68) -> 122.861 | T68: =+Q68/R68 -> 0.80393718 | V68: 39157 | W68: 49872.068 | X68: 2405.8 | Y68: 13.7811 | Z68: 3019.0821 | AC68: =+SUMPRODUCT(I68:L68,W67:Z67)/SUM(W67:AA67) -> -0.043899205 | AE68: =+AE67*(1+AC68) -> 80.738401 | AF68: =+AF67*(1+M68) -> 122.861 | AH68: =+B68 -> 39157 | AI68: =+(AE68/$AE$6)/(AF68/$AF$6) -> 0.65715242 | AJ68: =+_xlfn.PERCENTILE.INC(OFFSET(AI68,-52,0,52,1),0.1) -> 0.65507385 | AK68: =+_xlfn.PERCENTILE.INC(OFFSET(AI68,-52,0,52,1),0.25) -> 0.69786515 | AL68: =+_xlfn.PERCENTILE.INC(OFFSET(AI68,-52,0,52,1),0.5) -> 0.75444109 | AM68: =+_xlfn.PERCENTILE.INC(OFFSET(AI68,-52,0,52,1),0.75) -> 0.78864389 | AN68: =+_xlfn.PERCENTILE.INC(OFFSET(AI68,-52,0,52,1),0.9) -> 0.81883759
B69: 39164 | C69: 8.035 | D69: 2.312 | E69: 0.088 | F69: 1.81 | G69: 2085.51 | I69: =+C69/C68-1 -> 0.0055061945 | J69: =+D69/D68-1 -> 0.034914951 | K69: =+E69/E68-1 -> 0.035294118 | L69: =+F69/F68-1 -> 0.028993746 | M69: =+G69/G68-1 -> 0.05021679 | O69: =+AVERAGE(I69:L69) -> 0.026177252 | Q69: =+Q68*(1+O69) -> 101.35812 | R69: =+R68*(1+M69) -> 129.03068 | T69: =+Q69/R69 -> 0.785535 | V69: 39164 | W69: 50147.387 | X69: 2489.48 | Y69: 14.3542 | Z69: 3106.4766 | AC69: =+SUMPRODUCT(I69:L69,W68:Z68)/SUM(W68:AA68) -> 0.008074827 | AE69: =+AE68*(1+AC69) -> 81.390349 | AF69: =+AF68*(1+M69) -> 129.03068 | AH69: =+B69 -> 39164 | AI69: =+(AE69/$AE$6)/(AF69/$AF$6) -> 0.63078292 | AJ69: =+_xlfn.PERCENTILE.INC(OFFSET(AI69,-52,0,52,1),0.1) -> 0.65405854 | AK69: =+_xlfn.PERCENTILE.INC(OFFSET(AI69,-52,0,52,1),0.25) -> 0.69147871 | AL69: =+_xlfn.PERCENTILE.INC(OFFSET(AI69,-52,0,52,1),0.5) -> 0.74725333 | AM69: =+_xlfn.PERCENTILE.INC(OFFSET(AI69,-52,0,52,1),0.75) -> 0.78396091 | AN69: =+_xlfn.PERCENTILE.INC(OFFSET(AI69,-52,0,52,1),0.9) -> 0.81156495
... B1089: 46304 | C1089: 8065 | D1089: 5190 | E1089: 39.01 | F1089: 8340 | G1089: 2828027 | I1089: =+C1089/C1088-1 -> 0.001863354 | J1089: =+D1089/D1088-1 -> 0.043740573 | K1089: =+E1089/E1088-1 -> 0.0012833676 | L1089: =+F1089/F1088-1 -> 0.028994448 | M1089: =+G1089/G1088-1 -> 0.021810459 | O1089: =+AVERAGE(I1089:L1089) -> 0.018970436 | Q1089: =+Q1088*(1+O1089) -> 369640.9 | R1089: =+R1088*(1+M1089) -> 174970.27 | T1089: =+Q1089/R1089 -> 2.1125926 | V1089: 46304 | W1089: 31724855 | X1089: 7076670.8 | Y1089: 273070 | Z1089: 6626090.7 | AC1089: =+SUMPRODUCT(I1089:L1089,W1088:Z1088)/SUM(W1088:AA1088) -> 0.012016166 | AE1089: =+AE1088*(1+AC1089) -> 106021.84 | AF1089: =+AF1088*(1+M1089) -> 174970.27 | AH1089: =+B1089 -> 46304 | AI1089: =+(AE1089/$AE$6)/(AF1089/$AF$6) -> 0.60594202 | AJ1089: =+_xlfn.PERCENTILE.INC(OFFSET(AI1089,-52,0,52,1),0.1) -> 0.45138735 | AK1089: =+_xlfn.PERCENTILE.INC(OFFSET(AI1089,-52,0,52,1),0.25) -> 0.46524869 | AL1089: =+_xlfn.PERCENTILE.INC(OFFSET(AI1089,-52,0,52,1),0.5) -> 0.50603741 | AM1089: =+_xlfn.PERCENTILE.INC(OFFSET(AI1089,-52,0,52,1),0.75) -> 0.54684479 | AN1089: =+_xlfn.PERCENTILE.INC(OFFSET(AI1089,-52,0,52,1),0.9) -> 0.58664796

Sheet crack spread y Brent_WTI
A1: =+AVERAGE(B4:B5000) -> 12.990308 | B1: =+_xlfn.STDEV.S(B4:B5000) -> 10.959003
J2: Brent | K2: WTI
A3: Dates | B3: Crack Spread | C3: ZSPREAD | D3: YoY | I3: Dates | J3: CO1 Comdty | K3: CL1 COMB Comdty | L3: BRENT/WTI
A4: =_xll.BDH("CRK321M1 Index", "PX_LAST","1987-01-01", "", "Per=M","cols=2;rows=477") -> 31807 | B4: 3.002 | C4: =+(B4-$A$1)/$B$1 -> -0.91142492 | I4: =_xll.BDH(J$3,"PX_LAST","1990-12-28","","Dir=V","Per=M","Days=A","Dts=S","cols=2;rows=430") -> 33238 | J4: 28.27 | K4: =_xll.BDH(K$3,"PX_LAST","1990-12-28","","Dir=V","Per=M","Days=A","Dts=H","cols=1;rows=430") -> 28.44 | L4: =+J4/K4 -> 0.9940225
A5: 31835 | B5: 2.738 | C5: =+(B5-$A$1)/$B$1 -> -0.9355147 | I5: 33269 | J5: 20.06 | K5: 21.54 | L5: =+J5/K5 -> 0.93129062
A6: 31867 | B6: 3.126 | C6: =+(B6-$A$1)/$B$1 -> -0.90011002 | I6: 33297 | J6: 18.68 | K6: 19.16 | L6: =+J6/K6 -> 0.97494781
A7: 31897 | B7: 2.747 | C7: =+(B7-$A$1)/$B$1 -> -0.93469346 | I7: 33326 | J7: 18.17 | K7: 19.63 | L7: =+J7/K7 -> 0.92562404
A8: 31926 | B8: 2.978 | C8: =+(B8-$A$1)/$B$1 -> -0.9136149 | I8: 33358 | J8: 19.42 | K8: 20.96 | L8: =+J8/K8 -> 0.92652672
A9: 31958 | B9: 2.676 | C9: =+(B9-$A$1)/$B$1 -> -0.94117215 | I9: 33389 | J9: 19.21 | K9: 21.13 | L9: =+J9/K9 -> 0.90913393
A10: 31989 | B10: 1.743 | C10: =+(B10-$A$1)/$B$1 -> -1.0263076 | I10: 33417 | J10: 18.72 | K10: 20.56 | L10: =+J10/K10 -> 0.91050584
A11: 32020 | B11: 1.673 | C11: =+(B11-$A$1)/$B$1 -> -1.0326951 | I11: 33450 | J11: 19.74 | K11: 21.68 | L11: =+J11/K11 -> 0.91051661
A12: 32050 | B12: 2.242 | C12: =+(B12-$A$1)/$B$1 -> -0.9807743 | I12: 33480 | J12: 20.7 | K12: 22.26 | L12: =+J12/K12 -> 0.92991914
A13: 32080 | B13: 2.756 | C13: =+(B13-$A$1)/$B$1 -> -0.93387222 | I13: 33511 | J13: 21.05 | K13: 22.23 | L13: =+J13/K13 -> 0.94691858
A14: 32111 | B14: 2.766 | C14: =+(B14-$A$1)/$B$1 -> -0.93295973 | I14: 33542 | J14: 22.1 | K14: 23.37 | L14: =+J14/K14 -> 0.94565682
A15: 32142 | B15: 2.568 | C15: =+(B15-$A$1)/$B$1 -> -0.95102706 | I15: 33571 | J15: 20.13 | K15: 21.48 | L15: =+J15/K15 -> 0.93715084
A16: 32171 | B16: 2.527 | C16: =+(B16-$A$1)/$B$1 -> -0.95476828 | D16: =+B16/B4-1 -> -0.15822785 | I16: 33603 | J16: 17.61 | K16: 19.12 | L16: =+J16/K16 -> 0.9210251
A17: 32202 | B17: 3.163 | C17: =+(B17-$A$1)/$B$1 -> -0.8967338 | D17: =+B17/B5-1 -> 0.15522279 | I17: 33634 | J17: 18.15 | K17: 18.9 | L17: =+J17/K17 -> 0.96031746
A18: 32233 | B18: 3.207 | C18: =+(B18-$A$1)/$B$1 -> -0.89271884 | D18: =+B18/B6-1 -> 0.025911708 | I18: 33662 | J18: 17.55 | K18: 18.68 | L18: =+J18/K18 -> 0.93950749
A19: 32262 | B19: 3.233 | C19: =+(B19-$A$1)/$B$1 -> -0.89034636 | D19: =+B19/B7-1 -> 0.17692028 | I19: 33694 | J19: 18.14 | K19: 19.44 | L19: =+J19/K19 -> 0.93312757
A20: 32294 | B20: 3.504 | C20: =+(B20-$A$1)/$B$1 -> -0.86561783 | D20: =+B20/B8-1 -> 0.17662861 | I20: 33724 | J20: 19.66 | K20: 20.85 | L20: =+J20/K20 -> 0.94292566
A21: 32324 | B21: 4.048 | C21: =+(B21-$A$1)/$B$1 -> -0.81597828 | D21: =+B21/B9-1 -> 0.51270553 | I21: 33753 | J21: 20.79 | K21: 22.11 | L21: =+J21/K21 -> 0.94029851
A22: 32353 | B22: 3.48 | C22: =+(B22-$A$1)/$B$1 -> -0.86780781 | D22: =+B22/B10-1 -> 0.99655766 | I22: 33785 | J22: 20.41 | K22: 21.6 | L22: =+J22/K22 -> 0.94490741
A23: 32386 | B23: 3.303 | C23: =+(B23-$A$1)/$B$1 -> -0.88395892 | D23: =+B23/B11-1 -> 0.97429767 | I23: 33816 | J23: 20.47 | K23: 21.87 | L23: =+J23/K23 -> 0.93598537
A24: 32416 | B24: 3.877 | C24: =+(B24-$A$1)/$B$1 -> -0.83158189 | D24: =+B24/B12-1 -> 0.72925959 | I24: 33847 | J24: 19.87 | K24: 21.48 | L24: =+J24/K24 -> 0.92504655
