Workbook

Sheet Indice Bancos
B2: Start Date | C2: 42736
B3: End Date
I4: Retornos | O4: Ret EW | Q4: Indice EW | T4: Bancos / Merval | V4: Mkt Cap | AB4: Ret MktCap W | AD4: Indice MktCap W | AG4: Ratio Bancos y percentiles | AO4: Ratio Bancos/Utilities | AX4: =+MEDIAN(AX6:AX505) -> 0.74455845 | AY4: =+MEDIAN(AY6:AY505) -> 0.93037466 | AZ4: =+MEDIAN(AZ6:AZ505) -> 1.2733384 | BA4: =+MEDIAN(BA6:BA505) -> 0.58231214
B5: Dates | C5: BBAR AR Equity | D5: BMA AR Equity | E5: GGAL AR Equity | F5: SUPV AR Equity | G5: MERVAL Index | I5: =+C5 -> BBAR AR Equity | J5: =+D5 -> BMA AR Equity | K5: =+E5 -> GGAL AR Equity | L5: =+F5 -> SUPV AR Equity | M5: =+G5 -> MERVAL Index | Q5: Indice | R5: Merval | V5: Dates | W5: BBAR AR Equity | X5: BMA AR Equity | Y5: GGAL AR Equity | Z5: SUPV AR Equity | AD5: Indice | AE5: Merval | AG5: Fecha | AH5: Ratio | AI5: Q10 | AJ5: Q25 | AK5: Q50 | AL5: Q75 | AM5: Q90 | AO5: Fecha | AP5: Ratio | AQ5: Q10 | AR5: Q25 | AS5: Q50 | AT5: Q75 | AU5: Q90 | AX5: =+C5 -> BBAR AR Equity | AY5: =+D5 -> BMA AR Equity | AZ5: =+E5 -> GGAL AR Equity | BA5: =+F5 -> SUPV AR Equity
B6: =_xll.BDH(C$5,"PX_LAST",$C2,$C3,"Dir=V","Per=W","Days=A","Dts=S","cols=2;rows=510") -> 42741 | C6: 63.307 | D6: =_xll.BDH(D$5,"PX_LAST",$C2,$C3,"Dir=V","Per=W","Days=A","Dts=H","cols=1;rows=510") -> 77.584 | E6: =_xll.BDH(E$5,"PX_LAST",$C2,$C3,"Dir=V","Per=W","Days=A","Dts=H","cols=1;rows=510") -> 33.21 | F6: =_xll.BDH(F$5,"PX_LAST",$C2,$C3,"Dir=V","Per=W","Days=A","Dts=H","cols=1;rows=510") -> 39.188 | G6: =_xll.BDH(G$5,"PX_LAST",$C2,$C3,"Dir=V","Per=W","Days=A","Dts=H","cols=1;rows=510") -> 18284.28 | Q6: 100 | R6: 100 | T6: =+Q6/R6 -> 1 | V6: =_xll.BDH(W$5,"CUR_MKT_CAP",$C2,$C3,"Dir=V","Per=W","Days=A","Dts=S","cols=2;rows=510") -> 42741 | W6: 53016.69 | X6: =_xll.BDH(X$5,"CUR_MKT_CAP",$C2,$C3,"Dir=V","Per=W","Days=A","Dts=H","cols=1;rows=510") -> 66464.813 | Y6: =_xll.BDH(Y$5,"CUR_MKT_CAP",$C2,$C3,"Dir=V","Per=W","Days=A","Dts=H","cols=1;rows=510") -> 60787.371 | Z6: =_xll.BDH(Z$5,"PX_LAST",$C2,$C3,"Dir=V","Per=W","Days=A","Dts=H","cols=1;rows=510") -> 39.188 | AD6: 100 | AE6: 100 | AG6: =+B6 -> 42741 | AH6: =+(AD6/$AD$6)/(AE6/$AE$6) -> 1 | AO6: =+AG6 -> 42741 | AP6: =AD6/VLOOKUP(AO6,'[1]Indice Utilities'!$Z:$AJ,11,0) -> 1 | AX6: =+(C6/$C$6)/(AD6/$AD$6) -> 1 | AY6: =+(D6/$D$6)/(AD6/$AD$6) -> 1 | AZ6: =+(E6/$E$6)/(AD6/$AD$6) -> 1 | BA6: =+(F6/$F$6)/(AD6/$AD$6) -> 1
B7: 42748 | C7: 61.416 | D7: 78.471 | E7: 35.234 | F7: 40.295 | G7: 18885.09 | I7: =+C7/C6-1 -> -0.029870314 | J7: =+D7/D6-1 -> 0.01143277 | K7: =+E7/E6-1 -> 0.060945498 | L7: =+F7/F6-1 -> 0.028248443 | M7: =+G7/G6-1 -> 0.032859374 | O7: =+AVERAGE(I7:L7) -> 0.017689099 | Q7: =+Q6*(1+O7) -> 101.76891 | R7: =+R6*(1+M7) -> 103.28594 | T7: =+Q7/R7 -> 0.98531235 | V7: 42748 | W7: 51432.9 | X7: 67224.745 | Y7: 64493.125 | Z7: 40.295 | AB7: =+SUMPRODUCT(I7:L7,W6:Z6)/SUM(W6:Z6) -> 0.015984173 | AD7: =+AD6*(1+AB7) -> 101.59842 | AE7: =+AE6*(1+M7) -> 103.28594 | AG7: =+B7 -> 42748 | AH7: =+(AD7/$AD$6)/(AE7/$AE$6) -> 0.98366167 | AO7: =+AG7 -> 42748 | AP7: =AD7/VLOOKUP(AO7,'[1]Indice Utilities'!$Z:$AJ,11,0) -> 0.99789024 | AX7: =+(C7/$C$6)/(AD7/$AD$6) -> 0.95486693 | AY7: =+(D7/$D$6)/(AD7/$AD$6) -> 0.9955202 | AZ7: =+(E7/$E$6)/(AD7/$AD$6) -> 1.044254 | BA7: =+(F7/$F$6)/(AD7/$AD$6) -> 1.0120713
B8: 42755 | C8: 60.903 | D8: 80.996 | E8: 36.655 | F8: 39.852 | G8: 19039.49 | I8: =+C8/C7-1 -> -0.0083528722 | J8: =+D8/D7-1 -> 0.032177492 | K8: =+E8/E7-1 -> 0.040330363 | L8: =+F8/F7-1 -> -0.01099392 | M8: =+G8/G7-1 -> 0.0081757619 | O8: =+AVERAGE(I8:L8) -> 0.013290266 | Q8: =+Q7*(1+O8) -> 103.12145 | R8: =+R7*(1+M8) -> 104.13038 | T8: =+Q8/R8 -> 0.99031087 | V8: 42755 | W8: 51003.397 | X8: 69387.628 | Y8: 67093.654 | Z8: 39.852 | AB8: =+SUMPRODUCT(I8:L8,W7:Z7)/SUM(W7:Z7) -> 0.023658902 | AD8: =+AD7*(1+AB8) -> 104.00212 | AE8: =+AE7*(1+M8) -> 104.13038 | AG8: =+B8 -> 42755 | AH8: =+(AD8/$AD$6)/(AE8/$AE$6) -> 0.99876833 | AO8: =+AG8 -> 42755 | AP8: =AD8/VLOOKUP(AO8,'[1]Indice Utilities'!$Z:$AJ,11,0) -> 1.0278182 | AX8: =+(C8/$C$6)/(AD8/$AD$6) -> 0.92500641 | AY8: =+(D8/$D$6)/(AD8/$AD$6) -> 1.0038046 | AZ8: =+(E8/$E$6)/(AD8/$AD$6) -> 1.0612608 | BA8: =+(F8/$F$6)/(AD8/$AD$6) -> 0.97781076
B9: 42762 | C9: 64.044 | D9: 83.214 | E9: 35.234 | F9: 39.941 | G9: 19215.78 | I9: =+C9/C8-1 -> 0.051573814 | J9: =+D9/D8-1 -> 0.027384068 | K9: =+E9/E8-1 -> -0.03876688 | L9: =+F9/F8-1 -> 0.0022332631 | M9: =+G9/G8-1 -> 0.0092591766 | O9: =+AVERAGE(I9:L9) -> 0.010606066 | Q9: =+Q8*(1+O9) -> 104.21516 | R9: =+R8*(1+M9) -> 105.09454 | T9: =+Q9/R9 -> 0.99163247 | V9: 42762 | W9: 53634.099 | X9: 71287.458 | Y9: 64493.125 | Z9: 39.941 | AB9: =+SUMPRODUCT(I9:L9,W8:Z8)/SUM(W8:Z8) -> 0.010290028 | AD9: =+AD8*(1+AB9) -> 105.07231 | AE9: =+AE8*(1+M9) -> 105.09454 | AG9: =+B9 -> 42762 | AH9: =+(AD9/$AD$6)/(AE9/$AE$6) -> 0.99978846 | AO9: =+AG9 -> 42762 | AP9: =AD9/VLOOKUP(AO9,'[1]Indice Utilities'!$Z:$AJ,11,0) -> 1.033909 | AX9: =+(C9/$C$6)/(AD9/$AD$6) -> 0.96280523 | AY9: =+(D9/$D$6)/(AD9/$AD$6) -> 1.0207889 | AZ9: =+(E9/$E$6)/(AD9/$AD$6) -> 1.0097289 | BA9: =+(F9/$F$6)/(AD9/$AD$6) -> 0.97001301
B10: 42769 | C10: 64.076 | D10: 81.951 | E10: 35.909 | F10: 39.764 | G10: 19200.5 | I10: =+C10/C9-1 -> 0.00049965649 | J10: =+D10/D9-1 -> -0.015177735 | K10: =+E10/E9-1 -> 0.019157632 | L10: =+F10/F9-1 -> -0.0044315365 | M10: =+G10/G9-1 -> -0.00079517979 | O10: =+AVERAGE(I10:L10) -> 1.2004322e-05 | Q10: =+Q9*(1+O10) -> 104.21641 | R10: =+R9*(1+M10) -> 105.01097 | T10: =+Q10/R10 -> 0.99243354 | V10: 42769 | W10: 53660.943 | X10: 70206.016 | Y10: 65728.376 | Z10: 39.764 | AB10: =+SUMPRODUCT(I10:L10,W9:Z9)/SUM(W9:Z9) -> 0.00095101959 | AD10: =+AD9*(1+AB10) -> 105.17223 | AE10: =+AE9*(1+M10) -> 105.01097 | AG10: =+B10 -> 42769 | AH10: =+(AD10/$AD$6)/(AE10/$AE$6) -> 1.0015357 | AO10: =+AG10 -> 42769 | AP10: =AD10/VLOOKUP(AO10,'[1]Indice Utilities'!$Z:$AJ,11,0) -> 0.95731998 | AX10: =+(C10/$C$6)/(AD10/$AD$6) -> 0.96237106 | AY10: =+(D10/$D$6)/(AD10/$AD$6) -> 1.0043405 | AZ10: =+(E10/$E$6)/(AD10/$AD$6) -> 1.0280952 | BA10: =+(F10/$F$6)/(AD10/$AD$6) -> 0.96479682
B11: 42776 | C11: 65.326 | D11: 89.389 | E11: 39.035 | F11: 40.295 | G11: 19502.93 | I11: =+C11/C10-1 -> 0.019508084 | J11: =+D11/D10-1 -> 0.090761553 | K11: =+E11/E10-1 -> 0.087053385 | L11: =+F11/F10-1 -> 0.013353787 | M11: =+G11/G10-1 -> 0.015751152 | O11: =+AVERAGE(I11:L11) -> 0.052669202 | Q11: =+Q10*(1+O11) -> 109.7054 | R11: =+R10*(1+M11) -> 106.66501 | T11: =+Q11/R11 -> 1.0285041 | V11: 42776 | W11: 54707.855 | X11: 76577.753 | Y11: 71449.541 | Z11: 40.295 | AB11: =+SUMPRODUCT(I11:L11,W10:Z10)/SUM(W10:Z10) -> 0.069297498 | AD11: =+AD10*(1+AB11) -> 112.46041 | AE11: =+AE10*(1+M11) -> 106.66501 | AG11: =+B11 -> 42776 | AH11: =+(AD11/$AD$6)/(AE11/$AE$6) -> 1.0543326 | AO11: =+AG11 -> 42776 | AP11: =AD11/VLOOKUP(AO11,'[1]Indice Utilities'!$Z:$AJ,11,0) -> 1.0232508 | AX11: =+(C11/$C$6)/(AD11/$AD$6) -> 0.91756044 | AY11: =+(D11/$D$6)/(AD11/$AD$6) -> 1.0245007 | AZ11: =+(E11/$E$6)/(AD11/$AD$6) -> 1.0451669 | BA11: =+(F11/$F$6)/(AD11/$AD$6) -> 0.9143204
B12: 42783 | C12: 62.826 | D12: 85.977 | E12: 38.502 | F12: 43.395 | G12: 19681.34 | I12: =+C12/C11-1 -> -0.038269602 | J12: =+D12/D11-1 -> -0.038170245 | K12: =+E12/E11-1 -> -0.013654413 | L12: =+F12/F11-1 -> 0.076932622 | M12: =+G12/G11-1 -> 0.0091478562 | O12: =+AVERAGE(I12:L12) -> -0.0032904093 | Q12: =+Q11*(1+O12) -> 109.34443 | R12: =+R11*(1+M12) -> 107.64077 | T12: =+Q12/R12 -> 1.0158273 | V12: 42783 | W12: 52614.031 | X12: 73654.938 | Y12: 70474.342 | Z12: 43.395 | AB12: =+SUMPRODUCT(I12:L12,W11:Z11)/SUM(W11:Z11) -> -0.029535829 | AD12: =+AD11*(1+AB12) -> 109.1388 | AE12: =+AE11*(1+M12) -> 107.64077 | AG12: =+B12 -> 42783 | AH12: =+(AD12/$AD$6)/(AE12/$AE$6) -> 1.0139169 | AO12: =+AG12 -> 42783 | AP12: =AD12/VLOOKUP(AO12,'[1]Indice Utilities'!$Z:$AJ,11,0) -> 0.98507567 | AX12: =+(C12/$C$6)/(AD12/$AD$6) -> 0.90930278 | AY12: =+(D12/$D$6)/(AD12/$AD$6) -> 1.0153855 | AZ12: =+(E12/$E$6)/(AD12/$AD$6) -> 1.0622708 | BA12: =+(F12/$F$6)/(AD12/$AD$6) -> 1.0146294
B13: 42790 | C13: 59.3 | D13: 84.783 | E13: 36.016 | F13: 42.509 | G13: 19117.45 | I13: =+C13/C12-1 -> -0.056123261 | J13: =+D13/D12-1 -> -0.013887435 | K13: =+E13/E12-1 -> -0.064568074 | L13: =+F13/F12-1 -> -0.020417099 | M13: =+G13/G12-1 -> -0.028650996 | O13: =+AVERAGE(I13:L13) -> -0.038748967 | Q13: =+Q12*(1+O13) -> 105.10745 | R13: =+R12*(1+M13) -> 104.55676 | T13: =+Q13/R13 -> 1.0052669 | V13: 42790 | W13: 49661.203 | X13: 72631.953 | Y13: 65923.416 | Z13: 42.509 | AB13: =+SUMPRODUCT(I13:L13,W12:Z12)/SUM(W12:Z12) -> -0.04333132 | AD13: =+AD12*(1+AB13) -> 104.40967 | AE13: =+AE12*(1+M13) -> 104.55676 | AG13: =+B13 -> 42790 | AH13: =+(AD13/$AD$6)/(AE13/$AE$6) -> 0.99859323 | AO13: =+AG13 -> 42790 | AP13: =AD13/VLOOKUP(AO13,'[1]Indice Utilities'!$Z:$AJ,11,0) -> 0.92740467 | AX13: =+(C13/$C$6)/(AD13/$AD$6) -> 0.89714418 | AY13: =+(D13/$D$6)/(AD13/$AD$6) -> 1.0466366 | AZ13: =+(E13/$E$6)/(AD13/$AD$6) -> 1.0386898 | BA13: =+(F13/$F$6)/(AD13/$AD$6) -> 1.0389319
B14: 42797 | C14: 58.339 | D14: 87.547 | E14: 37.152 | F14: 42.066 | G14: 19265.45 | I14: =+C14/C13-1 -> -0.016205734 | J14: =+D14/D13-1 -> 0.032600875 | K14: =+E14/E13-1 -> 0.031541537 | L14: =+F14/F13-1 -> -0.010421323 | M14: =+G14/G13-1 -> 0.0077416183 | O14: =+AVERAGE(I14:L14) -> 0.009378839 | Q14: =+Q13*(1+O14) -> 106.09323 | R14: =+R13*(1+M14) -> 105.36619 | T14: =+Q14/R14 -> 1.0069001 | V14: 42797 | W14: 48855.886 | X14: 74999.433 | Y14: 68003.84 | Z14: 42.066 | AB14: =+SUMPRODUCT(I14:L14,W13:Z13)/SUM(W13:Z13) -> 0.019345425 | AD14: =+AD13*(1+AB14) -> 106.42952 | AE14: =+AE13*(1+M14) -> 105.36619 | AG14: =+B14 -> 42797 | AH14: =+(AD14/$AD$6)/(AE14/$AE$6) -> 1.0100917 | AO14: =+AG14 -> 42797 | AP14: =AD14/VLOOKUP(AO14,'[1]Indice Utilities'!$Z:$AJ,11,0) -> 0.93948899 | AX14: =+(C14/$C$6)/(AD14/$AD$6) -> 0.86585497 | AY14: =+(D14/$D$6)/(AD14/$AD$6) -> 1.0602469 | AZ14: =+(E14/$E$6)/(AD14/$AD$6) -> 1.0511174 | BA14: =+(F14/$F$6)/(AD14/$AD$6) -> 1.0085932
B15: 42804 | C15: 57.377 | D15: 86.523 | E15: 37.01 | F15: 41.181 | G15: 18895.91 | I15: =+C15/C14-1 -> -0.016489827 | J15: =+D15/D14-1 -> -0.011696574 | K15: =+E15/E14-1 -> -0.0038221361 | L15: =+F15/F14-1 -> -0.021038368 | M15: =+G15/G14-1 -> -0.019181488 | O15: =+AVERAGE(I15:L15) -> -0.013261726 | Q15: =+Q14*(1+O15) -> 104.68625 | R15: =+R14*(1+M15) -> 103.34511 | T15: =+Q15/R15 -> 1.0129773 | V15: 42804 | W15: 48050.569 | X15: 74122.589 | Y15: 67743.787 | Z15: 41.181 | AB15: =+SUMPRODUCT(I15:L15,W14:Z14)/SUM(W14:Z14) -> -0.010128474 | AD15: =+AD14*(1+AB15) -> 105.35155 | AE15: =+AE14*(1+M15) -> 103.34511 | AG15: =+B15 -> 42804 | AH15: =+(AD15/$AD$6)/(AE15/$AE$6) -> 1.0194149 | AO15: =+AG15 -> 42804 | AP15: =AD15/VLOOKUP(AO15,'[1]Indice Utilities'!$Z:$AJ,11,0) -> 0.92561915 | AX15: =+(C15/$C$6)/(AD15/$AD$6) -> 0.8602906 | AY15: =+(D15/$D$6)/(AD15/$AD$6) -> 1.0585673 | AZ15: =+(E15/$E$6)/(AD15/$AD$6) -> 1.0578139 | BA15: =+(F15/$F$6)/(AD15/$AD$6) -> 0.99747694
B16: 42811 | C16: 60.23 | D16: 88.024 | E16: 38.644 | F16: 43.218 | G16: 19434 | I16: =+C16/C15-1 -> 0.049723757 | J16: =+D16/D15-1 -> 0.017347988 | K16: =+E16/E15-1 -> 0.04415023 | L16: =+F16/F15-1 -> 0.049464559 | M16: =+G16/G15-1 -> 0.028476533 | O16: =+AVERAGE(I16:L16) -> 0.040171633 | Q16: =+Q15*(1+O16) -> 108.89167 | R16: =+R15*(1+M16) -> 106.28802 | T16: =+Q16/R16 -> 1.0244961 | V16: 42811 | W16: 50439.676 | X16: 75408.627 | Y16: 70734.395 | Z16: 43.218 | AB16: =+SUMPRODUCT(I16:L16,W15:Z15)/SUM(W15:Z15) -> 0.035102859 | AD16: =+AD15*(1+AB16) -> 109.04969 | AE16: =+AE15*(1+M16) -> 106.28802 | AG16: =+B16 -> 42811 | AH16: =+(AD16/$AD$6)/(AE16/$AE$6) -> 1.0259828 | AO16: =+AG16 -> 42811 | AP16: =AD16/VLOOKUP(AO16,'[1]Indice Utilities'!$Z:$AJ,11,0) -> 0.92575773 | AX16: =+(C16/$C$6)/(AD16/$AD$6) -> 0.87244226 | AY16: =+(D16/$D$6)/(AD16/$AD$6) -> 1.04041 | AZ16: =+(E16/$E$6)/(AD16/$AD$6) -> 1.0670598 | BA16: =+(F16/$F$6)/(AD16/$AD$6) -> 1.0113166
B17: 42818 | C17: 61.063 | D17: 90.651 | E17: 41.521 | F17: 43.04 | G17: 19705.1 | I17: =+C17/C16-1 -> 0.013830317 | J17: =+D17/D16-1 -> 0.029844133 | K17: =+E17/E16-1 -> 0.074448815 | L17: =+F17/F16-1 -> -0.0041186543 | M17: =+G17/G16-1 -> 0.013949779 | O17: =+AVERAGE(I17:L17) -> 0.028501153 | Q17: =+Q16*(1+O17) -> 111.99521 | R17: =+R16*(1+M17) -> 107.77072 | T17: =+Q17/R17 -> 1.0391989 | V17: 42818 | W17: 51137.617 | X17: 77659.195 | Y17: 76000.467 | Z17: 43.04 | AB17: =+SUMPRODUCT(I17:L17,W16:Z16)/SUM(W16:Z16) -> 0.041774838 | AD17: =+AD16*(1+AB17) -> 113.60522 | AE17: =+AE16*(1+M17) -> 107.77072 | AG17: =+B17 -> 42818 | AH17: =+(AD17/$AD$6)/(AE17/$AE$6) -> 1.0541381 | AO17: =+AG17 -> 42818 | AP17: =AD17/VLOOKUP(AO17,'[1]Indice Utilities'!$Z:$AJ,11,0) -> 0.97207165 | AX17: =+(C17/$C$6)/(AD17/$AD$6) -> 0.84903991 | AY17: =+(D17/$D$6)/(AD17/$AD$6) -> 1.0284949 | AZ17: =+(E17/$E$6)/(AD17/$AD$6) -> 1.1005268 | BA17: =+(F17/$F$6)/(AD17/$AD$6) -> 0.96676488
B18: 42825 | C18: 60.967 | D18: 91.095 | E18: 41.841 | F18: 47.026 | G18: 20265.32 | I18: =+C18/C17-1 -> -0.0015721468 | J18: =+D18/D17-1 -> 0.0048979052 | K18: =+E18/E17-1 -> 0.0077069435 | L18: =+F18/F17-1 -> 0.092611524 | M18: =+G18/G17-1 -> 0.028430203 | O18: =+AVERAGE(I18:L18) -> 0.025911056 | Q18: =+Q17*(1+O18) -> 114.89712 | R18: =+R17*(1+M18) -> 110.83466 | T18: =+Q18/R18 -> 1.0366533 | V18: 42825 | W18: 51057.085 | X18: 78039.161 | Y18: 76585.586 | Z18: 47.026 | AB18: =+SUMPRODUCT(I18:L18,W17:Z17)/SUM(W17:Z17) -> 0.0043433287 | AD18: =+AD17*(1+AB18) -> 114.09865 | AE18: =+AE17*(1+M18) -> 110.83466 | AG18: =+B18 -> 42825 | AH18: =+(AD18/$AD$6)/(AE18/$AE$6) -> 1.0294491 | AO18: =+AG18 -> 42825 | AP18: =AD18/VLOOKUP(AO18,'[1]Indice Utilities'!$Z:$AJ,11,0) -> 0.93631431 | AX18: =+(C18/$C$6)/(AD18/$AD$6) -> 0.84403916 | AY18: =+(D18/$D$6)/(AD18/$AD$6) -> 1.0290628 | AZ18: =+(E18/$E$6)/(AD18/$AD$6) -> 1.1042126 | BA18: =+(F18/$F$6)/(AD18/$AD$6) -> 1.0517304
... B57: 43098 | C57: 100.329 | D57: 149.264 | E57: 88.128 | F57: 100.162 | G57: 30065.61 | I57: =+C57/C56-1 -> 0.019531131 | J57: =+D57/D56-1 -> 0.028676182 | K57: =+E57/E56-1 -> 0.055905682 | L57: =+F57/F56-1 -> 0.029774022 | M57: =+G57/G56-1 -> 0.039198397 | O57: =+AVERAGE(I57:L57) -> 0.033471754 | Q57: =+Q56*(1+O57) -> 217.01162 | R57: =+R56*(1+M57) -> 164.4342 | T57: =+Q57/R57 -> 1.3197474 | V57: 43098 | W57: 94349.584 | X57: 145316.88 | Y57: 176490.78 | Z57: 100.162 | AB57: =+SUMPRODUCT(I57:L57,W56:Z56)/SUM(W56:Z56) -> 0.037914649 | AD57: =+AD56*(1+AB57) -> 207.52842 | AE57: =+AE56*(1+M57) -> 164.4342 | AG57: =+B57 -> 43098 | AH57: =+(AD57/$AD$6)/(AE57/$AE$6) -> 1.2620758 | AO57: =+AG57 -> 43098 | AP57: =AD57/VLOOKUP(AO57,'[1]Indice Utilities'!$Z:$AJ,11,0) -> 0.95902155 | AX57: =+(C57/$C$6)/(AD57/$AD$6) -> 0.76365494 | AY57: =+(D57/$D$6)/(AD57/$AD$6) -> 0.92705462 | AZ57: =+(E57/$E$6)/(AD57/$AD$6) -> 1.2786964 | BA57: =+(F57/$F$6)/(AD57/$AD$6) -> 1.2316074
B58: 43105 | C58: 105.509 | D58: 151.156 | E58: 92.438 | F58: 102.479 | G58: 32190.3 | I58: =+C58/C57-1 -> 0.051630137 | J58: =+D58/D57-1 -> 0.012675528 | K58: =+E58/E57-1 -> 0.048906137 | L58: =+F58/F57-1 -> 0.023132525 | M58: =+G58/G57-1 -> 0.070668448 | O58: =+AVERAGE(I58:L58) -> 0.034086082 | Q58: =+Q57*(1+O58) -> 224.40869 | R58: =+R57*(1+M58) -> 176.05451 | T58: =+Q58/R58 -> 1.2746546 | V58: 43105 | W58: 99220.228 | X58: 147158.45 | Y58: 185122.71 | Z58: 102.479 | AB58: =+SUMPRODUCT(I58:L58,W57:Z57)/SUM(W57:Z57) -> 0.036869132 | AD58: =+AD57*(1+AB58) -> 215.17982 | AE58: =+AE57*(1+M58) -> 176.05451 | AG58: =+B58 -> 43105 | AH58: =+(AD58/$AD$6)/(AE58/$AE$6) -> 1.222234 | AI58: =+_xlfn.PERCENTILE.INC(OFFSET(AH58,-52,0,52,1),0.1) -> 1.0001536 | AJ58: =+_xlfn.PERCENTILE.INC(OFFSET(AH58,-52,0,52,1),0.25) -> 1.0198766 | AK58: =+_xlfn.PERCENTILE.INC(OFFSET(AH58,-52,0,52,1),0.5) -> 1.0785454 | AL58: =+_xlfn.PERCENTILE.INC(OFFSET(AH58,-52,0,52,1),0.75) -> 1.1409934 | AM58: =+_xlfn.PERCENTILE.INC(OFFSET(AH58,-52,0,52,1),0.9) -> 1.2075559 | AO58: =+AG58 -> 43105 | AP58: =AD58/VLOOKUP(AO58,'[1]Indice Utilities'!$Z:$AJ,11,0) -> 0.90630434 | AQ58: =+_xlfn.PERCENTILE.INC(OFFSET(AP58,-52,0,52,1),0.1) -> 0.90949958 | AR58: =+_xlfn.PERCENTILE.INC(OFFSET(AP58,-52,0,52,1),0.25) -> 0.93347828 | AS58: =+_xlfn.PERCENTILE.INC(OFFSET(AP58,-52,0,52,1),0.5) -> 0.95009979 | AT58: =+_xlfn.PERCENTILE.INC(OFFSET(AP58,-52,0,52,1),0.75) -> 0.98027432 | AU58: =+_xlfn.PERCENTILE.INC(OFFSET(AP58,-52,0,52,1),0.9) -> 1.005755 | AX58: =+(C58/$C$6)/(AD58/$AD$6) -> 0.77452643 | AY58: =+(D58/$D$6)/(AD58/$AD$6) -> 0.90542335 | AZ58: =+(E58/$E$6)/(AD58/$AD$6) -> 1.2935408 | BA58: =+(F58/$F$6)/(AD58/$AD$6) -> 1.2152909
B59: 43112 | C59: 106.779 | D59: 148.955 | E59: 94.754 | F59: 106.222 | G59: 32719.7 | I59: =+C59/C58-1 -> 0.012036888 | J59: =+D59/D58-1 -> -0.014561116 | K59: =+E59/E58-1 -> 0.025054631 | L59: =+F59/F58-1 -> 0.036524556 | M59: =+G59/G58-1 -> 0.016445948 | O59: =+AVERAGE(I59:L59) -> 0.01476374 | Q59: =+Q58*(1+O59) -> 227.7218 | R59: =+R58*(1+M59) -> 178.9499 | T59: =+Q59/R59 -> 1.2725451 | V59: 43112 | W59: 100414.91 | X59: 145015.53 | Y59: 189759.69 | Z59: 106.222 | AB59: =+SUMPRODUCT(I59:L59,W58:Z58)/SUM(W58:Z58) -> 0.0085574668 | AD59: =+AD58*(1+AB59) -> 217.02121 | AE59: =+AE58*(1+M59) -> 178.9499 | AG59: =+B59 -> 43112 | AH59: =+(AD59/$AD$6)/(AE59/$AE$6) -> 1.2127485 | AI59: =+_xlfn.PERCENTILE.INC(OFFSET(AH59,-52,0,52,1),0.1) -> 1.0019457 | AJ59: =+_xlfn.PERCENTILE.INC(OFFSET(AH59,-52,0,52,1),0.25) -> 1.0244947 | AK59: =+_xlfn.PERCENTILE.INC(OFFSET(AH59,-52,0,52,1),0.5) -> 1.0809374 | AL59: =+_xlfn.PERCENTILE.INC(OFFSET(AH59,-52,0,52,1),0.75) -> 1.1475712 | AM59: =+_xlfn.PERCENTILE.INC(OFFSET(AH59,-52,0,52,1),0.9) -> 1.2207786 | AO59: =+AG59 -> 43112 | AP59: =AD59/VLOOKUP(AO59,'[1]Indice Utilities'!$Z:$AJ,11,0) -> 0.88281227 | AQ59: =+_xlfn.PERCENTILE.INC(OFFSET(AP59,-52,0,52,1),0.1) -> 0.90655203 | AR59: =+_xlfn.PERCENTILE.INC(OFFSET(AP59,-52,0,52,1),0.25) -> 0.92699294 | AS59: =+_xlfn.PERCENTILE.INC(OFFSET(AP59,-52,0,52,1),0.5) -> 0.94950498 | AT59: =+_xlfn.PERCENTILE.INC(OFFSET(AP59,-52,0,52,1),0.75) -> 0.97399172 | AU59: =+_xlfn.PERCENTILE.INC(OFFSET(AP59,-52,0,52,1),0.9) -> 1.005749 | AX59: =+(C59/$C$6)/(AD59/$AD$6) -> 0.77719847 | AY59: =+(D59/$D$6)/(AD59/$AD$6) -> 0.88466886 | AZ59: =+(E59/$E$6)/(AD59/$AD$6) -> 1.3146995 | BA59: =+(F59/$F$6)/(AD59/$AD$6) -> 1.2489907
B60: 43119 | C60: 107.137 | D60: 149.574 | E60: 97.532 | F60: 111.212 | G60: 33591.7 | I60: =+C60/C59-1 -> 0.0033527192 | J60: =+D60/D59-1 -> 0.0041556175 | K60: =+E60/E59-1 -> 0.029318024 | L60: =+F60/F59-1 -> 0.046977086 | M60: =+G60/G59-1 -> 0.026650611 | O60: =+AVERAGE(I60:L60) -> 0.020950861 | Q60: =+Q59*(1+O60) -> 232.49277 | R60: =+R59*(1+M60) -> 183.71902 | T60: =+Q60/R60 -> 1.2654801 | V60: 43119 | W60: 100751.88 | X60: 145618.22 | Y60: 195324.07 | Z60: 111.212 | AB60: =+SUMPRODUCT(I60:L60,W59:Z59)/SUM(W59:Z59) -> 0.014949956 | AD60: =+AD59*(1+AB60) -> 220.26567 | AE60: =+AE59*(1+M60) -> 183.71902 | AG60: =+B60 -> 43119 | AH60: =+(AD60/$AD$6)/(AE60/$AE$6) -> 1.1989269 | AI60: =+_xlfn.PERCENTILE.INC(OFFSET(AH60,-52,0,52,1),0.1) -> 1.0058345 | AJ60: =+_xlfn.PERCENTILE.INC(OFFSET(AH60,-52,0,52,1),0.25) -> 1.0285826 | AK60: =+_xlfn.PERCENTILE.INC(OFFSET(AH60,-52,0,52,1),0.5) -> 1.0823752 | AL60: =+_xlfn.PERCENTILE.INC(OFFSET(AH60,-52,0,52,1),0.75) -> 1.1543511 | AM60: =+_xlfn.PERCENTILE.INC(OFFSET(AH60,-52,0,52,1),0.9) -> 1.2212855 | AO60: =+AG60 -> 43119 | AP60: =AD60/VLOOKUP(AO60,'[1]Indice Utilities'!$Z:$AJ,11,0) -> 0.8679463 | AQ60: =+_xlfn.PERCENTILE.INC(OFFSET(AP60,-52,0,52,1),0.1) -> 0.90052455 | AR60: =+_xlfn.PERCENTILE.INC(OFFSET(AP60,-52,0,52,1),0.25) -> 0.92572308 | AS60: =+_xlfn.PERCENTILE.INC(OFFSET(AP60,-52,0,52,1),0.5) -> 0.94875673 | AT60: =+_xlfn.PERCENTILE.INC(OFFSET(AP60,-52,0,52,1),0.75) -> 0.96965132 | AU60: =+_xlfn.PERCENTILE.INC(OFFSET(AP60,-52,0,52,1),0.9) -> 1.005749 | AX60: =+(C60/$C$6)/(AD60/$AD$6) -> 0.76831788 | AY60: =+(D60/$D$6)/(AD60/$AD$6) -> 0.8752601 | AZ60: =+(E60/$E$6)/(AD60/$AD$6) -> 1.3333109 | BA60: =+(F60/$F$6)/(AD60/$AD$6) -> 1.288403
B61: 43126 | C61: 108.017 | D61: 147.441 | E61: 93.008 | F61: 112.37 | G61: 35126.22 | I61: =+C61/C60-1 -> 0.0082137824 | J61: =+D61/D60-1 -> -0.0142605 | K61: =+E61/E60-1 -> -0.046384776 | L61: =+F61/F60-1 -> 0.010412545 | M61: =+G61/G60-1 -> 0.045681523 | O61: =+AVERAGE(I61:L61) -> -0.010504737 | Q61: =+Q60*(1+O61) -> 230.0505 | R61: =+R60*(1+M61) -> 192.11158 | T61: =+Q61/R61 -> 1.1974837 | V61: 43126 | W61: 101578.97 | X61: 143542.27 | Y61: 186264.12 | Z61: 112.37 | AB61: =+SUMPRODUCT(I61:L61,W60:Z60)/SUM(W60:Z60) -> -0.023331404 | AD61: =+AD60*(1+AB61) -> 215.12656 | AE61: =+AE60*(1+M61) -> 192.11158 | AG61: =+B61 -> 43126 | AH61: =+(AD61/$AD$6)/(AE61/$AE$6) -> 1.1198 | AI61: =+_xlfn.PERCENTILE.INC(OFFSET(AH61,-52,0,52,1),0.1) -> 1.0078721 | AJ61: =+_xlfn.PERCENTILE.INC(OFFSET(AH61,-52,0,52,1),0.25) -> 1.0313277 | AK61: =+_xlfn.PERCENTILE.INC(OFFSET(AH61,-52,0,52,1),0.5) -> 1.0875387 | AL61: =+_xlfn.PERCENTILE.INC(OFFSET(AH61,-52,0,52,1),0.75) -> 1.1654639 | AM61: =+_xlfn.PERCENTILE.INC(OFFSET(AH61,-52,0,52,1),0.9) -> 1.2212855 | AO61: =+AG61 -> 43126 | AP61: =AD61/VLOOKUP(AO61,'[1]Indice Utilities'!$Z:$AJ,11,0) -> 0.79729521 | AQ61: =+_xlfn.PERCENTILE.INC(OFFSET(AP61,-52,0,52,1),0.1) -> 0.88451928 | AR61: =+_xlfn.PERCENTILE.INC(OFFSET(AP61,-52,0,52,1),0.25) -> 0.92509594 | AS61: =+_xlfn.PERCENTILE.INC(OFFSET(AP61,-52,0,52,1),0.5) -> 0.94779097 | AT61: =+_xlfn.PERCENTILE.INC(OFFSET(AP61,-52,0,52,1),0.75) -> 0.96612757 | AU61: =+_xlfn.PERCENTILE.INC(OFFSET(AP61,-52,0,52,1),0.9) -> 0.99984462 | AX61: =+(C61/$C$6)/(AD61/$AD$6) -> 0.79313359 | AY61: =+(D61/$D$6)/(AD61/$AD$6) -> 0.88338916 | AZ61: =+(E61/$E$6)/(AD61/$AD$6) -> 1.3018394 | BA61: =+(F61/$F$6)/(AD61/$AD$6) -> 1.3329174
B62: 43133 | C62: 97.756 | D62: 136.367 | E62: 88.556 | F62: 105.197 | G62: 32614.77 | I62: =+C62/C61-1 -> -0.094994306 | J62: =+D62/D61-1 -> -0.075108009 | K62: =+E62/E61-1 -> -0.04786685 | L62: =+F62/F61-1 -> -0.063833763 | M62: =+G62/G61-1 -> -0.071497873 | O62: =+AVERAGE(I62:L62) -> -0.070450732 | Q62: =+Q61*(1+O62) -> 213.84327 | R62: =+R61*(1+M62) -> 178.37601 | T62: =+Q62/R62 -> 1.1988342 | V62: 43133 | W62: 91929.579 | X62: 132760.69 | Y62: 177346.84 | Z62: 105.197 | AB62: =+SUMPRODUCT(I62:L62,W61:Z61)/SUM(W61:Z61) -> -0.068027351 | AD62: =+AD61*(1+AB62) -> 200.49207 | AE62: =+AE61*(1+M62) -> 178.37601 | AG62: =+B62 -> 43133 | AH62: =+(AD62/$AD$6)/(AE62/$AE$6) -> 1.1239856 | AI62: =+_xlfn.PERCENTILE.INC(OFFSET(AH62,-52,0,52,1),0.1) -> 1.0103069 | AJ62: =+_xlfn.PERCENTILE.INC(OFFSET(AH62,-52,0,52,1),0.25) -> 1.0324471 | AK62: =+_xlfn.PERCENTILE.INC(OFFSET(AH62,-52,0,52,1),0.5) -> 1.0935931 | AL62: =+_xlfn.PERCENTILE.INC(OFFSET(AH62,-52,0,52,1),0.75) -> 1.1654639 | AM62: =+_xlfn.PERCENTILE.INC(OFFSET(AH62,-52,0,52,1),0.9) -> 1.2212855 | AO62: =+AG62 -> 43133 | AP62: =AD62/VLOOKUP(AO62,'[1]Indice Utilities'!$Z:$AJ,11,0) -> 0.84955812 | AQ62: =+_xlfn.PERCENTILE.INC(OFFSET(AP62,-52,0,52,1),0.1) -> 0.88175841 | AR62: =+_xlfn.PERCENTILE.INC(OFFSET(AP62,-52,0,52,1),0.25) -> 0.92302469 | AS62: =+_xlfn.PERCENTILE.INC(OFFSET(AP62,-52,0,52,1),0.5) -> 0.94457781 | AT62: =+_xlfn.PERCENTILE.INC(OFFSET(AP62,-52,0,52,1),0.75) -> 0.96456338 | AU62: =+_xlfn.PERCENTILE.INC(OFFSET(AP62,-52,0,52,1),0.9) -> 0.99769514 | AX62: =+(C62/$C$6)/(AD62/$AD$6) -> 0.77018399 | AY62: =+(D62/$D$6)/(AD62/$AD$6) -> 0.87667762 | AZ62: =+(E62/$E$6)/(AD62/$AD$6) -> 1.3300008 | BA62: =+(F62/$F$6)/(AD62/$AD$6) -> 1.3389151
B63: 43140 | C63: 93.684 | D63: 131.38 | E63: 84.103 | F63: 100.028 | G63: 30143.44 | I63: =+C63/C62-1 -> -0.041654732 | J63: =+D63/D62-1 -> -0.036570431 | K63: =+E63/E62-1 -> -0.050284566 | L63: =+F63/F62-1 -> -0.049136382 | M63: =+G63/G62-1 -> -0.075773338 | O63: =+AVERAGE(I63:L63) -> -0.044411528 | Q63: =+Q62*(1+O63) -> 204.34616 | R63: =+R62*(1+M63) -> 164.85987 | T63: =+Q63/R63 -> 1.2395143 | V63: 43140 | W63: 88100.456 | X63: 127905.64 | Y63: 168429.56 | Z63: 100.028 | AB63: =+SUMPRODUCT(I63:L63,W62:Z62)/SUM(W62:Z62) -> -0.043783992 | AD63: =+AD62*(1+AB63) -> 191.71373 | AE63: =+AE62*(1+M63) -> 164.85987 | AG63: =+B63 -> 43140 | AH63: =+(AD63/$AD$6)/(AE63/$AE$6) -> 1.162889 | AI63: =+_xlfn.PERCENTILE.INC(OFFSET(AH63,-52,0,52,1),0.1) -> 1.0124109 | AJ63: =+_xlfn.PERCENTILE.INC(OFFSET(AH63,-52,0,52,1),0.25) -> 1.0487565 | AK63: =+_xlfn.PERCENTILE.INC(OFFSET(AH63,-52,0,52,1),0.5) -> 1.0957032 | AL63: =+_xlfn.PERCENTILE.INC(OFFSET(AH63,-52,0,52,1),0.75) -> 1.1654639 | AM63: =+_xlfn.PERCENTILE.INC(OFFSET(AH63,-52,0,52,1),0.9) -> 1.2212855 | AO63: =+AG63 -> 43140 | AP63: =AD63/VLOOKUP(AO63,'[1]Indice Utilities'!$Z:$AJ,11,0) -> 0.8613918 | AQ63: =+_xlfn.PERCENTILE.INC(OFFSET(AP63,-52,0,52,1),0.1) -> 0.87312988 | AR63: =+_xlfn.PERCENTILE.INC(OFFSET(AP63,-52,0,52,1),0.25) -> 0.92102847 | AS63: =+_xlfn.PERCENTILE.INC(OFFSET(AP63,-52,0,52,1),0.5) -> 0.94115137 | AT63: =+_xlfn.PERCENTILE.INC(OFFSET(AP63,-52,0,52,1),0.75) -> 0.96456338 | AU63: =+_xlfn.PERCENTILE.INC(OFFSET(AP63,-52,0,52,1),0.9) -> 0.99769514 | AX63: =+(C63/$C$6)/(AD63/$AD$6) -> 0.77189901 | AY63: =+(D63/$D$6)/(AD63/$AD$6) -> 0.88329115 | AZ63: =+(E63/$E$6)/(AD63/$AD$6) -> 1.3209592 | BA63: =+(F63/$F$6)/(AD63/$AD$6) -> 1.3314206
B64: 43147 | C64: 108.017 | D64: 150.537 | E64: 95.894 | F64: 114.375 | G64: 32677.25 | I64: =+C64/C63-1 -> 0.15299304 | J64: =+D64/D63-1 -> 0.14581367 | K64: =+E64/E63-1 -> 0.14019714 | L64: =+F64/F63-1 -> 0.14342984 | M64: =+G64/G63-1 -> 0.084058422 | O64: =+AVERAGE(I64:L64) -> 0.14560842 | Q64: =+Q63*(1+O64) -> 234.10069 | R64: =+R63*(1+M64) -> 178.71773 | T64: =+Q64/R64 -> 1.3098907 | V64: 43147 | W64: 101578.97 | X64: 146555.75 | Y64: 192042.51 | Z64: 114.375 | AB64: =+SUMPRODUCT(I64:L64,W63:Z63)/SUM(W63:Z63) -> 0.14499782 | AD64: =+AD63*(1+AB64) -> 219.5118 | AE64: =+AE63*(1+M64) -> 178.71773 | AG64: =+B64 -> 43147 | AH64: =+(AD64/$AD$6)/(AE64/$AE$6) -> 1.2282598 | AI64: =+_xlfn.PERCENTILE.INC(OFFSET(AH64,-52,0,52,1),0.1) -> 1.0124109 | AJ64: =+_xlfn.PERCENTILE.INC(OFFSET(AH64,-52,0,52,1),0.25) -> 1.0487565 | AK64: =+_xlfn.PERCENTILE.INC(OFFSET(AH64,-52,0,52,1),0.5) -> 1.1023511 | AL64: =+_xlfn.PERCENTILE.INC(OFFSET(AH64,-52,0,52,1),0.75) -> 1.1657314 | AM64: =+_xlfn.PERCENTILE.INC(OFFSET(AH64,-52,0,52,1),0.9) -> 1.2212855 | AO64: =+AG64 -> 43147 | AP64: =AD64/VLOOKUP(AO64,'[1]Indice Utilities'!$Z:$AJ,11,0) -> 0.91606987 | AQ64: =+_xlfn.PERCENTILE.INC(OFFSET(AP64,-52,0,52,1),0.1) -> 0.87095436 | AR64: =+_xlfn.PERCENTILE.INC(OFFSET(AP64,-52,0,52,1),0.25) -> 0.91865705 | AS64: =+_xlfn.PERCENTILE.INC(OFFSET(AP64,-52,0,52,1),0.5) -> 0.9399418 | AT64: =+_xlfn.PERCENTILE.INC(OFFSET(AP64,-52,0,52,1),0.75) -> 0.96403469 | AU64: =+_xlfn.PERCENTILE.INC(OFFSET(AP64,-52,0,52,1),0.9) -> 0.98598722 | AX64: =+(C64/$C$6)/(AD64/$AD$6) -> 0.77728897 | AY64: =+(D64/$D$6)/(AD64/$AD$6) -> 0.88392053 | AZ64: =+(E64/$E$6)/(AD64/$AD$6) -> 1.3154207 | BA64: =+(F64/$F$6)/(AD64/$AD$6) -> 1.3295973
B65: 43154 | C65: 106.421 | D65: 155.833 | E65: 93.151 | F65: 113.93 | G65: 32742.39 | I65: =+C65/C64-1 -> -0.014775452 | J65: =+D65/D64-1 -> 0.03518072 | K65: =+E65/E64-1 -> -0.028604501 | L65: =+F65/F64-1 -> -0.0038907104 | M65: =+G65/G64-1 -> 0.0019934358 | O65: =+AVERAGE(I65:L65) -> -0.0030224859 | Q65: =+Q64*(1+O65) -> 233.39312 | R65: =+R64*(1+M65) -> 179.07399 | T65: =+Q65/R65 -> 1.3033334 | V65: 43154 | W65: 100077.95 | X65: 151712.16 | Y65: 186549.47 | Z65: 113.93 | AB65: =+SUMPRODUCT(I65:L65,W64:Z64)/SUM(W64:Z64) -> -0.0041760133 | AD65: =+AD64*(1+AB65) -> 218.59512 | AE65: =+AE64*(1+M65) -> 179.07399 | AG65: =+B65 -> 43154 | AH65: =+(AD65/$AD$6)/(AE65/$AE$6) -> 1.2206972 | AI65: =+_xlfn.PERCENTILE.INC(OFFSET(AH65,-52,0,52,1),0.1) -> 1.0129607 | AJ65: =+_xlfn.PERCENTILE.INC(OFFSET(AH65,-52,0,52,1),0.25) -> 1.0596128 | AK65: =+_xlfn.PERCENTILE.INC(OFFSET(AH65,-52,0,52,1),0.5) -> 1.1138832 | AL65: =+_xlfn.PERCENTILE.INC(OFFSET(AH65,-52,0,52,1),0.75) -> 1.1754499 | AM65: =+_xlfn.PERCENTILE.INC(OFFSET(AH65,-52,0,52,1),0.9) -> 1.2276572 | AO65: =+AG65 -> 43154 | AP65: =AD65/VLOOKUP(AO65,'[1]Indice Utilities'!$Z:$AJ,11,0) -> 0.9365008 | AQ65: =+_xlfn.PERCENTILE.INC(OFFSET(AP65,-52,0,52,1),0.1) -> 0.87095436 | AR65: =+_xlfn.PERCENTILE.INC(OFFSET(AP65,-52,0,52,1),0.25) -> 0.9160437 | AS65: =+_xlfn.PERCENTILE.INC(OFFSET(AP65,-52,0,52,1),0.5) -> 0.93949372 | AT65: =+_xlfn.PERCENTILE.INC(OFFSET(AP65,-52,0,52,1),0.75) -> 0.96024907 | AU65: =+_xlfn.PERCENTILE.INC(OFFSET(AP65,-52,0,52,1),0.9) -> 0.9856638 | AX65: =+(C65/$C$6)/(AD65/$AD$6) -> 0.7690156 | AY65: =+(D65/$D$6)/(AD65/$AD$6) -> 0.91885464 | AZ65: =+(E65/$E$6)/(AD65/$AD$6) -> 1.2831523 | BA65: =+(F65/$F$6)/(AD65/$AD$6) -> 1.3299783
B66: 43161 | C66: 98.7 | D66: 149.47 | E66: 87.594 | F66: 105.197 | G66: 31900.7 | I66: =+C66/C65-1 -> -0.07255147 | J66: =+D66/D65-1 -> -0.040832173 | K66: =+E66/E65-1 -> -0.059655828 | L66: =+F66/F65-1 -> -0.07665233 | M66: =+G66/G65-1 -> -0.025706431 | O66: =+AVERAGE(I66:L66) -> -0.06242295 | Q66: =+Q65*(1+O66) -> 218.82403 | R66: =+R65*(1+M66) -> 174.47064 | T66: =+Q66/R66 -> 1.254217 | V66: 43161 | W66: 92817.935 | X66: 145517.77 | Y66: 175420.71 | Z66: 105.197 | AB66: =+SUMPRODUCT(I66:L66,W65:Z65)/SUM(W65:Z65) -> -0.056090407 | AD66: =+AD65*(1+AB66) -> 206.33403 | AE66: =+AE65*(1+M66) -> 174.47064 | AG66: =+B66 -> 43161 | AH66: =+(AD66/$AD$6)/(AE66/$AE$6) -> 1.1826289 | AI66: =+_xlfn.PERCENTILE.INC(OFFSET(AH66,-52,0,52,1),0.1) -> 1.0194765 | AJ66: =+_xlfn.PERCENTILE.INC(OFFSET(AH66,-52,0,52,1),0.25) -> 1.0665439 | AK66: =+_xlfn.PERCENTILE.INC(OFFSET(AH66,-52,0,52,1),0.5) -> 1.1206206 | AL66: =+_xlfn.PERCENTILE.INC(OFFSET(AH66,-52,0,52,1),0.75) -> 1.1834339 | AM66: =+_xlfn.PERCENTILE.INC(OFFSET(AH66,-52,0,52,1),0.9) -> 1.2276572 | AO66: =+AG66 -> 43161 | AP66: =AD66/VLOOKUP(AO66,'[1]Indice Utilities'!$Z:$AJ,11,0) -> 0.91227043 | AQ66: =+_xlfn.PERCENTILE.INC(OFFSET(AP66,-52,0,52,1),0.1) -> 0.87095436 | AR66: =+_xlfn.PERCENTILE.INC(OFFSET(AP66,-52,0,52,1),0.25) -> 0.9160437 | AS66: =+_xlfn.PERCENTILE.INC(OFFSET(AP66,-52,0,52,1),0.5) -> 0.93949372 | AT66: =+_xlfn.PERCENTILE.INC(OFFSET(AP66,-52,0,52,1),0.75) -> 0.96024907 | AU66: =+_xlfn.PERCENTILE.INC(OFFSET(AP66,-52,0,52,1),0.9) -> 0.9856638 | AX66: =+(C66/$C$6)/(AD66/$AD$6) -> 0.75560455 | AY66: =+(D66/$D$6)/(AD66/$AD$6) -> 0.93370786 | AZ66: =+(E66/$E$6)/(AD66/$AD$6) -> 1.2783054 | BA66: =+(F66/$F$6)/(AD66/$AD$6) -> 1.3010063
B67: 43168 | C67: 99.678 | D67: 153.529 | E67: 92.403 | F67: 106.845 | G67: 33182.6 | I67: =+C67/C66-1 -> 0.0099088146 | J67: =+D67/D66-1 -> 0.027155951 | K67: =+E67/E66-1 -> 0.054901021 | L67: =+F67/F66-1 -> 0.015665846 | M67: =+G67/G66-1 -> 0.040184071 | O67: =+AVERAGE(I67:L67) -> 0.026907908 | Q67: =+Q66*(1+O67) -> 224.71213 | R67: =+R66*(1+M67) -> 181.48158 | T67: =+Q67/R67 -> 1.238209 | V67: 43168 | W67: 93736.925 | X67: 149468.79 | Y67: 185051.37 | Z67: 106.845 | AB67: =+SUMPRODUCT(I67:L67,W66:Z66)/SUM(W66:Z66) -> 0.035045079 | AD67: =+AD66*(1+AB67) -> 213.56502 | AE67: =+AE66*(1+M67) -> 181.48158 | AG67: =+B67 -> 43168 | AH67: =+(AD67/$AD$6)/(AE67/$AE$6) -> 1.1767862 | AI67: =+_xlfn.PERCENTILE.INC(OFFSET(AH67,-52,0,52,1),0.1) -> 1.0206257 | AJ67: =+_xlfn.PERCENTILE.INC(OFFSET(AH67,-52,0,52,1),0.25) -> 1.0691437 | AK67: =+_xlfn.PERCENTILE.INC(OFFSET(AH67,-52,0,52,1),0.5) -> 1.1226444 | AL67: =+_xlfn.PERCENTILE.INC(OFFSET(AH67,-52,0,52,1),0.75) -> 1.1861377 | AM67: =+_xlfn.PERCENTILE.INC(OFFSET(AH67,-52,0,52,1),0.9) -> 1.2276572 | AO67: =+AG67 -> 43168 | AP67: =AD67/VLOOKUP(AO67,'[1]Indice Utilities'!$Z:$AJ,11,0) -> 0.88812158 | AQ67: =+_xlfn.PERCENTILE.INC(OFFSET(AP67,-52,0,52,1),0.1) -> 0.87095436 | AR67: =+_xlfn.PERCENTILE.INC(OFFSET(AP67,-52,0,52,1),0.25) -> 0.91504149 | AS67: =+_xlfn.PERCENTILE.INC(OFFSET(AP67,-52,0,52,1),0.5) -> 0.93900899 | AT67: =+_xlfn.PERCENTILE.INC(OFFSET(AP67,-52,0,52,1),0.75) -> 0.96024907 | AU67: =+_xlfn.PERCENTILE.INC(OFFSET(AP67,-52,0,52,1),0.9) -> 0.9856638 | AX67: =+(C67/$C$6)/(AD67/$AD$6) -> 0.73725455 | AY67: =+(D67/$D$6)/(AD67/$AD$6) -> 0.92659112 | AZ67: =+(E67/$E$6)/(AD67/$AD$6) -> 1.302828 | BA67: =+(F67/$F$6)/(AD67/$AD$6) -> 1.2766475
B68: 43175 | C68: 103.815 | D68: 151.844 | E68: 94.22 | F68: 110.544 | G68: 32555.08 | I68: =+C68/C67-1 -> 0.041503642 | J68: =+D68/D67-1 -> -0.010975125 | K68: =+E68/E67-1 -> 0.019663864 | L68: =+F68/F67-1 -> 0.034620244 | M68: =+G68/G67-1 -> -0.018911116 | O68: =+AVERAGE(I68:L68) -> 0.021203156 | Q68: =+Q67*(1+O68) -> 229.47674 | R68: =+R67*(1+M68) -> 178.04956 | T68: =+Q68/R68 -> 1.2888363 | V68: 43175 | W68: 97627.314 | X68: 147828.11 | Y68: 188689.62 | Z68: 110.544 | AB68: =+SUMPRODUCT(I68:L68,W67:Z67)/SUM(W67:Z67) -> 0.013755848 | AD68: =+AD67*(1+AB68) -> 216.50279 | AE68: =+AE67*(1+M68) -> 178.04956 | AG68: =+B68 -> 43175 | AH68: =+(AD68/$AD$6)/(AE68/$AE$6) -> 1.2159692 | AI68: =+_xlfn.PERCENTILE.INC(OFFSET(AH68,-52,0,52,1),0.1) -> 1.0263295 | AJ68: =+_xlfn.PERCENTILE.INC(OFFSET(AH68,-52,0,52,1),0.25) -> 1.0731168 | AK68: =+_xlfn.PERCENTILE.INC(OFFSET(AH68,-52,0,52,1),0.5) -> 1.1239166 | AL68: =+_xlfn.PERCENTILE.INC(OFFSET(AH68,-52,0,52,1),0.75) -> 1.1861377 | AM68: =+_xlfn.PERCENTILE.INC(OFFSET(AH68,-52,0,52,1),0.9) -> 1.2276572 | AO68: =+AG68 -> 43175 | AP68: =AD68/VLOOKUP(AO68,'[1]Indice Utilities'!$Z:$AJ,11,0) -> 0.90464279 | AQ68: =+_xlfn.PERCENTILE.INC(OFFSET(AP68,-52,0,52,1),0.1) -> 0.87095436 | AR68: =+_xlfn.PERCENTILE.INC(OFFSET(AP68,-52,0,52,1),0.25) -> 0.91139811 | AS68: =+_xlfn.PERCENTILE.INC(OFFSET(AP68,-52,0,52,1),0.5) -> 0.93900899 | AT68: =+_xlfn.PERCENTILE.INC(OFFSET(AP68,-52,0,52,1),0.75) -> 0.96024907 | AU68: =+_xlfn.PERCENTILE.INC(OFFSET(AP68,-52,0,52,1),0.9) -> 0.9856638 | AX68: =+(C68/$C$6)/(AD68/$AD$6) -> 0.75743415 | AY68: =+(D68/$D$6)/(AD68/$AD$6) -> 0.90398657 | AZ68: =+(E68/$E$6)/(AD68/$AD$6) -> 1.3104207 | BA68: =+(F68/$F$6)/(AD68/$AD$6) -> 1.3029225
B69: 43182 | C69: 98.472 | D69: 149.195 | E69: 91.299 | F69: 107.826 | G69: 31461.26 | I69: =+C69/C68-1 -> -0.051466551 | J69: =+D69/D68-1 -> -0.017445536 | K69: =+E69/E68-1 -> -0.03100191 | L69: =+F69/F68-1 -> -0.024587495 | M69: =+G69/G68-1 -> -0.033599057 | O69: =+AVERAGE(I69:L69) -> -0.031125373 | Q69: =+Q68*(1+O69) -> 222.33419 | R69: =+R68*(1+M69) -> 172.06726 | T69: =+Q69/R69 -> 1.2921353 | V69: 43182 | W69: 92603.504 | X69: 145249.91 | Y69: 182839.88 | Z69: 107.826 | AB69: =+SUMPRODUCT(I69:L69,W68:Z68)/SUM(W68:Z68) -> -0.030986218 | AD69: =+AD68*(1+AB69) -> 209.79418 | AE69: =+AE68*(1+M69) -> 172.06726 | AG69: =+B69 -> 43182 | AH69: =+(AD69/$AD$6)/(AE69/$AE$6) -> 1.2192568 | AI69: =+_xlfn.PERCENTILE.INC(OFFSET(AH69,-52,0,52,1),0.1) -> 1.0296996 | AJ69: =+_xlfn.PERCENTILE.INC(OFFSET(AH69,-52,0,52,1),0.25) -> 1.0754721 | AK69: =+_xlfn.PERCENTILE.INC(OFFSET(AH69,-52,0,52,1),0.5) -> 1.1251071 | AL69: =+_xlfn.PERCENTILE.INC(OFFSET(AH69,-52,0,52,1),0.75) -> 1.1972297 | AM69: =+_xlfn.PERCENTILE.INC(OFFSET(AH69,-52,0,52,1),0.9) -> 1.2276572 | AO69: =+AG69 -> 43182 | AP69: =AD69/VLOOKUP(AO69,'[1]Indice Utilities'!$Z:$AJ,11,0) -> 0.92321445 | AQ69: =+_xlfn.PERCENTILE.INC(OFFSET(AP69,-52,0,52,1),0.1) -> 0.87095436 | AR69: =+_xlfn.PERCENTILE.INC(OFFSET(AP69,-52,0,52,1),0.25) -> 0.90816197 | AS69: =+_xlfn.PERCENTILE.INC(OFFSET(AP69,-52,0,52,1),0.5) -> 0.93900899 | AT69: =+_xlfn.PERCENTILE.INC(OFFSET(AP69,-52,0,52,1),0.75) -> 0.96024907 | AU69: =+_xlfn.PERCENTILE.INC(OFFSET(AP69,-52,0,52,1),0.9) -> 0.9856638 | AX69: =+(C69/$C$6)/(AD69/$AD$6) -> 0.7414256 | AY69: =+(D69/$D$6)/(AD69/$AD$6) -> 0.91661858 | AZ69: =+(E69/$E$6)/(AD69/$AD$6) -> 1.3103994 | BA69: =+(F69/$F$6)/(AD69/$AD$6) -> 1.3115261
... B515: 46304 | C515: 6800 | D515: 10440 | E515: 5940 | F515: 2314 | G515: 2828027 | I515: =+C515/C514-1 -> 0.0074074074 | J515: =+D515/D514-1 -> -0.0057142857 | K515: =+E515/E514-1 -> 0.017994859 | L515: =+F515/F514-1 -> 0.028901734 | M515: =+G515/G514-1 -> 0.021810459 | O515: =+AVERAGE(I515:L515) -> 0.012147429 | Q515: =+Q514*(1+O515) -> 13428.87 | R515: =+R514*(1+M515) -> 15466.986 | T515: =+Q515/R515 -> 0.868228 | V515: 46304 | W515: 4166428.5 | X515: 6675476 | Y515: 9541147.2 | Z515: 2314 | AB515: =+SUMPRODUCT(I515:L515,W514:Z514)/SUM(W514:Z514) -> 0.007960313 | AD515: =+AD514*(1+AB515) -> 14199.562 | AE515: =+AE514*(1+M515) -> 15466.986 | AG515: =+B515 -> 46304 | AH515: =+(AD515/$AD$6)/(AE515/$AE$6) -> 0.91805616 | AI515: =+_xlfn.PERCENTILE.INC(OFFSET(AH515,-52,0,52,1),0.1) -> 0.95117447 | AJ515: =+_xlfn.PERCENTILE.INC(OFFSET(AH515,-52,0,52,1),0.25) -> 0.98742377 | AK515: =+_xlfn.PERCENTILE.INC(OFFSET(AH515,-52,0,52,1),0.5) -> 1.0456541 | AL515: =+_xlfn.PERCENTILE.INC(OFFSET(AH515,-52,0,52,1),0.75) -> 1.1041949 | AM515: =+_xlfn.PERCENTILE.INC(OFFSET(AH515,-52,0,52,1),0.9) -> 1.1286625 | AO515: =+AG515 -> 46304 | AP515: =AD515/VLOOKUP(AO515,'[1]Indice Utilities'!$Z:$AJ,11,0) -> #N/A | AQ515: =+_xlfn.PERCENTILE.INC(OFFSET(AP515,-52,0,52,1),0.1) -> 0.73843861 | AR515: =+_xlfn.PERCENTILE.INC(OFFSET(AP515,-52,0,52,1),0.25) -> 0.782608 | AS515: =+_xlfn.PERCENTILE.INC(OFFSET(AP515,-52,0,52,1),0.5) -> 0.8359267 | AT515: =+_xlfn.PERCENTILE.INC(OFFSET(AP515,-52,0,52,1),0.75) -> 0.90528121 | AU515: =+_xlfn.PERCENTILE.INC(OFFSET(AP515,-52,0,52,1),0.9) -> 0.93468884 | AX515: =+(C515/$C$6)/(AD515/$AD$6) -> 0.75645351 | AY515: =+(D515/$D$6)/(AD515/$AD$6) -> 0.94766184 | AZ515: =+(E515/$E$6)/(AD515/$AD$6) -> 1.2596289 | BA515: =+(F515/$F$6)/(AD515/$AD$6) -> 0.41584867

Sheet Relativos

Sheet Beta Rolling
A1: =+'Indice Bancos'!B5 -> Dates | B1: =+'Indice Bancos'!I5 -> BBAR AR Equity | C1: =+'Indice Bancos'!J5 -> BMA AR Equity | D1: =+'Indice Bancos'!K5 -> GGAL AR Equity | E1: =+'Indice Bancos'!L5 -> SUPV AR Equity | G1: =+'Indice Bancos'!M5 -> MERVAL Index
A2: =+'Indice Bancos'!B6 -> 42741
A3: =+'Indice Bancos'!B7 -> 42748 | B3: =+'Indice Bancos'!I7 -> -0.029870314 | C3: =+'Indice Bancos'!J7 -> 0.01143277 | D3: =+'Indice Bancos'!K7 -> 0.060945498 | E3: =+'Indice Bancos'!L7 -> 0.028248443 | G3: =+'Indice Bancos'!M7 -> 0.032859374
A4: =+'Indice Bancos'!B8 -> 42755 | B4: =+'Indice Bancos'!I8 -> -0.0083528722 | C4: =+'Indice Bancos'!J8 -> 0.032177492 | D4: =+'Indice Bancos'!K8 -> 0.040330363 | E4: =+'Indice Bancos'!L8 -> -0.01099392 | G4: =+'Indice Bancos'!M8 -> 0.0081757619
A5: =+'Indice Bancos'!B9 -> 42762 | B5: =+'Indice Bancos'!I9 -> 0.051573814 | C5: =+'Indice Bancos'!J9 -> 0.027384068 | D5: =+'Indice Bancos'!K9 -> -0.03876688 | E5: =+'Indice Bancos'!L9 -> 0.0022332631 | G5: =+'Indice Bancos'!M9 -> 0.0092591766
A6: =+'Indice Bancos'!B10 -> 42769 | B6: =+'Indice Bancos'!I10 -> 0.00049965649 | C6: =+'Indice Bancos'!J10 -> -0.015177735 | D6: =+'Indice Bancos'!K10 -> 0.019157632 | E6: =+'Indice Bancos'!L10 -> -0.0044315365 | G6: =+'Indice Bancos'!M10 -> -0.00079517979
A7: =+'Indice Bancos'!B11 -> 42776 | B7: =+'Indice Bancos'!I11 -> 0.019508084 | C7: =+'Indice Bancos'!J11 -> 0.090761553 | D7: =+'Indice Bancos'!K11 -> 0.087053385 | E7: =+'Indice Bancos'!L11 -> 0.013353787 | G7: =+'Indice Bancos'!M11 -> 0.015751152
A8: =+'Indice Bancos'!B12 -> 42783 | B8: =+'Indice Bancos'!I12 -> -0.038269602 | C8: =+'Indice Bancos'!J12 -> -0.038170245 | D8: =+'Indice Bancos'!K12 -> -0.013654413 | E8: =+'Indice Bancos'!L12 -> 0.076932622 | G8: =+'Indice Bancos'!M12 -> 0.0091478562
A9: =+'Indice Bancos'!B13 -> 42790 | B9: =+'Indice Bancos'!I13 -> -0.056123261 | C9: =+'Indice Bancos'!J13 -> -0.013887435 | D9: =+'Indice Bancos'!K13 -> -0.064568074 | E9: =+'Indice Bancos'!L13 -> -0.020417099 | G9: =+'Indice Bancos'!M13 -> -0.028650996
A10: =+'Indice Bancos'!B14 -> 42797 | B10: =+'Indice Bancos'!I14 -> -0.016205734 | C10: =+'Indice Bancos'!J14 -> 0.032600875 | D10: =+'Indice Bancos'!K14 -> 0.031541537 | E10: =+'Indice Bancos'!L14 -> -0.010421323 | G10: =+'Indice Bancos'!M14 -> 0.0077416183
A11: =+'Indice Bancos'!B15 -> 42804 | B11: =+'Indice Bancos'!I15 -> -0.016489827 | C11: =+'Indice Bancos'!J15 -> -0.011696574 | D11: =+'Indice Bancos'!K15 -> -0.0038221361 | E11: =+'Indice Bancos'!L15 -> -0.021038368 | G11: =+'Indice Bancos'!M15 -> -0.019181488
A12: =+'Indice Bancos'!B16 -> 42811 | B12: =+'Indice Bancos'!I16 -> 0.049723757 | C12: =+'Indice Bancos'!J16 -> 0.017347988 | D12: =+'Indice Bancos'!K16 -> 0.04415023 | E12: =+'Indice Bancos'!L16 -> 0.049464559 | G12: =+'Indice Bancos'!M16 -> 0.028476533
A13: =+'Indice Bancos'!B17 -> 42818 | B13: =+'Indice Bancos'!I17 -> 0.013830317 | C13: =+'Indice Bancos'!J17 -> 0.029844133 | D13: =+'Indice Bancos'!K17 -> 0.074448815 | E13: =+'Indice Bancos'!L17 -> -0.0041186543 | G13: =+'Indice Bancos'!M17 -> 0.013949779
A14: =+'Indice Bancos'!B18 -> 42825 | B14: =+'Indice Bancos'!I18 -> -0.0015721468 | C14: =+'Indice Bancos'!J18 -> 0.0048979052 | D14: =+'Indice Bancos'!K18 -> 0.0077069435 | E14: =+'Indice Bancos'!L18 -> 0.092611524 | G14: =+'Indice Bancos'!M18 -> 0.028430203
... A90: =+'Indice Bancos'!B94 -> 43357 | B90: =+'Indice Bancos'!I94 -> 0.0087729808 | C90: =+'Indice Bancos'!J94 -> -0.0031597551 | D90: =+'Indice Bancos'!K94 -> -0.01992133 | E90: =+'Indice Bancos'!L94 -> -0.051913503 | G90: =+'Indice Bancos'!M94 -> 0.012284301
A91: =+'Indice Bancos'!B95 -> 43364 | B91: =+'Indice Bancos'!I95 -> 0.30608636 | C91: =+'Indice Bancos'!J95 -> 0.14787787 | D91: =+'Indice Bancos'!K95 -> 0.2886296 | E91: =+'Indice Bancos'!L95 -> 0.25584239 | G91: =+'Indice Bancos'!M95 -> 0.13750972 | I91: =+A1 -> Dates | J91: =+B1 -> BBAR AR Equity | K91: =+C1 -> BMA AR Equity | L91: =+D1 -> GGAL AR Equity | M91: =+E1 -> SUPV AR Equity
A92: =+'Indice Bancos'!B96 -> 43371 | B92: =+'Indice Bancos'!I96 -> 0.065241993 | C92: =+'Indice Bancos'!J96 -> -0.05075861 | D92: =+'Indice Bancos'!K96 -> -0.04777274 | E92: =+'Indice Bancos'!L96 -> -0.086483985 | G92: =+'Indice Bancos'!M96 -> -0.025208931 | I92: =+A92 -> 43371 | J92: =+SLOPE(B3:B92,$G3:$G92) -> 1.1661612 | K92: =+SLOPE(C3:C92,$G3:$G92) -> 1.040295 | L92: =+SLOPE(D3:D92,$G3:$G92) -> 1.0863557 | M92: =+SLOPE(E3:E92,$G3:$G92) -> 1.590764
A93: =+'Indice Bancos'!B97 -> 43378 | B93: =+'Indice Bancos'!I97 -> -0.12249234 | C93: =+'Indice Bancos'!J97 -> -0.098514233 | D93: =+'Indice Bancos'!K97 -> -0.13487992 | E93: =+'Indice Bancos'!L97 -> -0.11893781 | G93: =+'Indice Bancos'!M97 -> -0.098412308 | I93: =+A93 -> 43378 | J93: =+SLOPE(B4:B93,$G4:$G93) -> 1.1797826 | K93: =+SLOPE(C4:C93,$G4:$G93) -> 1.0405589 | L93: =+SLOPE(D4:D93,$G4:$G93) -> 1.1007745 | M93: =+SLOPE(E4:E93,$G4:$G93) -> 1.569407
A94: =+'Indice Bancos'!B98 -> 43385 | B94: =+'Indice Bancos'!I98 -> -0.081199399 | C94: =+'Indice Bancos'!J98 -> -0.045132179 | D94: =+'Indice Bancos'!K98 -> 0 | E94: =+'Indice Bancos'!L98 -> -0.028414499 | G94: =+'Indice Bancos'!M98 -> -0.018911641 | I94: =+A94 -> 43385 | J94: =+SLOPE(B5:B94,$G5:$G94) -> 1.1879782 | K94: =+SLOPE(C5:C94,$G5:$G94) -> 1.0436206 | L94: =+SLOPE(D5:D94,$G5:$G94) -> 1.097823 | M94: =+SLOPE(E5:E94,$G5:$G94) -> 1.5690176
A95: =+'Indice Bancos'!B99 -> 43392 | B95: =+'Indice Bancos'!I99 -> -0.039152481 | C95: =+'Indice Bancos'!J99 -> -0.070225014 | D95: =+'Indice Bancos'!K99 -> -0.079318861 | E95: =+'Indice Bancos'!L99 -> -0.060327762 | G95: =+'Indice Bancos'!M99 -> -0.031248543 | I95: =+A95 -> 43392 | J95: =+SLOPE(B6:B95,$G6:$G95) -> 1.1872763 | K95: =+SLOPE(C6:C95,$G6:$G95) -> 1.0505007 | L95: =+SLOPE(D6:D95,$G6:$G95) -> 1.1083172 | M95: =+SLOPE(E6:E95,$G6:$G95) -> 1.5708471
A96: =+'Indice Bancos'!B100 -> 43399 | B96: =+'Indice Bancos'!I100 -> 0.077859268 | C96: =+'Indice Bancos'!J100 -> 0.14270019 | D96: =+'Indice Bancos'!K100 -> 0.0095044128 | E96: =+'Indice Bancos'!L100 -> 0.13228938 | G96: =+'Indice Bancos'!M100 -> 0.024294047 | I96: =+A96 -> 43399 | J96: =+SLOPE(B7:B96,$G7:$G96) -> 1.1925344 | K96: =+SLOPE(C7:C96,$G7:$G96) -> 1.0621762 | L96: =+SLOPE(D7:D96,$G7:$G96) -> 1.1070097 | M96: =+SLOPE(E7:E96,$G7:$G96) -> 1.5807255
A97: =+'Indice Bancos'!B101 -> 43406 | B97: =+'Indice Bancos'!I101 -> 0.10179253 | C97: =+'Indice Bancos'!J101 -> 0.091831325 | D97: =+'Indice Bancos'!K101 -> 0.12831532 | E97: =+'Indice Bancos'!L101 -> 0.10910346 | G97: =+'Indice Bancos'!M101 -> 0.069778654 | I97: =+A97 -> 43406 | J97: =+SLOPE(B8:B97,$G8:$G97) -> 1.1991495 | K97: =+SLOPE(C8:C97,$G8:$G97) -> 1.0646676 | L97: =+SLOPE(D8:D97,$G8:$G97) -> 1.1204364 | M97: =+SLOPE(E8:E97,$G8:$G97) -> 1.5815166
A98: =+'Indice Bancos'!B102 -> 43413 | B98: =+'Indice Bancos'!I102 -> -0.080160424 | C98: =+'Indice Bancos'!J102 -> -0.095456378 | D98: =+'Indice Bancos'!K102 -> -0.05842419 | E98: =+'Indice Bancos'!L102 -> -0.082114074 | G98: =+'Indice Bancos'!M102 -> -0.04795689 | I98: =+A98 -> 43413 | J98: =+SLOPE(B9:B98,$G9:$G98) -> 1.2061517 | K98: =+SLOPE(C9:C98,$G9:$G98) -> 1.0777 | L98: =+SLOPE(D9:D98,$G9:$G98) -> 1.1225471 | M98: =+SLOPE(E9:E98,$G9:$G98) -> 1.5815489
A99: =+'Indice Bancos'!B103 -> 43420 | B99: =+'Indice Bancos'!I103 -> 0.11521218 | C99: =+'Indice Bancos'!J103 -> 0.099424995 | D99: =+'Indice Bancos'!K103 -> 0.064812956 | E99: =+'Indice Bancos'!L103 -> 0.064984738 | G99: =+'Indice Bancos'!M103 -> 0.040008705 | I99: =+A99 -> 43420 | J99: =+SLOPE(B10:B99,$G10:$G99) -> 1.2142784 | K99: =+SLOPE(C10:C99,$G10:$G99) -> 1.0913139 | L99: =+SLOPE(D10:D99,$G10:$G99) -> 1.1195718 | M99: =+SLOPE(E10:E99,$G10:$G99) -> 1.5874727
A100: =+'Indice Bancos'!B104 -> 43427 | B100: =+'Indice Bancos'!I104 -> -0.013909967 | C100: =+'Indice Bancos'!J104 -> 0.0049735187 | D100: =+'Indice Bancos'!K104 -> 0.01248387 | E100: =+'Indice Bancos'!L104 -> 0.057852556 | G100: =+'Indice Bancos'!M104 -> -0.012400492 | I100: =+A100 -> 43427 | J100: =+SLOPE(B11:B100,$G11:$G100) -> 1.2143864 | K100: =+SLOPE(C11:C100,$G11:$G100) -> 1.0891966 | L100: =+SLOPE(D11:D100,$G11:$G100) -> 1.1170101 | M100: =+SLOPE(E11:E100,$G11:$G100) -> 1.5797111
A101: =+'Indice Bancos'!B105 -> 43434 | B101: =+'Indice Bancos'!I105 -> 0.006716745 | C101: =+'Indice Bancos'!J105 -> -0.010778897 | D101: =+'Indice Bancos'!K105 -> 0.047286267 | E101: =+'Indice Bancos'!L105 -> -0.0037462579 | G101: =+'Indice Bancos'!M105 -> 0.024707488 | I101: =+A101 -> 43434 | J101: =+SLOPE(B12:B101,$G12:$G101) -> 1.2129985 | K101: =+SLOPE(C12:C101,$G12:$G101) -> 1.0871299 | L101: =+SLOPE(D12:D101,$G12:$G101) -> 1.1208176 | M101: =+SLOPE(E12:E101,$G12:$G101) -> 1.5773643
A102: =+'Indice Bancos'!B106 -> 43441 | B102: =+'Indice Bancos'!I106 -> -0.0023285951 | C102: =+'Indice Bancos'!J106 -> -0.046215829 | D102: =+'Indice Bancos'!K106 -> 0.016682164 | E102: =+'Indice Bancos'!L106 -> 0.0052544109 | G102: =+'Indice Bancos'!M106 -> 0.0021542072 | I102: =+A102 -> 43441 | J102: =+SLOPE(B13:B102,$G13:$G102) -> 1.2113617 | K102: =+SLOPE(C13:C102,$G13:$G102) -> 1.0895954 | L102: =+SLOPE(D13:D102,$G13:$G102) -> 1.1193485 | M102: =+SLOPE(E13:E102,$G13:$G102) -> 1.5764473
A103: =+'Indice Bancos'!B107 -> 43448 | B103: =+'Indice Bancos'!I107 -> -0.034442167 | C103: =+'Indice Bancos'!J107 -> -0.0098795601 | D103: =+'Indice Bancos'!K107 -> 0.021236819 | E103: =+'Indice Bancos'!L107 -> -0.014211282 | G103: =+'Indice Bancos'!M107 -> -0.013976051 | I103: =+A103 -> 43448 | J103: =+SLOPE(B14:B103,$G14:$G103) -> 1.2133374 | K103: =+SLOPE(C14:C103,$G14:$G103) -> 1.0881294 | L103: =+SLOPE(D14:D103,$G14:$G103) -> 1.1133065 | M103: =+SLOPE(E14:E103,$G14:$G103) -> 1.5763262
... A511: =+'Indice Bancos'!B515 -> 46304 | B511: =+'Indice Bancos'!I515 -> 0.0074074074 | C511: =+'Indice Bancos'!J515 -> -0.0057142857 | D511: =+'Indice Bancos'!K515 -> 0.017994859 | E511: =+'Indice Bancos'!L515 -> 0.028901734 | G511: =+'Indice Bancos'!M515 -> 0.021810459 | I511: =+A511 -> 46304 | J511: =+SLOPE(B422:B511,$G422:$G511) -> 1.3808373 | K511: =+SLOPE(C422:C511,$G422:$G511) -> 1.2639558 | L511: =+SLOPE(D422:D511,$G422:$G511) -> 1.3253954 | M511: =+SLOPE(E422:E511,$G422:$G511) -> 1.6760156

Sheet BASE
A1: BMA AR Equity | F1: GGAL AR Equity | K1: BBAR AR Equity | P1: VALO AR Equity | AC1: =+AVERAGE(AB3:AB2000) -> 1.2128981 | AD1: =+_xlfn.STDEV.S(AB3:AB2000) -> 0.64294819
A2: Date | B2: RETURN_COM_EQY | C2: PX_TO_BOOK_RATIO | D2: PE_RATIO | E2: CUR_MKT_CAP | F2: Date | G2: RETURN_COM_EQY | H2: PX_TO_BOOK_RATIO | I2: PE_RATIO | J2: CUR_MKT_CAP | K2: Date | L2: RETURN_COM_EQY | M2: PX_TO_BOOK_RATIO | N2: PE_RATIO | O2: CUR_MKT_CAP | P2: Date | Q2: RETURN_COM_EQY | R2: PX_TO_BOOK_RATIO | S2: PE_RATIO | AA2: =+A2 -> Date | AB2: PBV Sector | AC2: Z Score | AD2: Relativo | AE2: Q90 | AF2: Q75 | AG2: Q50 | AH2: Q25 | AI2: Q10
A3: =_xll.BDH($A$1,$B$2:$E$2,"02/10/2001","","FX=ARS","Dir=V","Dts=S","Sort=A","Quote=C","QtTyp=Y","Days=T","Per=cw","DtFmt=D","UseDPDF=Y","cols=5;rows=1304") -> 37169 | B3: -80.7193 | C3: 0.1066 | D3: #N/A N/A | E3: 21.0622 | F3: =_xll.BDH($F$1,$G$2:$J$2,"02/10/2001","","FX=ARS","Dir=V","Dts=S","Sort=A","Quote=C","QtTyp=Y","Days=T","Per=cw","DtFmt=D","UseDPDF=Y","cols=5;rows=1304") -> 37169 | G3: 13.5991 | H3: 0.2712 | I3: 1.9387 | J3: 551.6654 | K3: =_xll.BDH($K$1,$L$2:$O$2,"02/10/2001","","FX=ARS","Dir=V","Dts=S","Sort=A","Quote=C","QtTyp=Y","Days=T","Per=cw","DtFmt=D","UseDPDF=Y","cols=5;rows=1304") -> 37169 | L3: 17.8185 | M3: 0.2236 | N3: 1.2198 | O3: 545.0406 | AA3: =+A3 -> 37169 | AB3: =+(C3*E3+H3*J3+M3*O3)/(E3+J3+O3) -> 0.24488795 | AC3: =+(AB3-$AC$1)/$AD$1 -> -1.5055804
A4: 37176 | B4: -80.7193 | C4: 0.1076 | D4: #N/A N/A | E4: 21.2554 | F4: 37176 | G4: 13.5991 | H4: 0.3136 | I4: 2.242 | J4: 637.9655 | K4: 37176 | L4: 17.8185 | M4: 0.2408 | N4: 1.3136 | O4: 586.9668 | AA4: =+A4 -> 37176 | AB4: =+(C4*E4+H4*J4+M4*O4)/(E4+J4+O4) -> 0.27579687 | AC4: =+(AB4-$AC$1)/$AD$1 -> -1.4575067
A5: 37183 | B5: -80.7193 | C5: 0.15 | D5: #N/A N/A | E5: 29.6288 | F5: 37183 | G5: 13.5991 | H5: 0.3598 | I5: 2.5722 | J5: 731.9125 | K5: 37183 | L5: 17.8185 | M5: 0.2735 | N5: 1.4919 | O5: 666.6266 | AA5: =+A5 -> 37183 | AB5: =+(C5*E5+H5*J5+M5*O5)/(E5+J5+O5) -> 0.31516519 | AC5: =+(AB5-$AC$1)/$AD$1 -> -1.3962757
A6: 37190 | B6: -80.7193 | C6: 0.1565 | D6: #N/A N/A | E6: 30.917 | F6: 37190 | G6: 13.5991 | H6: 0.3377 | I6: 2.4148 | J6: 687.1238 | K6: 37190 | L6: 17.8185 | M6: 0.2554 | N6: 1.3934 | O6: 622.6041 | AA6: =+A6 -> 37190 | AB6: =+(C6*E6+H6*J6+M6*O6)/(E6+J6+O6) -> 0.29530065 | AC6: =+(AB6-$AC$1)/$AD$1 -> -1.4271717
A7: 37197 | B7: -80.7193 | C7: 0.1483 | D7: #N/A N/A | E7: 29.3067 | F7: 37197 | G7: 13.5991 | H7: 0.2631 | I7: 1.8811 | J7: 535.2793 | K7: 37197 | L7: 17.8185 | M7: 0.2305 | N7: 1.2573 | O7: 561.8111 | AA7: =+A7 -> 37197 | AB7: =+(C7*E7+H7*J7+M7*O7)/(E7+J7+O7) -> 0.24385328 | AC7: =+(AB7-$AC$1)/$AD$1 -> -1.5071896
A8: 37204 | B8: -80.7193 | C8: 0.1298 | D8: #N/A N/A | E8: 25.6353 | F8: 37204 | G8: 13.5991 | H8: 0.2733 | I8: 1.9541 | J8: 556.035 | K8: 37204 | L8: 17.8185 | M8: 0.2528 | N8: 1.3793 | O8: 616.3151 | AA8: =+A8 -> 37204 | AB8: =+(C8*E8+H8*J8+M8*O8)/(E8+J8+O8) -> 0.25968287 | AC8: =+(AB8-$AC$1)/$AD$1 -> -1.4825693
A9: 37211 | B9: -80.7193 | C9: 0.1252 | D9: #N/A N/A | E9: 24.7336 | F9: 37211 | G9: 13.5991 | H9: 0.2658 | I9: 1.9003 | J9: 540.7413 | K9: 37211 | L9: 17.8185 | M9: 0.2193 | N9: 1.1963 | O9: 534.559 | AA9: =+A9 -> 37211 | AB9: =+(C9*E9+H9*J9+M9*O9)/(E9+J9+O9) -> 0.24004212 | AC9: =+(AB9-$AC$1)/$AD$1 -> -1.5131173
A10: 37218 | B10: -80.7193 | C10: #N/A N/A | D10: #N/A N/A | E10: 24.7336 | F10: 37218 | G10: 13.5991 | H10: 0.255 | I10: 1.8235 | J10: 518.8932 | K10: 37218 | L10: 17.8185 | M10: 0.2176 | N10: 1.187 | O10: 530.3664 | AA10: =+A10 -> 37218 | AB10: =+(C9*E10+H10*J10+M10*O10)/(E10+J10+O10) -> 0.23354165 | AC10: =+(AB10-$AC$1)/$AD$1 -> -1.5232277
A11: 37225 | B11: -80.7193 | C11: #N/A N/A | D11: #N/A N/A | E11: 24.7336 | F11: 37225 | G11: 13.5991 | H11: 0.2164 | I11: 1.5471 | J11: 440.2399 | K11: 37225 | L11: 17.8185 | M11: 0.2193 | N11: 1.1963 | O11: 534.559 | AA11: =+A11 -> 37225 | AB11: =+(C9*E11+H11*J11+M11*O11)/(E11+J11+O11) -> 0.21569419 | AC11: =+(AB11-$AC$1)/$AD$1 -> -1.5509865
A12: 37232 | B12: -80.7193 | C12: 0.1174 | D12: #N/A N/A | E12: 23.1877 | F12: 37232 | G12: 13.5991 | H12: 0.247 | I12: 1.766 | J12: 502.5071 | K12: 37232 | L12: 17.8185 | M12: 0.2494 | N12: 1.3605 | O12: 607.9299 | AA12: =+A12 -> 37232 | AB12: =+(C12*E12+H12*J12+M12*O12)/(E12+J12+O12) -> 0.24563615 | AC12: =+(AB12-$AC$1)/$AD$1 -> -1.5044167
A13: 37239 | B13: -80.7193 | C13: 0.1206 | D13: #N/A N/A | E13: 23.8318 | F13: 37239 | G13: 13.5991 | H13: 0.2228 | I13: 1.5932 | J13: 453.3488 | K13: 37239 | L13: 17.8185 | M13: 0.2365 | N13: 1.2902 | O13: 576.4852 | AA13: =+A13 -> 37239 | AB13: =+(C13*E13+H13*J13+M13*O13)/(E13+J13+O13) -> 0.22798403 | AC13: =+(AB13-$AC$1)/$AD$1 -> -1.5318716
A14: 37246 | B14: -80.7193 | C14: 0.1206 | D14: #N/A N/A | E14: 23.8318 | F14: 37246 | G14: 13.5991 | H14: 0.2524 | I14: 1.8043 | J14: 513.4311 | K14: 37246 | L14: 17.8185 | M14: 0.258 | N14: 1.4075 | O14: 628.893 | AA14: =+A14 -> 37246 | AB14: =+(C14*E14+H14*J14+M14*O14)/(E14+J14+O14) -> 0.25272652 | AC14: =+(AB14-$AC$1)/$AD$1 -> -1.4933888
A15: 37253 | B15: -92.054 | C15: 0.1936 | D15: #N/A N/A | E15: 23.1877 | F15: 37253 | G15: 8.7976 | H15: 0.2503 | I15: 2.6034 | J15: 504.6919 | K15: 37253 | L15: 1.3953 | M15: 0.3075 | N15: 6.0472 | O15: 618.4114 | AA15: =+A15 -> 37253 | AB15: =+(C15*E15+H15*J15+M15*O15)/(E15+J15+O15) -> 0.28001182 | AC15: =+(AB15-$AC$1)/$AD$1 -> -1.450951
A16: 37260 | B16: -92.054 | C16: 0.2043 | D16: #N/A N/A | E16: 24.4759 | F16: 37260 | G16: 8.7976 | H16: 0.2704 | I16: 2.8119 | J16: 545.1109 | K16: 37260 | L16: 1.3953 | M16: 0.3575 | N16: 7.0311 | O16: 719.0343 | AA16: =+A16 -> 37260 | AB16: =+(C16*E16+H16*J16+M16*O16)/(E16+J16+O16) -> 0.31774521 | AC16: =+(AB16-$AC$1)/$AD$1 -> -1.3922629
A17: 37274 | B17: -92.054 | C17: 0.2097 | D17: #N/A N/A | E17: 25.12 | F17: 37274 | G17: 8.7976 | H17: 0.2655 | I17: 2.7612 | J17: 535.2793 | K17: 37274 | L17: 1.3953 | M17: 0.2866 | N17: 5.6372 | O17: 576.4852 | AA17: =+A17 -> 37274 | AB17: =+(C17*E17+H17*J17+M17*O17)/(E17+J17+O17) -> 0.27496635 | AC17: =+(AB17-$AC$1)/$AD$1 -> -1.4587984
A18: 37281 | B18: -92.054 | C18: 0.2689 | D18: #N/A N/A | E18: 32.2052 | F18: 37281 | G18: 8.7976 | H18: 0.3088 | I18: 3.212 | J18: 622.6718 | K18: 37281 | L18: 1.3953 | M18: 0.3179 | N18: 6.2522 | O18: 639.3745 | AA18: =+A18 -> 37281 | AB18: =+(C18*E18+H18*J18+M18*O18)/(E18+J18+O18) -> 0.31230266 | AC18: =+(AB18-$AC$1)/$AD$1 -> -1.4007279
A19: 37288 | B19: -92.054 | C19: 0.2662 | D19: #N/A N/A | E19: 31.8831 | F19: 37288 | G19: 8.7976 | H19: 0.2763 | I19: 2.8739 | J19: 557.1274 | K19: 37288 | L19: 1.3953 | M19: 0.37 | N19: 7.2771 | O19: 744.19 | AA19: =+A19 -> 37288 | AB19: =+(C19*E19+H19*J19+M19*O19)/(E19+J19+O19) -> 0.32836162 | AC19: =+(AB19-$AC$1)/$AD$1 -> -1.3757508
A20: 37295 | B20: -92.054 | C20: 0.2097 | D20: #N/A N/A | E20: 25.12 | F20: 37295 | G20: 8.7976 | H20: 0.2357 | I20: 2.4513 | J20: 475.1969 | K20: 37295 | L20: 1.3953 | M20: 0.2971 | N20: 5.8422 | O20: 597.4483 | AA20: =+A20 -> 37295 | AB20: =+(C20*E20+H20*J20+M20*O20)/(E20+J20+O20) -> 0.26852141 | AC20: =+(AB20-$AC$1)/$AD$1 -> -1.4688224
A21: 37302 | B21: -92.054 | C21: 0.2151 | D21: #N/A N/A | E21: 25.7641 | F21: 37302 | G21: 8.7976 | H21: 0.1869 | I21: 1.9441 | J21: 376.8803 | K21: 37302 | L21: 1.3953 | M21: 0.2366 | N21: 4.6533 | O21: 475.8624 | AA21: =+A21 -> 37302 | AB21: =+(C21*E21+H21*J21+M21*O21)/(E21+J21+O21) -> 0.21464812 | AC21: =+(AB21-$AC$1)/$AD$1 -> -1.5526135
A22: 37309 | B22: -92.054 | C22: 0.2259 | D22: #N/A N/A | E22: 27.0523 | F22: 37309 | G22: 8.7976 | H22: 0.1409 | I22: 1.4651 | J22: 284.0257 | K22: 37309 | L22: 1.3953 | M22: 0.1928 | N22: 3.7923 | O22: 387.8173 | AA22: =+A22 -> 37309 | AB22: =+(C22*E22+H22*J22+M22*O22)/(E22+J22+O22) -> 0.17298945 | AC22: =+(AB22-$AC$1)/$AD$1 -> -1.6174067
A23: 37316 | B23: -92.054 | C23: 0.2285 | D23: #N/A N/A | E23: 27.3744 | F23: 37316 | G23: 8.7976 | H23: 0.2438 | I23: 2.5358 | J23: 491.583 | K23: 37316 | L23: 1.3953 | M23: 0.2408 | N23: 4.7352 | O23: 484.2476 | AA23: =+A23 -> 37316 | AB23: =+(C23*E23+H23*J23+M23*O23)/(E23+J23+O23) -> 0.24193441 | AC23: =+(AB23-$AC$1)/$AD$1 -> -1.5101741
... A26: 37337 | B26: -92.054 | C26: 0.1995 | D26: #N/A N/A | E26: 23.8962 | F26: 37337 | G26: 8.7976 | H26: 0.2319 | I26: 2.4118 | J26: 467.55 | K26: 37337 | L26: 1.3953 | M26: 0.2866 | N26: 5.6372 | O26: 576.4852 | AA26: =+A26 -> 37337 | AB26: =+(C26*E26+H26*J26+M26*O26)/(E26+J26+O26) -> 0.26070288 | AC26: =+(AB26-$AC$1)/$AD$1 -> -1.4809829
A27: 37344 | B27: 35.7337 | C27: 0.0163 | D27: 0.079 | E27: 24.1539 | F27: 37344 | G27: 8.7976 | H27: 0.227 | I27: 2.3611 | J27: 457.7184 | K27: 37344 | L27: -5.2097 | M27: 0.169 | N27: 5.4117 | O27: 549.2332 | AA27: =+A27 -> 37344 | AB27: =+(C27*E27+H27*J27+M27*O27)/(E27+J27+O27) -> 0.19116977 | AC27: =+(AB27-$AC$1)/$AD$1 -> -1.5891302
A28: 37351 | B28: 35.7337 | C28: 0.0148 | D28: 0.0716 | E28: 21.8995 | F28: 37351 | G28: 8.7976 | H28: 0.2048 | I28: 2.1301 | J28: 412.9297 | K28: 37351 | L28: -5.2097 | M28: 0.1722 | N28: #N/A N/A | O28: 559.7148 | AA28: =+A28 -> 37351 | AB28: =+(C28*E28+H28*J28+M28*O28)/(E28+J28+O28) -> 0.18226947 | AC28: =+(AB28-$AC$1)/$AD$1 -> -1.6029731
A29: 37358 | B29: 35.7337 | C29: 0.0146 | D29: 0.0703 | E29: 21.5131 | F29: 37358 | G29: 8.7976 | H29: 0.1923 | I29: 2.0005 | J29: 387.8044 | K29: 37358 | L29: -5.2097 | M29: 0.138 | N29: #N/A N/A | O29: 448.6103 | AA29: =+A29 -> 37358 | AB29: =+(C29*E29+H29*J29+M29*O29)/(E29+J29+O29) -> 0.1594506 | AC29: =+(AB29-$AC$1)/$AD$1 -> -1.6384641
A30: 37365 | B30: 35.7337 | C30: 0.0174 | D30: 0.084 | E30: 25.6997 | F30: 37365 | G30: 8.7976 | H30: 0.233 | I30: 2.4231 | J30: 469.7349 | K30: 37365 | L30: -5.2097 | M30: 0.1838 | N30: #N/A N/A | O30: 597.4483 | AA30: =+A30 -> 37365 | AB30: =+(C30*E30+H30*J30+M30*O30)/(E30+J30+O30) -> 0.2010338 | AC30: =+(AB30-$AC$1)/$AD$1 -> -1.5737883
A31: 37379 | B31: 35.7337 | C31: 0.0161 | D31: 0.0779 | E31: 23.8318 | F31: 37379 | G31: 8.7976 | H31: 0.2227 | I31: 2.316 | J31: 448.9791 | K31: 37379 | L31: -5.2097 | M31: 0.1729 | N31: #N/A N/A | O31: 561.8111 | AA31: =+A31 -> 37379 | AB31: =+(C31*E31+H31*J31+M31*O31)/(E31+J31+O31) -> 0.19089917 | AC31: =+(AB31-$AC$1)/$AD$1 -> -1.589551
A32: 37386 | B32: 35.7337 | C32: 0.0157 | D32: 0.0758 | E32: 23.1877 | F32: 37386 | G32: 8.7976 | H32: 0.2059 | I32: 2.1413 | J32: 415.1145 | K32: 37386 | L32: -5.2097 | M32: 0.1471 | N32: #N/A N/A | O32: 477.9587 | AA32: =+A32 -> 37386 | AB32: =+(C32*E32+H32*J32+M32*O32)/(E32+J32+O32) -> 0.17041418 | AC32: =+(AB32-$AC$1)/$AD$1 -> -1.6214121
A33: 37393 | B33: 35.7337 | C33: 0.0156 | D33: 0.0756 | E33: 23.1233 | F33: 37393 | G33: 8.7976 | H33: 0.1891 | I33: 1.9667 | J33: 381.2499 | K33: 37393 | L33: -5.2097 | M33: 0.1419 | N33: #N/A N/A | O33: 461.1882 | AA33: =+A33 -> 37393 | AB33: =+(C33*E33+H33*J33+M33*O33)/(E33+J33+O33) -> 0.15931589 | AC33: =+(AB33-$AC$1)/$AD$1 -> -1.6386736
A34: 37400 | B34: 35.7337 | C34: 0.0156 | D34: 0.0756 | E34: 23.1233 | F34: 37400 | G34: 8.7976 | H34: 0.1533 | I34: 1.5947 | J34: 309.1511 | K34: 37400 | L34: -5.2097 | M34: 0.1213 | N34: #N/A N/A | O34: 394.1063 | AA34: =+A34 -> 37400 | AB34: =+(C34*E34+H34*J34+M34*O34)/(E34+J34+O34) -> 0.13155454 | AC34: =+(AB34-$AC$1)/$AD$1 -> -1.6818518
A35: 37407 | B35: 35.7337 | C35: 0.0183 | D35: 0.0885 | E35: 27.0523 | F35: 37407 | G35: 8.7976 | H35: 0.1571 | I35: 1.6342 | J35: 316.7979 | K35: 37407 | L35: -5.2097 | M35: 0.1258 | N35: #N/A N/A | O35: 408.7804 | AA35: =+A35 -> 37407 | AB35: =+(C35*E35+H35*J35+M35*O35)/(E35+J35+O35) -> 0.13511088 | AC35: =+(AB35-$AC$1)/$AD$1 -> -1.6763205
A36: 37414 | B36: 35.7337 | C36: 0.0233 | D36: 0.1127 | E36: 34.4595 | F36: 37414 | G36: 8.7976 | H36: 0.1246 | I36: 1.2961 | J36: 251.2535 | K36: 37414 | L36: -5.2097 | M36: 0.1464 | N36: #N/A N/A | O36: 475.8624 | AA36: =+A36 -> 37414 | AB36: =+(C36*E36+H36*J36+M36*O36)/(E36+J36+O36) -> 0.13363791 | AC36: =+(AB36-$AC$1)/$AD$1 -> -1.6786115
A37: 37421 | B37: 35.7337 | C37: 0.0205 | D37: 0.099 | E37: 30.2729 | F37: 37421 | G37: 8.7976 | H37: 0.0786 | I37: 0.8171 | J37: 158.399 | K37: 37421 | L37: -5.2097 | M37: 0.1032 | N37: #N/A N/A | O37: 335.4096 | AA37: =+A37 -> 37421 | AB37: =+(C37*E37+H37*J37+M37*O37)/(E37+J37+O37) -> 0.090987807 | AC37: =+(AB37-$AC$1)/$AD$1 -> -1.7449467
A38: 37428 | B38: 35.7337 | C38: 0.0196 | D38: 0.0948 | E38: 28.9847 | F38: 37428 | G38: 8.7976 | H38: 0.1029 | I38: 1.0707 | J38: 207.5573 | K38: 37428 | L38: -5.2097 | M38: 0.1097 | N38: #N/A N/A | O38: 356.3727 | AA38: =+A38 -> 37428 | AB38: =+(C38*E38+H38*J38+M38*O38)/(E38+J38+O38) -> 0.10291503 | AC38: =+(AB38-$AC$1)/$AD$1 -> -1.7263959
