Workbook
Name MIN_BANCOS: Parametros!$B$5
Name MIN_OBS_ROLL: Parametros!$B$6
Name MIN_OBS_Z: Parametros!$B$7
Name Z_CLIP: Parametros!$B$8
Name AMPLITUD: Parametros!$B$9
Name W_BANCOS: Parametros!$B$10
Name COSTO: Parametros!$B$11
Name FECHA_ERA: Parametros!$B$12
Name INICIO_VIVO: Parametros!$B$13
Name MESES_EVAL: Parametros!$B$14

Sheet LEEME
A1: Seguimiento en vivo de la regla H_OVR3
A2: Reversión tras sobrerreacciones de los bancos al riesgo país (EMBI). Sobre/sub-ponderación de bancos vs Merval.
A4: Qué hace la regla
A5: 1. Mide el spread de los bancos contra el Merval ajustado por β (T2), sobre retornos en exceso de la Badlar.
A6: 2. Estima con los 36 meses previos cuánto se mueve ese spread por cada variación del EMBI (β_E).
A7: 3. El residuo de cada mes es lo que los bancos se movieron de más (o de menos) respecto de lo que explica el EMBI. El gap suma los últimos 3 meses.
A8: 4. El gap se estandariza con toda su historia disponible (z expansivo, recortado a ±3). Score = −z: si los bancos cayeron de más, el score es positivo.
A9: 5. m = 1 + 0.2·tanh(score) va de 0.8 a 1.2. Se aplica el promedio de los últimos 3 meses (cada señal se mantiene 3 meses).
A10: 6. Peso de bancos en la cartera = m × peso de bancos en el benchmark, durante el mes siguiente.
A12: Fórmulas (iguales al código Python)
A13: rf_t = ln(1 + Badlar_{t−1}/1200) · XB_t = ln(1 + r_bancos,t) − rf_t · XM_t = ln(1 + r_Merval,t) − rf_t
A14: β_t = cov(XB, XM) / var(XM), ventana de 36 meses hasta t−1 (mínimo 24) · T2_t = XB_t − β_t·XM_t
... A36: Origen: proyecto bancos_model_prod, xs_model/build_excel_hovr3.py (METHODOLOGY §14).

Sheet Tablero
A1: H_OVR3 — Reversión tras sobrerreacciones de los bancos al EMBI
A2: Paper trading: OW/UW de bancos vs Merval. Regla congelada el 2026-10-10. Se actualiza sola al cargar la hoja Datos.
A4: SEÑAL VIGENTE
A5: Última fila con señal | B5: =MAX(Calculo!$BI$5:$BI$352)
A6: Fecha de la señal (cierre de mes) | B6: =IF(B5>0,INDEX(Calculo!$A:$A,B5),"")
A7: Gap de 3 meses (residuo acumulado) | B7: =IF(B5>0,INDEX(Calculo!$AP:$AP,B5),"")
A8: Score (positivo = bancos cayeron de más) | B8: =IF(B5>0,INDEX(Calculo!$AW:$AW,B5),"")
A9: m del mes | B9: =IF(B5>0,INDEX(Calculo!$AX:$AX,B5),"")
A10: m A APLICAR el mes siguiente (promedio 3 meses) | B10: =IF(B5>0,INDEX(Calculo!$AY:$AY,B5),"")
A11: Lectura | B11: =IF(ISNUMBER(B10),IF(B10>=1,"Sobreponderar bancos ","Subponderar bancos ")&TEXT(ABS(B10-1),"0.0%")&" sobre su peso en el benchmark","")
A12: Ejemplo: peso de bancos si el benchmark pesa W_BANCOS | B12: =IF(ISNUMBER(B10),B10*W_BANCOS,"")
A14: SEGUIMIENTO EN VIVO
A15: Primer mes en vivo (retorno) | B15: =INICIO_VIVO
A16: Meses en vivo | B16: =SUM(Calculo!$BG$5:$BG$352)
A17: Activo neto acumulado en vivo (pb, con W_BANCOS) | B17: =IF(B16>0,SUM(Calculo!$BH$5:$BH$352)*10000,"")
A18: IR anualizado en vivo | B18: =IF(B16>=2,AVERAGE(Calculo!$BH$5:$BH$352)/STDEV(Calculo!$BH$5:$BH$352)*SQRT(12),"")
A19: Acierto (meses con activo > 0) | B19: =IF(B16>0,COUNTIF(Calculo!$BH$5:$BH$352,">0")/B16,"")
A20: ESTADO DE LA REGLA | B20: =IF(B16<MESES_EVAL,"EN EVALUACIÓN ("&B16&" de "&MESES_EVAL&" meses)",IF(B18<0,"DESCARTAR: IR en vivo negativo a los "&MESES_EVAL&" meses","MANTENER: IR en vivo ≥ 0"))
A22: CONTEXTO: BACKTEST (fuera de muestra, post hoc)
A23: IR era A (hasta 2016-05) | B23: =AVERAGE(Calculo!$BE$5:$BE$352)/STDEV(Calculo!$BE$5:$BE$352)*SQRT(12) | C23: Python: 0.56
A24: IR era B (desde 2016-06) | B24: =AVERAGE(Calculo!$BF$5:$BF$352)/STDEV(Calculo!$BF$5:$BF$352)*SQRT(12) | C24: Python: 0.19
A25: IR total | B25: =AVERAGE(Calculo!$BC$5:$BC$352)/STDEV(Calculo!$BC$5:$BC$352)*SQRT(12) | C25: Python: 0.33
A26: Activo promedio (pb/año, con W_BANCOS) | B26: =AVERAGE(Calculo!$BC$5:$BC$352)*12*10000 | C26: Python: 18.7
A28: Cuidado: la regla se eligió después de ver los datos (DSR 0.016 con 194 ensayos). El backtest es contexto, no evidencia. La decisión se toma sólo con los meses en vivo.
A30: ÚLTIMOS 12 MESES
A31: Fecha | B31: Score | C31: m del mes | D31: m a aplicar | E31: Spread T2 del mes | F31: Activo neto (pb) | G31: En vivo
A32: =IF($B$5-11>=5,INDEX(Calculo!$A:$A,$B$5-11),"") | B32: =IF($B$5-11>=5,IF(ISNUMBER(INDEX(Calculo!$AW:$AW,$B$5-11)),INDEX(Calculo!$AW:$AW,$B$5-11),""),"") | C32: =IF($B$5-11>=5,IF(ISNUMBER(INDEX(Calculo!$AX:$AX,$B$5-11)),INDEX(Calculo!$AX:$AX,$B$5-11),""),"") | D32: =IF($B$5-11>=5,IF(ISNUMBER(INDEX(Calculo!$AY:$AY,$B$5-11)),INDEX(Calculo!$AY:$AY,$B$5-11),""),"") | E32: =IF($B$5-11>=5,IF(ISNUMBER(INDEX(Calculo!$W:$W,$B$5-11)),INDEX(Calculo!$W:$W,$B$5-11),""),"") | F32: =IF($B$5-11>=5,IF(ISNUMBER(INDEX(Calculo!$BC:$BC,$B$5-11)),INDEX(Calculo!$BC:$BC,$B$5-11)*10000,""),"") | G32: =IF($B$5-11>=5,IF(ISNUMBER(INDEX(Calculo!$BG:$BG,$B$5-11)),INDEX(Calculo!$BG:$BG,$B$5-11),""),"")
A33: =IF($B$5-10>=5,INDEX(Calculo!$A:$A,$B$5-10),"") | B33: =IF($B$5-10>=5,IF(ISNUMBER(INDEX(Calculo!$AW:$AW,$B$5-10)),INDEX(Calculo!$AW:$AW,$B$5-10),""),"") | C33: =IF($B$5-10>=5,IF(ISNUMBER(INDEX(Calculo!$AX:$AX,$B$5-10)),INDEX(Calculo!$AX:$AX,$B$5-10),""),"") | D33: =IF($B$5-10>=5,IF(ISNUMBER(INDEX(Calculo!$AY:$AY,$B$5-10)),INDEX(Calculo!$AY:$AY,$B$5-10),""),"") | E33: =IF($B$5-10>=5,IF(ISNUMBER(INDEX(Calculo!$W:$W,$B$5-10)),INDEX(Calculo!$W:$W,$B$5-10),""),"") | F33: =IF($B$5-10>=5,IF(ISNUMBER(INDEX(Calculo!$BC:$BC,$B$5-10)),INDEX(Calculo!$BC:$BC,$B$5-10)*10000,""),"") | G33: =IF($B$5-10>=5,IF(ISNUMBER(INDEX(Calculo!$BG:$BG,$B$5-10)),INDEX(Calculo!$BG:$BG,$B$5-10),""),"")
A34: =IF($B$5-9>=5,INDEX(Calculo!$A:$A,$B$5-9),"") | B34: =IF($B$5-9>=5,IF(ISNUMBER(INDEX(Calculo!$AW:$AW,$B$5-9)),INDEX(Calculo!$AW:$AW,$B$5-9),""),"") | C34: =IF($B$5-9>=5,IF(ISNUMBER(INDEX(Calculo!$AX:$AX,$B$5-9)),INDEX(Calculo!$AX:$AX,$B$5-9),""),"") | D34: =IF($B$5-9>=5,IF(ISNUMBER(INDEX(Calculo!$AY:$AY,$B$5-9)),INDEX(Calculo!$AY:$AY,$B$5-9),""),"") | E34: =IF($B$5-9>=5,IF(ISNUMBER(INDEX(Calculo!$W:$W,$B$5-9)),INDEX(Calculo!$W:$W,$B$5-9),""),"") | F34: =IF($B$5-9>=5,IF(ISNUMBER(INDEX(Calculo!$BC:$BC,$B$5-9)),INDEX(Calculo!$BC:$BC,$B$5-9)*10000,""),"") | G34: =IF($B$5-9>=5,IF(ISNUMBER(INDEX(Calculo!$BG:$BG,$B$5-9)),INDEX(Calculo!$BG:$BG,$B$5-9),""),"")
A35: =IF($B$5-8>=5,INDEX(Calculo!$A:$A,$B$5-8),"") | B35: =IF($B$5-8>=5,IF(ISNUMBER(INDEX(Calculo!$AW:$AW,$B$5-8)),INDEX(Calculo!$AW:$AW,$B$5-8),""),"") | C35: =IF($B$5-8>=5,IF(ISNUMBER(INDEX(Calculo!$AX:$AX,$B$5-8)),INDEX(Calculo!$AX:$AX,$B$5-8),""),"") | D35: =IF($B$5-8>=5,IF(ISNUMBER(INDEX(Calculo!$AY:$AY,$B$5-8)),INDEX(Calculo!$AY:$AY,$B$5-8),""),"") | E35: =IF($B$5-8>=5,IF(ISNUMBER(INDEX(Calculo!$W:$W,$B$5-8)),INDEX(Calculo!$W:$W,$B$5-8),""),"") | F35: =IF($B$5-8>=5,IF(ISNUMBER(INDEX(Calculo!$BC:$BC,$B$5-8)),INDEX(Calculo!$BC:$BC,$B$5-8)*10000,""),"") | G35: =IF($B$5-8>=5,IF(ISNUMBER(INDEX(Calculo!$BG:$BG,$B$5-8)),INDEX(Calculo!$BG:$BG,$B$5-8),""),"")
A36: =IF($B$5-7>=5,INDEX(Calculo!$A:$A,$B$5-7),"") | B36: =IF($B$5-7>=5,IF(ISNUMBER(INDEX(Calculo!$AW:$AW,$B$5-7)),INDEX(Calculo!$AW:$AW,$B$5-7),""),"") | C36: =IF($B$5-7>=5,IF(ISNUMBER(INDEX(Calculo!$AX:$AX,$B$5-7)),INDEX(Calculo!$AX:$AX,$B$5-7),""),"") | D36: =IF($B$5-7>=5,IF(ISNUMBER(INDEX(Calculo!$AY:$AY,$B$5-7)),INDEX(Calculo!$AY:$AY,$B$5-7),""),"") | E36: =IF($B$5-7>=5,IF(ISNUMBER(INDEX(Calculo!$W:$W,$B$5-7)),INDEX(Calculo!$W:$W,$B$5-7),""),"") | F36: =IF($B$5-7>=5,IF(ISNUMBER(INDEX(Calculo!$BC:$BC,$B$5-7)),INDEX(Calculo!$BC:$BC,$B$5-7)*10000,""),"") | G36: =IF($B$5-7>=5,IF(ISNUMBER(INDEX(Calculo!$BG:$BG,$B$5-7)),INDEX(Calculo!$BG:$BG,$B$5-7),""),"")
A37: =IF($B$5-6>=5,INDEX(Calculo!$A:$A,$B$5-6),"") | B37: =IF($B$5-6>=5,IF(ISNUMBER(INDEX(Calculo!$AW:$AW,$B$5-6)),INDEX(Calculo!$AW:$AW,$B$5-6),""),"") | C37: =IF($B$5-6>=5,IF(ISNUMBER(INDEX(Calculo!$AX:$AX,$B$5-6)),INDEX(Calculo!$AX:$AX,$B$5-6),""),"") | D37: =IF($B$5-6>=5,IF(ISNUMBER(INDEX(Calculo!$AY:$AY,$B$5-6)),INDEX(Calculo!$AY:$AY,$B$5-6),""),"") | E37: =IF($B$5-6>=5,IF(ISNUMBER(INDEX(Calculo!$W:$W,$B$5-6)),INDEX(Calculo!$W:$W,$B$5-6),""),"") | F37: =IF($B$5-6>=5,IF(ISNUMBER(INDEX(Calculo!$BC:$BC,$B$5-6)),INDEX(Calculo!$BC:$BC,$B$5-6)*10000,""),"") | G37: =IF($B$5-6>=5,IF(ISNUMBER(INDEX(Calculo!$BG:$BG,$B$5-6)),INDEX(Calculo!$BG:$BG,$B$5-6),""),"")
A38: =IF($B$5-5>=5,INDEX(Calculo!$A:$A,$B$5-5),"") | B38: =IF($B$5-5>=5,IF(ISNUMBER(INDEX(Calculo!$AW:$AW,$B$5-5)),INDEX(Calculo!$AW:$AW,$B$5-5),""),"") | C38: =IF($B$5-5>=5,IF(ISNUMBER(INDEX(Calculo!$AX:$AX,$B$5-5)),INDEX(Calculo!$AX:$AX,$B$5-5),""),"") | D38: =IF($B$5-5>=5,IF(ISNUMBER(INDEX(Calculo!$AY:$AY,$B$5-5)),INDEX(Calculo!$AY:$AY,$B$5-5),""),"") | E38: =IF($B$5-5>=5,IF(ISNUMBER(INDEX(Calculo!$W:$W,$B$5-5)),INDEX(Calculo!$W:$W,$B$5-5),""),"") | F38: =IF($B$5-5>=5,IF(ISNUMBER(INDEX(Calculo!$BC:$BC,$B$5-5)),INDEX(Calculo!$BC:$BC,$B$5-5)*10000,""),"") | G38: =IF($B$5-5>=5,IF(ISNUMBER(INDEX(Calculo!$BG:$BG,$B$5-5)),INDEX(Calculo!$BG:$BG,$B$5-5),""),"")
A39: =IF($B$5-4>=5,INDEX(Calculo!$A:$A,$B$5-4),"") | B39: =IF($B$5-4>=5,IF(ISNUMBER(INDEX(Calculo!$AW:$AW,$B$5-4)),INDEX(Calculo!$AW:$AW,$B$5-4),""),"") | C39: =IF($B$5-4>=5,IF(ISNUMBER(INDEX(Calculo!$AX:$AX,$B$5-4)),INDEX(Calculo!$AX:$AX,$B$5-4),""),"") | D39: =IF($B$5-4>=5,IF(ISNUMBER(INDEX(Calculo!$AY:$AY,$B$5-4)),INDEX(Calculo!$AY:$AY,$B$5-4),""),"") | E39: =IF($B$5-4>=5,IF(ISNUMBER(INDEX(Calculo!$W:$W,$B$5-4)),INDEX(Calculo!$W:$W,$B$5-4),""),"") | F39: =IF($B$5-4>=5,IF(ISNUMBER(INDEX(Calculo!$BC:$BC,$B$5-4)),INDEX(Calculo!$BC:$BC,$B$5-4)*10000,""),"") | G39: =IF($B$5-4>=5,IF(ISNUMBER(INDEX(Calculo!$BG:$BG,$B$5-4)),INDEX(Calculo!$BG:$BG,$B$5-4),""),"")
A40: =IF($B$5-3>=5,INDEX(Calculo!$A:$A,$B$5-3),"") | B40: =IF($B$5-3>=5,IF(ISNUMBER(INDEX(Calculo!$AW:$AW,$B$5-3)),INDEX(Calculo!$AW:$AW,$B$5-3),""),"") | C40: =IF($B$5-3>=5,IF(ISNUMBER(INDEX(Calculo!$AX:$AX,$B$5-3)),INDEX(Calculo!$AX:$AX,$B$5-3),""),"") | D40: =IF($B$5-3>=5,IF(ISNUMBER(INDEX(Calculo!$AY:$AY,$B$5-3)),INDEX(Calculo!$AY:$AY,$B$5-3),""),"") | E40: =IF($B$5-3>=5,IF(ISNUMBER(INDEX(Calculo!$W:$W,$B$5-3)),INDEX(Calculo!$W:$W,$B$5-3),""),"") | F40: =IF($B$5-3>=5,IF(ISNUMBER(INDEX(Calculo!$BC:$BC,$B$5-3)),INDEX(Calculo!$BC:$BC,$B$5-3)*10000,""),"") | G40: =IF($B$5-3>=5,IF(ISNUMBER(INDEX(Calculo!$BG:$BG,$B$5-3)),INDEX(Calculo!$BG:$BG,$B$5-3),""),"")
A41: =IF($B$5-2>=5,INDEX(Calculo!$A:$A,$B$5-2),"") | B41: =IF($B$5-2>=5,IF(ISNUMBER(INDEX(Calculo!$AW:$AW,$B$5-2)),INDEX(Calculo!$AW:$AW,$B$5-2),""),"") | C41: =IF($B$5-2>=5,IF(ISNUMBER(INDEX(Calculo!$AX:$AX,$B$5-2)),INDEX(Calculo!$AX:$AX,$B$5-2),""),"") | D41: =IF($B$5-2>=5,IF(ISNUMBER(INDEX(Calculo!$AY:$AY,$B$5-2)),INDEX(Calculo!$AY:$AY,$B$5-2),""),"") | E41: =IF($B$5-2>=5,IF(ISNUMBER(INDEX(Calculo!$W:$W,$B$5-2)),INDEX(Calculo!$W:$W,$B$5-2),""),"") | F41: =IF($B$5-2>=5,IF(ISNUMBER(INDEX(Calculo!$BC:$BC,$B$5-2)),INDEX(Calculo!$BC:$BC,$B$5-2)*10000,""),"") | G41: =IF($B$5-2>=5,IF(ISNUMBER(INDEX(Calculo!$BG:$BG,$B$5-2)),INDEX(Calculo!$BG:$BG,$B$5-2),""),"")
A42: =IF($B$5-1>=5,INDEX(Calculo!$A:$A,$B$5-1),"") | B42: =IF($B$5-1>=5,IF(ISNUMBER(INDEX(Calculo!$AW:$AW,$B$5-1)),INDEX(Calculo!$AW:$AW,$B$5-1),""),"") | C42: =IF($B$5-1>=5,IF(ISNUMBER(INDEX(Calculo!$AX:$AX,$B$5-1)),INDEX(Calculo!$AX:$AX,$B$5-1),""),"") | D42: =IF($B$5-1>=5,IF(ISNUMBER(INDEX(Calculo!$AY:$AY,$B$5-1)),INDEX(Calculo!$AY:$AY,$B$5-1),""),"") | E42: =IF($B$5-1>=5,IF(ISNUMBER(INDEX(Calculo!$W:$W,$B$5-1)),INDEX(Calculo!$W:$W,$B$5-1),""),"") | F42: =IF($B$5-1>=5,IF(ISNUMBER(INDEX(Calculo!$BC:$BC,$B$5-1)),INDEX(Calculo!$BC:$BC,$B$5-1)*10000,""),"") | G42: =IF($B$5-1>=5,IF(ISNUMBER(INDEX(Calculo!$BG:$BG,$B$5-1)),INDEX(Calculo!$BG:$BG,$B$5-1),""),"")
A43: =IF($B$5-0>=5,INDEX(Calculo!$A:$A,$B$5-0),"") | B43: =IF($B$5-0>=5,IF(ISNUMBER(INDEX(Calculo!$AW:$AW,$B$5-0)),INDEX(Calculo!$AW:$AW,$B$5-0),""),"") | C43: =IF($B$5-0>=5,IF(ISNUMBER(INDEX(Calculo!$AX:$AX,$B$5-0)),INDEX(Calculo!$AX:$AX,$B$5-0),""),"") | D43: =IF($B$5-0>=5,IF(ISNUMBER(INDEX(Calculo!$AY:$AY,$B$5-0)),INDEX(Calculo!$AY:$AY,$B$5-0),""),"") | E43: =IF($B$5-0>=5,IF(ISNUMBER(INDEX(Calculo!$W:$W,$B$5-0)),INDEX(Calculo!$W:$W,$B$5-0),""),"") | F43: =IF($B$5-0>=5,IF(ISNUMBER(INDEX(Calculo!$BC:$BC,$B$5-0)),INDEX(Calculo!$BC:$BC,$B$5-0)*10000,""),"") | G43: =IF($B$5-0>=5,IF(ISNUMBER(INDEX(Calculo!$BG:$BG,$B$5-0)),INDEX(Calculo!$BG:$BG,$B$5-0),""),"")

Sheet Parametros
A1: Parámetros congelados de la regla H_OVR3 (no modificar)
A2: Fijados el 2026-10-10. Cambiar cualquiera invalida el seguimiento en vivo.
A4: Nombre | B4: Valor | C4: Descripción
A5: MIN_BANCOS | B5: 2 | C5: Mínimo de bancos con retorno para calcular el promedio del sector
A6: MIN_OBS_ROLL | B6: 24 | C6: Observaciones mínimas dentro de las ventanas móviles de 36 meses (β y regresión vs EMBI)
A7: MIN_OBS_Z | B7: 36 | C7: Observaciones mínimas del z-score expansivo del gap
A8: Z_CLIP | B8: 3 | C8: Recorte del z-score (±)
A9: AMPLITUD | B9: 0.2 | C9: m = 1 + AMPLITUD·tanh(score): multiplicador entre 0.8 y 1.2
A10: W_BANCOS | B10: 0.25 | C10: Peso ilustrativo de bancos en el benchmark (escala el activo; no afecta el IR)
A11: COSTO | B11: 0.01 | C11: Costo por unidad de cambio en (m − 1): 2 × 50 pb (dos patas)
A12: FECHA_ERA | B12: 42521 | C12: Corte de eras del backtest (A ≤ fecha < B)
A13: INICIO_VIVO | B13: 46356 | C13: Primer mes de retorno en vivo (usa la señal del cierre de oct-2026)
A14: MESES_EVAL | B14: 24 | C14: Meses en vivo para la decisión: si el IR acumulado es < 0, se descarta la regla
A16: Fijos en las fórmulas (no son celdas editables)
A17: Ventana de β (bancos vs Merval) | B17: 36 meses, datos hasta t−1
A18: Ventana de la regresión del spread contra ΔlogEMBI | B18: 36 meses, datos hasta t−1
A19: Gap de sobrerreacción | B19: suma de 3 meses de residuos (requiere los 3)
A20: Mantener la señal | B20: promedio de los multiplicadores de los últimos 3 meses (tramos superpuestos)

Sheet Datos
A1: Datos de entrada (único lugar para cargar información)
A2: Cada mes agregar UNA fila al final con el cierre del mes. Celdas amarillas = carga. No modificar filas anteriores. Fuente y unidades: ver encabezados y LEEME.
A4: Fecha (fin de mes) | B4: GGAL | C4: BBAR | D4: BMA | E4: SUPV | F4: MERVAL ARS | G4: Badlar (% TNA) | H4: EMBI Argentina (pb)
A5: 38017 | B5: 2.074 | C5: 6.855 | D5: 2.839 | F5: 1140.81 | G5: 1.5 | H5: 5764.38
A6: 38046 | B6: 2.322 | C6: 6.793 | D6: 3.034 | F6: 1183.14 | G6: 1.125 | H6: 5865.65
A7: 38077 | B7: 2.245 | C7: 6.628 | D7: 3.117 | F7: 1201.66 | G7: 1.6875 | H7: 4872.94
A8: 38107 | B8: 1.973 | C8: 5.232 | D8: 2.978 | F8: 1077.93 | G8: 1.8125 | H8: 4628.15
A9: 38138 | B9: 1.674 | C9: 4.236 | D9: 2.459 | F9: 952.62 | G9: 3.875 | H9: 4950
A10: 38168 | B10: 1.614 | C10: 4 | D10: 2.496 | F10: 945.45 | G10: 2.4375 | H10: 5188.06
A11: 38199 | B11: 1.535 | C11: 4.236 | D11: 2.829 | F11: 966.1 | G11: 4 | H11: 5036.41
A12: 38230 | B12: 1.505 | C12: 4.039 | D12: 2.944 | F12: 952.14 | G12: 4.4375 | H12: 5258.49
A13: 38260 | B13: 1.953 | C13: 5.122 | D13: 3.136 | F13: 1142.5 | G13: 5.1875 | H13: 5440.02
A14: 38291 | B14: 2.471 | C14: 4.959 | D14: 3.328 | F14: 1287.14 | G14: 4.375 | H14: 5440.1
A15: 38321 | B15: 2.142 | C15: 5.053 | D15: 3.223 | F15: 1213.09 | G15: 4.125 | H15: 5193.84
A16: 38352 | B16: 2.511 | C16: 6.042 | D16: 3.539 | F16: 1375.37 | G16: 4 | H16: 4702.63
... A152: 42490 | B152: 41.366 | C152: 134.159 | D152: 103.756 | F152: 13724.07 | G152: 30.5625 | H152: 544
A153: 42521 | B153: 40.522 | C153: 118.573 | D153: 100.006 | E153: 32.208 | F153: 12681.74 | G153: 31.25 | H153: 522
A154: 42551 | B154: 46.928 | C154: 137.382 | D154: 127.394 | E154: 37.792 | F154: 14683.49 | G154: 26.625 | H154: 518
A155: 42582 | B155: 45.606 | C155: 133.732 | D155: 128.417 | E155: 40.783 | F155: 15803.5 | G155: 25.625 | H155: 521
A156: 42613 | B156: 45.606 | C156: 135.537 | D156: 135.94 | E156: 41.631 | F156: 15649.47 | G156: 24 | H156: 454
A157: 42643 | B157: 47.792 | C157: 135.069 | D157: 136.513 | E157: 45.869 | F157: 16675.68 | G157: 22.1875 | H157: 439
A158: 42674 | B158: 47.894 | C158: 134.868 | D158: 131.98 | E158: 47.365 | F158: 17610.13 | G158: 21.75 | H158: 451
A159: 42704 | B159: 45.148 | C159: 130.388 | D159: 130.833 | E159: 45.32 | F159: 17442.4 | G159: 20.375 | H159: 515
A160: 42735 | B160: 43.42 | C160: 124.37 | D160: 117.864 | E160: 40.883 | F160: 16917.86 | G160: 19.875 | H160: 455
A161: 42766 | B161: 50.283 | C161: 130.254 | D161: 137.604 | E161: 46.168 | F161: 19062.59 | G161: 19.375 | H161: 469
A162: 42794 | B162: 51.554 | C162: 123.702 | D162: 142.596 | E162: 47.863 | F162: 19117.45 | G162: 20.1875 | H162: 466
A163: 42825 | B163: 59.893 | C163: 127.179 | D163: 153.212 | E163: 52.949 | F163: 20265.32 | G163: 19.0625 | H163: 452
A164: 42855 | B164: 61.723 | C164: 127.045 | D164: 154.073 | E164: 52.899 | F164: 21019.91 | G164: 20 | H164: 415
... A277: 46295 | B277: 8619.655 | C277: 14537.483 | D277: 18122.092 | E277: 2610.009 | F277: 2819323 | G277: 22.8125 | H277: 607

Sheet Calculo
A1: Cálculo de la regla H_OVR3 (fórmulas; no editar)
A2: Cada columna replica una línea del código Python. Columnas 'f' = 1 si el dato existe; columnas 'v' = valor numérico (0 si falta) para las ventanas móviles.
A3: Fecha | B3: Retornos locales | I3: Tasa libre de riesgo | K3: Spread ajustado por β (T2) | R3: β bancos vs Merval | X3: Regresión vs EMBI | AM3: Gap y señal | AX3: Posición | BA3: Resultado | BG3: Seguimiento | BJ3: Gráfico
A4: Fecha | B4: r GGAL | C4: r BBAR | D4: r BMA | E4: r SUPV | F4: N bancos | G4: r bancos (EW) | H4: r Merval | I4: Badlar (ffill) | J4: rf (log, mes) | K4: ln(1+r bancos) − rf | L4: ln(1+r Merval) − rf | M4: f XB | N4: v XB | O4: f XM | P4: v XM | Q4: f par | R4: n pares (36m, t−1) | S4: cov (36m, t−1) | T4: n Merval (36m, t−1) | U4: var Merval (36m, t−1) | V4: β | W4: T2 = XB − β·XM | X4: Δ ln EMBI | Y4: f T2 | Z4: v T2 | AA4: f ΔEMBI | AB4: v ΔEMBI | AC4: f par | AD4: n pares (36m, t−1) | AE4: cov(T2, ΔEMBI) | AF4: n ΔEMBI | AG4: var ΔEMBI | AH4: n T2 | AI4: media T2 | AJ4: media ΔEMBI | AK4: β_E | AL4: a_E | AM4: residuo e = T2 − (a + β_E·ΔEMBI) | AN4: f e | AO4: v e | AP4: gap 3m | AQ4: f gap | AR4: v gap | AS4: n gap (expansivo) | AT4: media gap (expansiva) | AU4: desvío gap (expansivo) | AV4: z gap (±Z_CLIP) | AW4: score = −z | AX4: m del mes = 1 + 0.2·tanh(score) | AY4: m a aplicar (prom. 3 meses) | AZ4: tilt = m − 1 | BA4: activo bruto | BB4: costo | BC4: activo neto | BD4: era | BE4: neto era A | BF4: neto era B | BG4: en vivo (1/0) | BH4: neto en vivo | BI4: fila con señal | BJ4: acumulado total (pb) (NA en meses sin dato) | BK4: acumulado en vivo (pb) (NA en meses sin dato) | BL4: m a aplicar (gráfico) (NA en meses sin dato)
A5: =IF(Datos!A5="","",Datos!A5) | B5: ="" | C5: ="" | D5: ="" | E5: ="" | F5: =IF($A5="","",COUNT(B5:E5)) | G5: =IF($A5="","",IF(F5>=MIN_BANCOS,AVERAGE(B5:E5),"")) | H5: ="" | I5: =IF($A5="","",IF(ISNUMBER(Datos!G5),Datos!G5,"")) | J5: =IF($A5="","",0) | K5: =IF(ISNUMBER(G5),LN(1+G5)-J5,"") | L5: =IF(ISNUMBER(H5),LN(1+H5)-J5,"") | M5: =IF(ISNUMBER(K5),1,0) | N5: =IF(M5=1,K5,0) | O5: =IF(ISNUMBER(L5),1,0) | P5: =IF(O5=1,L5,0) | Q5: =M5*O5 | R5: =0 | S5: ="" | T5: =0 | U5: ="" | V5: =IF(OR(S5="",U5=""),"",S5/U5) | W5: =IF(AND(ISNUMBER(K5),ISNUMBER(L5),ISNUMBER(V5)),K5-V5*L5,"") | X5: ="" | Y5: =IF(ISNUMBER(W5),1,0) | Z5: =IF(Y5=1,W5,0) | AA5: =IF(ISNUMBER(X5),1,0) | AB5: =IF(AA5=1,X5,0) | AC5: =Y5*AA5 | AD5: =0 | AE5: ="" | AF5: =0 | AG5: ="" | AH5: =0 | AI5: ="" | AJ5: ="" | AK5: =IF(OR(AE5="",AG5=""),"",AE5/AG5) | AL5: =IF(OR(AI5="",AK5="",AJ5=""),"",AI5-AK5*AJ5) | AM5: =IF(AND(ISNUMBER(W5),ISNUMBER(X5),ISNUMBER(AK5),ISNUMBER(AL5)),W5-(AL5+AK5*X5),"") | AN5: =IF(ISNUMBER(AM5),1,0) | AO5: =IF(AN5=1,AM5,0) | AP5: ="" | AQ5: =IF(ISNUMBER(AP5),1,0) | AR5: =IF(AQ5=1,AP5,0) | AS5: =SUM(AQ$5:AQ5) | AT5: =IF(AS5>=MIN_OBS_Z,SUMPRODUCT(AQ$5:AQ5,AR$5:AR5)/AS5,"") | AU5: =IF(AS5>=MIN_OBS_Z,SQRT(SUMPRODUCT(AQ$5:AQ5,(AR$5:AR5-AT5)^2)/(AS5-1)),"") | AV5: =IF(AND(AQ5=1,ISNUMBER(AT5)),MAX(-Z_CLIP,MIN(Z_CLIP,(AR5-AT5)/AU5)),"") | AW5: =IF(ISNUMBER(AV5),-AV5,"") | AX5: =IF(ISNUMBER(AW5),1+AMPLITUD*TANH(AW5),"") | AY5: =IF($A5="","",IF(COUNT(AX5:AX5)>0,AVERAGE(AX5:AX5),"")) | AZ5: =IF(ISNUMBER(AY5),AY5-1,"") | BA5: ="" | BB5: =0 | BC5: =IF(ISNUMBER(BA5),BA5-BB5,"") | BD5: =IF(ISNUMBER(BC5),IF(A5<=FECHA_ERA,"A","B"),"") | BE5: =IF(BD5="A",BC5,"") | BF5: =IF(BD5="B",BC5,"") | BG5: =IF(AND(ISNUMBER(BC5),ISNUMBER(A5)),IF(A5>=INICIO_VIVO,1,0),0) | BH5: =IF(BG5=1,BC5,"") | BI5: =IF(ISNUMBER(AY5),ROW(),0) | BJ5: =IF(ISNUMBER(BC5),SUM(BC$5:BC5)*10000,NA()) | BK5: =IF(BG5=1,SUM(BH$5:BH5)*10000,NA()) | BL5: =IF(ISNUMBER(AY5),AY5,NA())
A6: =IF(Datos!A6="","",Datos!A6) | B6: =IF(OR($A6="",NOT(ISNUMBER(Datos!B6)),NOT(ISNUMBER(Datos!B5))),"",Datos!B6/Datos!B5-1) | C6: =IF(OR($A6="",NOT(ISNUMBER(Datos!C6)),NOT(ISNUMBER(Datos!C5))),"",Datos!C6/Datos!C5-1) | D6: =IF(OR($A6="",NOT(ISNUMBER(Datos!D6)),NOT(ISNUMBER(Datos!D5))),"",Datos!D6/Datos!D5-1) | E6: =IF(OR($A6="",NOT(ISNUMBER(Datos!E6)),NOT(ISNUMBER(Datos!E5))),"",Datos!E6/Datos!E5-1) | F6: =IF($A6="","",COUNT(B6:E6)) | G6: =IF($A6="","",IF(F6>=MIN_BANCOS,AVERAGE(B6:E6),"")) | H6: =IF(OR($A6="",NOT(ISNUMBER(Datos!F6)),NOT(ISNUMBER(Datos!F5))),"",Datos!F6/Datos!F5-1) | I6: =IF($A6="","",IF(ISNUMBER(Datos!G6),Datos!G6,I5)) | J6: =IF($A6="","",IF(ISNUMBER(I5),LN(1+I5/100/12),0)) | K6: =IF(ISNUMBER(G6),LN(1+G6)-J6,"") | L6: =IF(ISNUMBER(H6),LN(1+H6)-J6,"") | M6: =IF(ISNUMBER(K6),1,0) | N6: =IF(M6=1,K6,0) | O6: =IF(ISNUMBER(L6),1,0) | P6: =IF(O6=1,L6,0) | Q6: =M6*O6 | R6: =SUM(Q5:Q5) | S6: =IF(OR($A6="",R6<MIN_OBS_ROLL),"",(SUMPRODUCT(Q5:Q5,N5:N5,P5:P5)/R6-SUMPRODUCT(Q5:Q5,N5:N5)/R6*SUMPRODUCT(Q5:Q5,P5:P5)/R6)*R6/(R6-1)) | T6: =SUM(O5:O5) | U6: =IF(OR($A6="",T6<MIN_OBS_ROLL),"",SUMPRODUCT(O5:O5,(P5:P5-SUMPRODUCT(O5:O5,P5:P5)/T6)^2)/(T6-1)) | V6: =IF(OR(S6="",U6=""),"",S6/U6) | W6: =IF(AND(ISNUMBER(K6),ISNUMBER(L6),ISNUMBER(V6)),K6-V6*L6,"") | X6: =IF(OR($A6="",NOT(ISNUMBER(Datos!H6)),NOT(ISNUMBER(Datos!H5))),"",LN(Datos!H6)-LN(Datos!H5)) | Y6: =IF(ISNUMBER(W6),1,0) | Z6: =IF(Y6=1,W6,0) | AA6: =IF(ISNUMBER(X6),1,0) | AB6: =IF(AA6=1,X6,0) | AC6: =Y6*AA6 | AD6: =SUM(AC5:AC5) | AE6: =IF(OR($A6="",AD6<MIN_OBS_ROLL),"",(SUMPRODUCT(AC5:AC5,Z5:Z5,AB5:AB5)/AD6-SUMPRODUCT(AC5:AC5,Z5:Z5)/AD6*SUMPRODUCT(AC5:AC5,AB5:AB5)/AD6)*AD6/(AD6-1)) | AF6: =SUM(AA5:AA5) | AG6: =IF(OR($A6="",AF6<MIN_OBS_ROLL),"",SUMPRODUCT(AA5:AA5,(AB5:AB5-SUMPRODUCT(AA5:AA5,AB5:AB5)/AF6)^2)/(AF6-1)) | AH6: =SUM(Y5:Y5) | AI6: =IF(OR($A6="",AH6<MIN_OBS_ROLL),"",SUMPRODUCT(Y5:Y5,Z5:Z5)/AH6) | AJ6: =IF(OR($A6="",AF6<MIN_OBS_ROLL),"",SUMPRODUCT(AA5:AA5,AB5:AB5)/AF6) | AK6: =IF(OR(AE6="",AG6=""),"",AE6/AG6) | AL6: =IF(OR(AI6="",AK6="",AJ6=""),"",AI6-AK6*AJ6) | AM6: =IF(AND(ISNUMBER(W6),ISNUMBER(X6),ISNUMBER(AK6),ISNUMBER(AL6)),W6-(AL6+AK6*X6),"") | AN6: =IF(ISNUMBER(AM6),1,0) | AO6: =IF(AN6=1,AM6,0) | AP6: ="" | AQ6: =IF(ISNUMBER(AP6),1,0) | AR6: =IF(AQ6=1,AP6,0) | AS6: =SUM(AQ$5:AQ6) | AT6: =IF(AS6>=MIN_OBS_Z,SUMPRODUCT(AQ$5:AQ6,AR$5:AR6)/AS6,"") | AU6: =IF(AS6>=MIN_OBS_Z,SQRT(SUMPRODUCT(AQ$5:AQ6,(AR$5:AR6-AT6)^2)/(AS6-1)),"") | AV6: =IF(AND(AQ6=1,ISNUMBER(AT6)),MAX(-Z_CLIP,MIN(Z_CLIP,(AR6-AT6)/AU6)),"") | AW6: =IF(ISNUMBER(AV6),-AV6,"") | AX6: =IF(ISNUMBER(AW6),1+AMPLITUD*TANH(AW6),"") | AY6: =IF($A6="","",IF(COUNT(AX5:AX6)>0,AVERAGE(AX5:AX6),"")) | AZ6: =IF(ISNUMBER(AY6),AY6-1,"") | BA6: =IF(AND(ISNUMBER(AZ5),ISNUMBER(W6)),AZ5*W_BANCOS*W6,"") | BB6: =0 | BC6: =IF(ISNUMBER(BA6),BA6-BB6,"") | BD6: =IF(ISNUMBER(BC6),IF(A6<=FECHA_ERA,"A","B"),"") | BE6: =IF(BD6="A",BC6,"") | BF6: =IF(BD6="B",BC6,"") | BG6: =IF(AND(ISNUMBER(BC6),ISNUMBER(A6)),IF(A6>=INICIO_VIVO,1,0),0) | BH6: =IF(BG6=1,BC6,"") | BI6: =IF(ISNUMBER(AY6),ROW(),0) | BJ6: =IF(ISNUMBER(BC6),SUM(BC$5:BC6)*10000,NA()) | BK6: =IF(BG6=1,SUM(BH$5:BH6)*10000,NA()) | BL6: =IF(ISNUMBER(AY6),AY6,NA())
A7: =IF(Datos!A7="","",Datos!A7) | B7: =IF(OR($A7="",NOT(ISNUMBER(Datos!B7)),NOT(ISNUMBER(Datos!B6))),"",Datos!B7/Datos!B6-1) | C7: =IF(OR($A7="",NOT(ISNUMBER(Datos!C7)),NOT(ISNUMBER(Datos!C6))),"",Datos!C7/Datos!C6-1) | D7: =IF(OR($A7="",NOT(ISNUMBER(Datos!D7)),NOT(ISNUMBER(Datos!D6))),"",Datos!D7/Datos!D6-1) | E7: =IF(OR($A7="",NOT(ISNUMBER(Datos!E7)),NOT(ISNUMBER(Datos!E6))),"",Datos!E7/Datos!E6-1) | F7: =IF($A7="","",COUNT(B7:E7)) | G7: =IF($A7="","",IF(F7>=MIN_BANCOS,AVERAGE(B7:E7),"")) | H7: =IF(OR($A7="",NOT(ISNUMBER(Datos!F7)),NOT(ISNUMBER(Datos!F6))),"",Datos!F7/Datos!F6-1) | I7: =IF($A7="","",IF(ISNUMBER(Datos!G7),Datos!G7,I6)) | J7: =IF($A7="","",IF(ISNUMBER(I6),LN(1+I6/100/12),0)) | K7: =IF(ISNUMBER(G7),LN(1+G7)-J7,"") | L7: =IF(ISNUMBER(H7),LN(1+H7)-J7,"") | M7: =IF(ISNUMBER(K7),1,0) | N7: =IF(M7=1,K7,0) | O7: =IF(ISNUMBER(L7),1,0) | P7: =IF(O7=1,L7,0) | Q7: =M7*O7 | R7: =SUM(Q5:Q6) | S7: =IF(OR($A7="",R7<MIN_OBS_ROLL),"",(SUMPRODUCT(Q5:Q6,N5:N6,P5:P6)/R7-SUMPRODUCT(Q5:Q6,N5:N6)/R7*SUMPRODUCT(Q5:Q6,P5:P6)/R7)*R7/(R7-1)) | T7: =SUM(O5:O6) | U7: =IF(OR($A7="",T7<MIN_OBS_ROLL),"",SUMPRODUCT(O5:O6,(P5:P6-SUMPRODUCT(O5:O6,P5:P6)/T7)^2)/(T7-1)) | V7: =IF(OR(S7="",U7=""),"",S7/U7) | W7: =IF(AND(ISNUMBER(K7),ISNUMBER(L7),ISNUMBER(V7)),K7-V7*L7,"") | X7: =IF(OR($A7="",NOT(ISNUMBER(Datos!H7)),NOT(ISNUMBER(Datos!H6))),"",LN(Datos!H7)-LN(Datos!H6)) | Y7: =IF(ISNUMBER(W7),1,0) | Z7: =IF(Y7=1,W7,0) | AA7: =IF(ISNUMBER(X7),1,0) | AB7: =IF(AA7=1,X7,0) | AC7: =Y7*AA7 | AD7: =SUM(AC5:AC6) | AE7: =IF(OR($A7="",AD7<MIN_OBS_ROLL),"",(SUMPRODUCT(AC5:AC6,Z5:Z6,AB5:AB6)/AD7-SUMPRODUCT(AC5:AC6,Z5:Z6)/AD7*SUMPRODUCT(AC5:AC6,AB5:AB6)/AD7)*AD7/(AD7-1)) | AF7: =SUM(AA5:AA6) | AG7: =IF(OR($A7="",AF7<MIN_OBS_ROLL),"",SUMPRODUCT(AA5:AA6,(AB5:AB6-SUMPRODUCT(AA5:AA6,AB5:AB6)/AF7)^2)/(AF7-1)) | AH7: =SUM(Y5:Y6) | AI7: =IF(OR($A7="",AH7<MIN_OBS_ROLL),"",SUMPRODUCT(Y5:Y6,Z5:Z6)/AH7) | AJ7: =IF(OR($A7="",AF7<MIN_OBS_ROLL),"",SUMPRODUCT(AA5:AA6,AB5:AB6)/AF7) | AK7: =IF(OR(AE7="",AG7=""),"",AE7/AG7) | AL7: =IF(OR(AI7="",AK7="",AJ7=""),"",AI7-AK7*AJ7) | AM7: =IF(AND(ISNUMBER(W7),ISNUMBER(X7),ISNUMBER(AK7),ISNUMBER(AL7)),W7-(AL7+AK7*X7),"") | AN7: =IF(ISNUMBER(AM7),1,0) | AO7: =IF(AN7=1,AM7,0) | AP7: =IF(SUM(AN5:AN7)=3,SUM(AO5:AO7),"") | AQ7: =IF(ISNUMBER(AP7),1,0) | AR7: =IF(AQ7=1,AP7,0) | AS7: =SUM(AQ$5:AQ7) | AT7: =IF(AS7>=MIN_OBS_Z,SUMPRODUCT(AQ$5:AQ7,AR$5:AR7)/AS7,"") | AU7: =IF(AS7>=MIN_OBS_Z,SQRT(SUMPRODUCT(AQ$5:AQ7,(AR$5:AR7-AT7)^2)/(AS7-1)),"") | AV7: =IF(AND(AQ7=1,ISNUMBER(AT7)),MAX(-Z_CLIP,MIN(Z_CLIP,(AR7-AT7)/AU7)),"") | AW7: =IF(ISNUMBER(AV7),-AV7,"") | AX7: =IF(ISNUMBER(AW7),1+AMPLITUD*TANH(AW7),"") | AY7: =IF($A7="","",IF(COUNT(AX5:AX7)>0,AVERAGE(AX5:AX7),"")) | AZ7: =IF(ISNUMBER(AY7),AY7-1,"") | BA7: =IF(AND(ISNUMBER(AZ6),ISNUMBER(W7)),AZ6*W_BANCOS*W7,"") | BB7: =IF(AND(ISNUMBER(AZ6),ISNUMBER(AZ5)),ABS(AZ6-AZ5)*W_BANCOS*COSTO,0) | BC7: =IF(ISNUMBER(BA7),BA7-BB7,"") | BD7: =IF(ISNUMBER(BC7),IF(A7<=FECHA_ERA,"A","B"),"") | BE7: =IF(BD7="A",BC7,"") | BF7: =IF(BD7="B",BC7,"") | BG7: =IF(AND(ISNUMBER(BC7),ISNUMBER(A7)),IF(A7>=INICIO_VIVO,1,0),0) | BH7: =IF(BG7=1,BC7,"") | BI7: =IF(ISNUMBER(AY7),ROW(),0) | BJ7: =IF(ISNUMBER(BC7),SUM(BC$5:BC7)*10000,NA()) | BK7: =IF(BG7=1,SUM(BH$5:BH7)*10000,NA()) | BL7: =IF(ISNUMBER(AY7),AY7,NA())
A8: =IF(Datos!A8="","",Datos!A8) | B8: =IF(OR($A8="",NOT(ISNUMBER(Datos!B8)),NOT(ISNUMBER(Datos!B7))),"",Datos!B8/Datos!B7-1) | C8: =IF(OR($A8="",NOT(ISNUMBER(Datos!C8)),NOT(ISNUMBER(Datos!C7))),"",Datos!C8/Datos!C7-1) | D8: =IF(OR($A8="",NOT(ISNUMBER(Datos!D8)),NOT(ISNUMBER(Datos!D7))),"",Datos!D8/Datos!D7-1) | E8: =IF(OR($A8="",NOT(ISNUMBER(Datos!E8)),NOT(ISNUMBER(Datos!E7))),"",Datos!E8/Datos!E7-1) | F8: =IF($A8="","",COUNT(B8:E8)) | G8: =IF($A8="","",IF(F8>=MIN_BANCOS,AVERAGE(B8:E8),"")) | H8: =IF(OR($A8="",NOT(ISNUMBER(Datos!F8)),NOT(ISNUMBER(Datos!F7))),"",Datos!F8/Datos!F7-1) | I8: =IF($A8="","",IF(ISNUMBER(Datos!G8),Datos!G8,I7)) | J8: =IF($A8="","",IF(ISNUMBER(I7),LN(1+I7/100/12),0)) | K8: =IF(ISNUMBER(G8),LN(1+G8)-J8,"") | L8: =IF(ISNUMBER(H8),LN(1+H8)-J8,"") | M8: =IF(ISNUMBER(K8),1,0) | N8: =IF(M8=1,K8,0) | O8: =IF(ISNUMBER(L8),1,0) | P8: =IF(O8=1,L8,0) | Q8: =M8*O8 | R8: =SUM(Q5:Q7) | S8: =IF(OR($A8="",R8<MIN_OBS_ROLL),"",(SUMPRODUCT(Q5:Q7,N5:N7,P5:P7)/R8-SUMPRODUCT(Q5:Q7,N5:N7)/R8*SUMPRODUCT(Q5:Q7,P5:P7)/R8)*R8/(R8-1)) | T8: =SUM(O5:O7) | U8: =IF(OR($A8="",T8<MIN_OBS_ROLL),"",SUMPRODUCT(O5:O7,(P5:P7-SUMPRODUCT(O5:O7,P5:P7)/T8)^2)/(T8-1)) | V8: =IF(OR(S8="",U8=""),"",S8/U8) | W8: =IF(AND(ISNUMBER(K8),ISNUMBER(L8),ISNUMBER(V8)),K8-V8*L8,"") | X8: =IF(OR($A8="",NOT(ISNUMBER(Datos!H8)),NOT(ISNUMBER(Datos!H7))),"",LN(Datos!H8)-LN(Datos!H7)) | Y8: =IF(ISNUMBER(W8),1,0) | Z8: =IF(Y8=1,W8,0) | AA8: =IF(ISNUMBER(X8),1,0) | AB8: =IF(AA8=1,X8,0) | AC8: =Y8*AA8 | AD8: =SUM(AC5:AC7) | AE8: =IF(OR($A8="",AD8<MIN_OBS_ROLL),"",(SUMPRODUCT(AC5:AC7,Z5:Z7,AB5:AB7)/AD8-SUMPRODUCT(AC5:AC7,Z5:Z7)/AD8*SUMPRODUCT(AC5:AC7,AB5:AB7)/AD8)*AD8/(AD8-1)) | AF8: =SUM(AA5:AA7) | AG8: =IF(OR($A8="",AF8<MIN_OBS_ROLL),"",SUMPRODUCT(AA5:AA7,(AB5:AB7-SUMPRODUCT(AA5:AA7,AB5:AB7)/AF8)^2)/(AF8-1)) | AH8: =SUM(Y5:Y7) | AI8: =IF(OR($A8="",AH8<MIN_OBS_ROLL),"",SUMPRODUCT(Y5:Y7,Z5:Z7)/AH8) | AJ8: =IF(OR($A8="",AF8<MIN_OBS_ROLL),"",SUMPRODUCT(AA5:AA7,AB5:AB7)/AF8) | AK8: =IF(OR(AE8="",AG8=""),"",AE8/AG8) | AL8: =IF(OR(AI8="",AK8="",AJ8=""),"",AI8-AK8*AJ8) | AM8: =IF(AND(ISNUMBER(W8),ISNUMBER(X8),ISNUMBER(AK8),ISNUMBER(AL8)),W8-(AL8+AK8*X8),"") | AN8: =IF(ISNUMBER(AM8),1,0) | AO8: =IF(AN8=1,AM8,0) | AP8: =IF(SUM(AN6:AN8)=3,SUM(AO6:AO8),"") | AQ8: =IF(ISNUMBER(AP8),1,0) | AR8: =IF(AQ8=1,AP8,0) | AS8: =SUM(AQ$5:AQ8) | AT8: =IF(AS8>=MIN_OBS_Z,SUMPRODUCT(AQ$5:AQ8,AR$5:AR8)/AS8,"") | AU8: =IF(AS8>=MIN_OBS_Z,SQRT(SUMPRODUCT(AQ$5:AQ8,(AR$5:AR8-AT8)^2)/(AS8-1)),"") | AV8: =IF(AND(AQ8=1,ISNUMBER(AT8)),MAX(-Z_CLIP,MIN(Z_CLIP,(AR8-AT8)/AU8)),"") | AW8: =IF(ISNUMBER(AV8),-AV8,"") | AX8: =IF(ISNUMBER(AW8),1+AMPLITUD*TANH(AW8),"") | AY8: =IF($A8="","",IF(COUNT(AX6:AX8)>0,AVERAGE(AX6:AX8),"")) | AZ8: =IF(ISNUMBER(AY8),AY8-1,"") | BA8: =IF(AND(ISNUMBER(AZ7),ISNUMBER(W8)),AZ7*W_BANCOS*W8,"") | BB8: =IF(AND(ISNUMBER(AZ7),ISNUMBER(AZ6)),ABS(AZ7-AZ6)*W_BANCOS*COSTO,0) | BC8: =IF(ISNUMBER(BA8),BA8-BB8,"") | BD8: =IF(ISNUMBER(BC8),IF(A8<=FECHA_ERA,"A","B"),"") | BE8: =IF(BD8="A",BC8,"") | BF8: =IF(BD8="B",BC8,"") | BG8: =IF(AND(ISNUMBER(BC8),ISNUMBER(A8)),IF(A8>=INICIO_VIVO,1,0),0) | BH8: =IF(BG8=1,BC8,"") | BI8: =IF(ISNUMBER(AY8),ROW(),0) | BJ8: =IF(ISNUMBER(BC8),SUM(BC$5:BC8)*10000,NA()) | BK8: =IF(BG8=1,SUM(BH$5:BH8)*10000,NA()) | BL8: =IF(ISNUMBER(AY8),AY8,NA())
A9: =IF(Datos!A9="","",Datos!A9) | B9: =IF(OR($A9="",NOT(ISNUMBER(Datos!B9)),NOT(ISNUMBER(Datos!B8))),"",Datos!B9/Datos!B8-1) | C9: =IF(OR($A9="",NOT(ISNUMBER(Datos!C9)),NOT(ISNUMBER(Datos!C8))),"",Datos!C9/Datos!C8-1) | D9: =IF(OR($A9="",NOT(ISNUMBER(Datos!D9)),NOT(ISNUMBER(Datos!D8))),"",Datos!D9/Datos!D8-1) | E9: =IF(OR($A9="",NOT(ISNUMBER(Datos!E9)),NOT(ISNUMBER(Datos!E8))),"",Datos!E9/Datos!E8-1) | F9: =IF($A9="","",COUNT(B9:E9)) | G9: =IF($A9="","",IF(F9>=MIN_BANCOS,AVERAGE(B9:E9),"")) | H9: =IF(OR($A9="",NOT(ISNUMBER(Datos!F9)),NOT(ISNUMBER(Datos!F8))),"",Datos!F9/Datos!F8-1) | I9: =IF($A9="","",IF(ISNUMBER(Datos!G9),Datos!G9,I8)) | J9: =IF($A9="","",IF(ISNUMBER(I8),LN(1+I8/100/12),0)) | K9: =IF(ISNUMBER(G9),LN(1+G9)-J9,"") | L9: =IF(ISNUMBER(H9),LN(1+H9)-J9,"") | M9: =IF(ISNUMBER(K9),1,0) | N9: =IF(M9=1,K9,0) | O9: =IF(ISNUMBER(L9),1,0) | P9: =IF(O9=1,L9,0) | Q9: =M9*O9 | R9: =SUM(Q5:Q8) | S9: =IF(OR($A9="",R9<MIN_OBS_ROLL),"",(SUMPRODUCT(Q5:Q8,N5:N8,P5:P8)/R9-SUMPRODUCT(Q5:Q8,N5:N8)/R9*SUMPRODUCT(Q5:Q8,P5:P8)/R9)*R9/(R9-1)) | T9: =SUM(O5:O8) | U9: =IF(OR($A9="",T9<MIN_OBS_ROLL),"",SUMPRODUCT(O5:O8,(P5:P8-SUMPRODUCT(O5:O8,P5:P8)/T9)^2)/(T9-1)) | V9: =IF(OR(S9="",U9=""),"",S9/U9) | W9: =IF(AND(ISNUMBER(K9),ISNUMBER(L9),ISNUMBER(V9)),K9-V9*L9,"") | X9: =IF(OR($A9="",NOT(ISNUMBER(Datos!H9)),NOT(ISNUMBER(Datos!H8))),"",LN(Datos!H9)-LN(Datos!H8)) | Y9: =IF(ISNUMBER(W9),1,0) | Z9: =IF(Y9=1,W9,0) | AA9: =IF(ISNUMBER(X9),1,0) | AB9: =IF(AA9=1,X9,0) | AC9: =Y9*AA9 | AD9: =SUM(AC5:AC8) | AE9: =IF(OR($A9="",AD9<MIN_OBS_ROLL),"",(SUMPRODUCT(AC5:AC8,Z5:Z8,AB5:AB8)/AD9-SUMPRODUCT(AC5:AC8,Z5:Z8)/AD9*SUMPRODUCT(AC5:AC8,AB5:AB8)/AD9)*AD9/(AD9-1)) | AF9: =SUM(AA5:AA8) | AG9: =IF(OR($A9="",AF9<MIN_OBS_ROLL),"",SUMPRODUCT(AA5:AA8,(AB5:AB8-SUMPRODUCT(AA5:AA8,AB5:AB8)/AF9)^2)/(AF9-1)) | AH9: =SUM(Y5:Y8) | AI9: =IF(OR($A9="",AH9<MIN_OBS_ROLL),"",SUMPRODUCT(Y5:Y8,Z5:Z8)/AH9) | AJ9: =IF(OR($A9="",AF9<MIN_OBS_ROLL),"",SUMPRODUCT(AA5:AA8,AB5:AB8)/AF9) | AK9: =IF(OR(AE9="",AG9=""),"",AE9/AG9) | AL9: =IF(OR(AI9="",AK9="",AJ9=""),"",AI9-AK9*AJ9) | AM9: =IF(AND(ISNUMBER(W9),ISNUMBER(X9),ISNUMBER(AK9),ISNUMBER(AL9)),W9-(AL9+AK9*X9),"") | AN9: =IF(ISNUMBER(AM9),1,0) | AO9: =IF(AN9=1,AM9,0) | AP9: =IF(SUM(AN7:AN9)=3,SUM(AO7:AO9),"") | AQ9: =IF(ISNUMBER(AP9),1,0) | AR9: =IF(AQ9=1,AP9,0) | AS9: =SUM(AQ$5:AQ9) | AT9: =IF(AS9>=MIN_OBS_Z,SUMPRODUCT(AQ$5:AQ9,AR$5:AR9)/AS9,"") | AU9: =IF(AS9>=MIN_OBS_Z,SQRT(SUMPRODUCT(AQ$5:AQ9,(AR$5:AR9-AT9)^2)/(AS9-1)),"") | AV9: =IF(AND(AQ9=1,ISNUMBER(AT9)),MAX(-Z_CLIP,MIN(Z_CLIP,(AR9-AT9)/AU9)),"") | AW9: =IF(ISNUMBER(AV9),-AV9,"") | AX9: =IF(ISNUMBER(AW9),1+AMPLITUD*TANH(AW9),"") | AY9: =IF($A9="","",IF(COUNT(AX7:AX9)>0,AVERAGE(AX7:AX9),"")) | AZ9: =IF(ISNUMBER(AY9),AY9-1,"") | BA9: =IF(AND(ISNUMBER(AZ8),ISNUMBER(W9)),AZ8*W_BANCOS*W9,"") | BB9: =IF(AND(ISNUMBER(AZ8),ISNUMBER(AZ7)),ABS(AZ8-AZ7)*W_BANCOS*COSTO,0) | BC9: =IF(ISNUMBER(BA9),BA9-BB9,"") | BD9: =IF(ISNUMBER(BC9),IF(A9<=FECHA_ERA,"A","B"),"") | BE9: =IF(BD9="A",BC9,"") | BF9: =IF(BD9="B",BC9,"") | BG9: =IF(AND(ISNUMBER(BC9),ISNUMBER(A9)),IF(A9>=INICIO_VIVO,1,0),0) | BH9: =IF(BG9=1,BC9,"") | BI9: =IF(ISNUMBER(AY9),ROW(),0) | BJ9: =IF(ISNUMBER(BC9),SUM(BC$5:BC9)*10000,NA()) | BK9: =IF(BG9=1,SUM(BH$5:BH9)*10000,NA()) | BL9: =IF(ISNUMBER(AY9),AY9,NA())
A10: =IF(Datos!A10="","",Datos!A10) | B10: =IF(OR($A10="",NOT(ISNUMBER(Datos!B10)),NOT(ISNUMBER(Datos!B9))),"",Datos!B10/Datos!B9-1) | C10: =IF(OR($A10="",NOT(ISNUMBER(Datos!C10)),NOT(ISNUMBER(Datos!C9))),"",Datos!C10/Datos!C9-1) | D10: =IF(OR($A10="",NOT(ISNUMBER(Datos!D10)),NOT(ISNUMBER(Datos!D9))),"",Datos!D10/Datos!D9-1) | E10: =IF(OR($A10="",NOT(ISNUMBER(Datos!E10)),NOT(ISNUMBER(Datos!E9))),"",Datos!E10/Datos!E9-1) | F10: =IF($A10="","",COUNT(B10:E10)) | G10: =IF($A10="","",IF(F10>=MIN_BANCOS,AVERAGE(B10:E10),"")) | H10: =IF(OR($A10="",NOT(ISNUMBER(Datos!F10)),NOT(ISNUMBER(Datos!F9))),"",Datos!F10/Datos!F9-1) | I10: =IF($A10="","",IF(ISNUMBER(Datos!G10),Datos!G10,I9)) | J10: =IF($A10="","",IF(ISNUMBER(I9),LN(1+I9/100/12),0)) | K10: =IF(ISNUMBER(G10),LN(1+G10)-J10,"") | L10: =IF(ISNUMBER(H10),LN(1+H10)-J10,"") | M10: =IF(ISNUMBER(K10),1,0) | N10: =IF(M10=1,K10,0) | O10: =IF(ISNUMBER(L10),1,0) | P10: =IF(O10=1,L10,0) | Q10: =M10*O10 | R10: =SUM(Q5:Q9) | S10: =IF(OR($A10="",R10<MIN_OBS_ROLL),"",(SUMPRODUCT(Q5:Q9,N5:N9,P5:P9)/R10-SUMPRODUCT(Q5:Q9,N5:N9)/R10*SUMPRODUCT(Q5:Q9,P5:P9)/R10)*R10/(R10-1)) | T10: =SUM(O5:O9) | U10: =IF(OR($A10="",T10<MIN_OBS_ROLL),"",SUMPRODUCT(O5:O9,(P5:P9-SUMPRODUCT(O5:O9,P5:P9)/T10)^2)/(T10-1)) | V10: =IF(OR(S10="",U10=""),"",S10/U10) | W10: =IF(AND(ISNUMBER(K10),ISNUMBER(L10),ISNUMBER(V10)),K10-V10*L10,"") | X10: =IF(OR($A10="",NOT(ISNUMBER(Datos!H10)),NOT(ISNUMBER(Datos!H9))),"",LN(Datos!H10)-LN(Datos!H9)) | Y10: =IF(ISNUMBER(W10),1,0) | Z10: =IF(Y10=1,W10,0) | AA10: =IF(ISNUMBER(X10),1,0) | AB10: =IF(AA10=1,X10,0) | AC10: =Y10*AA10 | AD10: =SUM(AC5:AC9) | AE10: =IF(OR($A10="",AD10<MIN_OBS_ROLL),"",(SUMPRODUCT(AC5:AC9,Z5:Z9,AB5:AB9)/AD10-SUMPRODUCT(AC5:AC9,Z5:Z9)/AD10*SUMPRODUCT(AC5:AC9,AB5:AB9)/AD10)*AD10/(AD10-1)) | AF10: =SUM(AA5:AA9) | AG10: =IF(OR($A10="",AF10<MIN_OBS_ROLL),"",SUMPRODUCT(AA5:AA9,(AB5:AB9-SUMPRODUCT(AA5:AA9,AB5:AB9)/AF10)^2)/(AF10-1)) | AH10: =SUM(Y5:Y9) | AI10: =IF(OR($A10="",AH10<MIN_OBS_ROLL),"",SUMPRODUCT(Y5:Y9,Z5:Z9)/AH10) | AJ10: =IF(OR($A10="",AF10<MIN_OBS_ROLL),"",SUMPRODUCT(AA5:AA9,AB5:AB9)/AF10) | AK10: =IF(OR(AE10="",AG10=""),"",AE10/AG10) | AL10: =IF(OR(AI10="",AK10="",AJ10=""),"",AI10-AK10*AJ10) | AM10: =IF(AND(ISNUMBER(W10),ISNUMBER(X10),ISNUMBER(AK10),ISNUMBER(AL10)),W10-(AL10+AK10*X10),"") | AN10: =IF(ISNUMBER(AM10),1,0) | AO10: =IF(AN10=1,AM10,0) | AP10: =IF(SUM(AN8:AN10)=3,SUM(AO8:AO10),"") | AQ10: =IF(ISNUMBER(AP10),1,0) | AR10: =IF(AQ10=1,AP10,0) | AS10: =SUM(AQ$5:AQ10) | AT10: =IF(AS10>=MIN_OBS_Z,SUMPRODUCT(AQ$5:AQ10,AR$5:AR10)/AS10,"") | AU10: =IF(AS10>=MIN_OBS_Z,SQRT(SUMPRODUCT(AQ$5:AQ10,(AR$5:AR10-AT10)^2)/(AS10-1)),"") | AV10: =IF(AND(AQ10=1,ISNUMBER(AT10)),MAX(-Z_CLIP,MIN(Z_CLIP,(AR10-AT10)/AU10)),"") | AW10: =IF(ISNUMBER(AV10),-AV10,"") | AX10: =IF(ISNUMBER(AW10),1+AMPLITUD*TANH(AW10),"") | AY10: =IF($A10="","",IF(COUNT(AX8:AX10)>0,AVERAGE(AX8:AX10),"")) | AZ10: =IF(ISNUMBER(AY10),AY10-1,"") | BA10: =IF(AND(ISNUMBER(AZ9),ISNUMBER(W10)),AZ9*W_BANCOS*W10,"") | BB10: =IF(AND(ISNUMBER(AZ9),ISNUMBER(AZ8)),ABS(AZ9-AZ8)*W_BANCOS*COSTO,0) | BC10: =IF(ISNUMBER(BA10),BA10-BB10,"") | BD10: =IF(ISNUMBER(BC10),IF(A10<=FECHA_ERA,"A","B"),"") | BE10: =IF(BD10="A",BC10,"") | BF10: =IF(BD10="B",BC10,"") | BG10: =IF(AND(ISNUMBER(BC10),ISNUMBER(A10)),IF(A10>=INICIO_VIVO,1,0),0) | BH10: =IF(BG10=1,BC10,"") | BI10: =IF(ISNUMBER(AY10),ROW(),0) | BJ10: =IF(ISNUMBER(BC10),SUM(BC$5:BC10)*10000,NA()) | BK10: =IF(BG10=1,SUM(BH$5:BH10)*10000,NA()) | BL10: =IF(ISNUMBER(AY10),AY10,NA())
A11: =IF(Datos!A11="","",Datos!A11) | B11: =IF(OR($A11="",NOT(ISNUMBER(Datos!B11)),NOT(ISNUMBER(Datos!B10))),"",Datos!B11/Datos!B10-1) | C11: =IF(OR($A11="",NOT(ISNUMBER(Datos!C11)),NOT(ISNUMBER(Datos!C10))),"",Datos!C11/Datos!C10-1) | D11: =IF(OR($A11="",NOT(ISNUMBER(Datos!D11)),NOT(ISNUMBER(Datos!D10))),"",Datos!D11/Datos!D10-1) | E11: =IF(OR($A11="",NOT(ISNUMBER(Datos!E11)),NOT(ISNUMBER(Datos!E10))),"",Datos!E11/Datos!E10-1) | F11: =IF($A11="","",COUNT(B11:E11)) | G11: =IF($A11="","",IF(F11>=MIN_BANCOS,AVERAGE(B11:E11),"")) | H11: =IF(OR($A11="",NOT(ISNUMBER(Datos!F11)),NOT(ISNUMBER(Datos!F10))),"",Datos!F11/Datos!F10-1) | I11: =IF($A11="","",IF(ISNUMBER(Datos!G11),Datos!G11,I10)) | J11: =IF($A11="","",IF(ISNUMBER(I10),LN(1+I10/100/12),0)) | K11: =IF(ISNUMBER(G11),LN(1+G11)-J11,"") | L11: =IF(ISNUMBER(H11),LN(1+H11)-J11,"") | M11: =IF(ISNUMBER(K11),1,0) | N11: =IF(M11=1,K11,0) | O11: =IF(ISNUMBER(L11),1,0) | P11: =IF(O11=1,L11,0) | Q11: =M11*O11 | R11: =SUM(Q5:Q10) | S11: =IF(OR($A11="",R11<MIN_OBS_ROLL),"",(SUMPRODUCT(Q5:Q10,N5:N10,P5:P10)/R11-SUMPRODUCT(Q5:Q10,N5:N10)/R11*SUMPRODUCT(Q5:Q10,P5:P10)/R11)*R11/(R11-1)) | T11: =SUM(O5:O10) | U11: =IF(OR($A11="",T11<MIN_OBS_ROLL),"",SUMPRODUCT(O5:O10,(P5:P10-SUMPRODUCT(O5:O10,P5:P10)/T11)^2)/(T11-1)) | V11: =IF(OR(S11="",U11=""),"",S11/U11) | W11: =IF(AND(ISNUMBER(K11),ISNUMBER(L11),ISNUMBER(V11)),K11-V11*L11,"") | X11: =IF(OR($A11="",NOT(ISNUMBER(Datos!H11)),NOT(ISNUMBER(Datos!H10))),"",LN(Datos!H11)-LN(Datos!H10)) | Y11: =IF(ISNUMBER(W11),1,0) | Z11: =IF(Y11=1,W11,0) | AA11: =IF(ISNUMBER(X11),1,0) | AB11: =IF(AA11=1,X11,0) | AC11: =Y11*AA11 | AD11: =SUM(AC5:AC10) | AE11: =IF(OR($A11="",AD11<MIN_OBS_ROLL),"",(SUMPRODUCT(AC5:AC10,Z5:Z10,AB5:AB10)/AD11-SUMPRODUCT(AC5:AC10,Z5:Z10)/AD11*SUMPRODUCT(AC5:AC10,AB5:AB10)/AD11)*AD11/(AD11-1)) | AF11: =SUM(AA5:AA10) | AG11: =IF(OR($A11="",AF11<MIN_OBS_ROLL),"",SUMPRODUCT(AA5:AA10,(AB5:AB10-SUMPRODUCT(AA5:AA10,AB5:AB10)/AF11)^2)/(AF11-1)) | AH11: =SUM(Y5:Y10) | AI11: =IF(OR($A11="",AH11<MIN_OBS_ROLL),"",SUMPRODUCT(Y5:Y10,Z5:Z10)/AH11) | AJ11: =IF(OR($A11="",AF11<MIN_OBS_ROLL),"",SUMPRODUCT(AA5:AA10,AB5:AB10)/AF11) | AK11: =IF(OR(AE11="",AG11=""),"",AE11/AG11) | AL11: =IF(OR(AI11="",AK11="",AJ11=""),"",AI11-AK11*AJ11) | AM11: =IF(AND(ISNUMBER(W11),ISNUMBER(X11),ISNUMBER(AK11),ISNUMBER(AL11)),W11-(AL11+AK11*X11),"") | AN11: =IF(ISNUMBER(AM11),1,0) | AO11: =IF(AN11=1,AM11,0) | AP11: =IF(SUM(AN9:AN11)=3,SUM(AO9:AO11),"") | AQ11: =IF(ISNUMBER(AP11),1,0) | AR11: =IF(AQ11=1,AP11,0) | AS11: =SUM(AQ$5:AQ11) | AT11: =IF(AS11>=MIN_OBS_Z,SUMPRODUCT(AQ$5:AQ11,AR$5:AR11)/AS11,"") | AU11: =IF(AS11>=MIN_OBS_Z,SQRT(SUMPRODUCT(AQ$5:AQ11,(AR$5:AR11-AT11)^2)/(AS11-1)),"") | AV11: =IF(AND(AQ11=1,ISNUMBER(AT11)),MAX(-Z_CLIP,MIN(Z_CLIP,(AR11-AT11)/AU11)),"") | AW11: =IF(ISNUMBER(AV11),-AV11,"") | AX11: =IF(ISNUMBER(AW11),1+AMPLITUD*TANH(AW11),"") | AY11: =IF($A11="","",IF(COUNT(AX9:AX11)>0,AVERAGE(AX9:AX11),"")) | AZ11: =IF(ISNUMBER(AY11),AY11-1,"") | BA11: =IF(AND(ISNUMBER(AZ10),ISNUMBER(W11)),AZ10*W_BANCOS*W11,"") | BB11: =IF(AND(ISNUMBER(AZ10),ISNUMBER(AZ9)),ABS(AZ10-AZ9)*W_BANCOS*COSTO,0) | BC11: =IF(ISNUMBER(BA11),BA11-BB11,"") | BD11: =IF(ISNUMBER(BC11),IF(A11<=FECHA_ERA,"A","B"),"") | BE11: =IF(BD11="A",BC11,"") | BF11: =IF(BD11="B",BC11,"") | BG11: =IF(AND(ISNUMBER(BC11),ISNUMBER(A11)),IF(A11>=INICIO_VIVO,1,0),0) | BH11: =IF(BG11=1,BC11,"") | BI11: =IF(ISNUMBER(AY11),ROW(),0) | BJ11: =IF(ISNUMBER(BC11),SUM(BC$5:BC11)*10000,NA()) | BK11: =IF(BG11=1,SUM(BH$5:BH11)*10000,NA()) | BL11: =IF(ISNUMBER(AY11),AY11,NA())
A12: =IF(Datos!A12="","",Datos!A12) | B12: =IF(OR($A12="",NOT(ISNUMBER(Datos!B12)),NOT(ISNUMBER(Datos!B11))),"",Datos!B12/Datos!B11-1) | C12: =IF(OR($A12="",NOT(ISNUMBER(Datos!C12)),NOT(ISNUMBER(Datos!C11))),"",Datos!C12/Datos!C11-1) | D12: =IF(OR($A12="",NOT(ISNUMBER(Datos!D12)),NOT(ISNUMBER(Datos!D11))),"",Datos!D12/Datos!D11-1) | E12: =IF(OR($A12="",NOT(ISNUMBER(Datos!E12)),NOT(ISNUMBER(Datos!E11))),"",Datos!E12/Datos!E11-1) | F12: =IF($A12="","",COUNT(B12:E12)) | G12: =IF($A12="","",IF(F12>=MIN_BANCOS,AVERAGE(B12:E12),"")) | H12: =IF(OR($A12="",NOT(ISNUMBER(Datos!F12)),NOT(ISNUMBER(Datos!F11))),"",Datos!F12/Datos!F11-1) | I12: =IF($A12="","",IF(ISNUMBER(Datos!G12),Datos!G12,I11)) | J12: =IF($A12="","",IF(ISNUMBER(I11),LN(1+I11/100/12),0)) | K12: =IF(ISNUMBER(G12),LN(1+G12)-J12,"") | L12: =IF(ISNUMBER(H12),LN(1+H12)-J12,"") | M12: =IF(ISNUMBER(K12),1,0) | N12: =IF(M12=1,K12,0) | O12: =IF(ISNUMBER(L12),1,0) | P12: =IF(O12=1,L12,0) | Q12: =M12*O12 | R12: =SUM(Q5:Q11) | S12: =IF(OR($A12="",R12<MIN_OBS_ROLL),"",(SUMPRODUCT(Q5:Q11,N5:N11,P5:P11)/R12-SUMPRODUCT(Q5:Q11,N5:N11)/R12*SUMPRODUCT(Q5:Q11,P5:P11)/R12)*R12/(R12-1)) | T12: =SUM(O5:O11) | U12: =IF(OR($A12="",T12<MIN_OBS_ROLL),"",SUMPRODUCT(O5:O11,(P5:P11-SUMPRODUCT(O5:O11,P5:P11)/T12)^2)/(T12-1)) | V12: =IF(OR(S12="",U12=""),"",S12/U12) | W12: =IF(AND(ISNUMBER(K12),ISNUMBER(L12),ISNUMBER(V12)),K12-V12*L12,"") | X12: =IF(OR($A12="",NOT(ISNUMBER(Datos!H12)),NOT(ISNUMBER(Datos!H11))),"",LN(Datos!H12)-LN(Datos!H11)) | Y12: =IF(ISNUMBER(W12),1,0) | Z12: =IF(Y12=1,W12,0) | AA12: =IF(ISNUMBER(X12),1,0) | AB12: =IF(AA12=1,X12,0) | AC12: =Y12*AA12 | AD12: =SUM(AC5:AC11) | AE12: =IF(OR($A12="",AD12<MIN_OBS_ROLL),"",(SUMPRODUCT(AC5:AC11,Z5:Z11,AB5:AB11)/AD12-SUMPRODUCT(AC5:AC11,Z5:Z11)/AD12*SUMPRODUCT(AC5:AC11,AB5:AB11)/AD12)*AD12/(AD12-1)) | AF12: =SUM(AA5:AA11) | AG12: =IF(OR($A12="",AF12<MIN_OBS_ROLL),"",SUMPRODUCT(AA5:AA11,(AB5:AB11-SUMPRODUCT(AA5:AA11,AB5:AB11)/AF12)^2)/(AF12-1)) | AH12: =SUM(Y5:Y11) | AI12: =IF(OR($A12="",AH12<MIN_OBS_ROLL),"",SUMPRODUCT(Y5:Y11,Z5:Z11)/AH12) | AJ12: =IF(OR($A12="",AF12<MIN_OBS_ROLL),"",SUMPRODUCT(AA5:AA11,AB5:AB11)/AF12) | AK12: =IF(OR(AE12="",AG12=""),"",AE12/AG12) | AL12: =IF(OR(AI12="",AK12="",AJ12=""),"",AI12-AK12*AJ12) | AM12: =IF(AND(ISNUMBER(W12),ISNUMBER(X12),ISNUMBER(AK12),ISNUMBER(AL12)),W12-(AL12+AK12*X12),"") | AN12: =IF(ISNUMBER(AM12),1,0) | AO12: =IF(AN12=1,AM12,0) | AP12: =IF(SUM(AN10:AN12)=3,SUM(AO10:AO12),"") | AQ12: =IF(ISNUMBER(AP12),1,0) | AR12: =IF(AQ12=1,AP12,0) | AS12: =SUM(AQ$5:AQ12) | AT12: =IF(AS12>=MIN_OBS_Z,SUMPRODUCT(AQ$5:AQ12,AR$5:AR12)/AS12,"") | AU12: =IF(AS12>=MIN_OBS_Z,SQRT(SUMPRODUCT(AQ$5:AQ12,(AR$5:AR12-AT12)^2)/(AS12-1)),"") | AV12: =IF(AND(AQ12=1,ISNUMBER(AT12)),MAX(-Z_CLIP,MIN(Z_CLIP,(AR12-AT12)/AU12)),"") | AW12: =IF(ISNUMBER(AV12),-AV12,"") | AX12: =IF(ISNUMBER(AW12),1+AMPLITUD*TANH(AW12),"") | AY12: =IF($A12="","",IF(COUNT(AX10:AX12)>0,AVERAGE(AX10:AX12),"")) | AZ12: =IF(ISNUMBER(AY12),AY12-1,"") | BA12: =IF(AND(ISNUMBER(AZ11),ISNUMBER(W12)),AZ11*W_BANCOS*W12,"") | BB12: =IF(AND(ISNUMBER(AZ11),ISNUMBER(AZ10)),ABS(AZ11-AZ10)*W_BANCOS*COSTO,0) | BC12: =IF(ISNUMBER(BA12),BA12-BB12,"") | BD12: =IF(ISNUMBER(BC12),IF(A12<=FECHA_ERA,"A","B"),"") | BE12: =IF(BD12="A",BC12,"") | BF12: =IF(BD12="B",BC12,"") | BG12: =IF(AND(ISNUMBER(BC12),ISNUMBER(A12)),IF(A12>=INICIO_VIVO,1,0),0) | BH12: =IF(BG12=1,BC12,"") | BI12: =IF(ISNUMBER(AY12),ROW(),0) | BJ12: =IF(ISNUMBER(BC12),SUM(BC$5:BC12)*10000,NA()) | BK12: =IF(BG12=1,SUM(BH$5:BH12)*10000,NA()) | BL12: =IF(ISNUMBER(AY12),AY12,NA())
A13: =IF(Datos!A13="","",Datos!A13) | B13: =IF(OR($A13="",NOT(ISNUMBER(Datos!B13)),NOT(ISNUMBER(Datos!B12))),"",Datos!B13/Datos!B12-1) | C13: =IF(OR($A13="",NOT(ISNUMBER(Datos!C13)),NOT(ISNUMBER(Datos!C12))),"",Datos!C13/Datos!C12-1) | D13: =IF(OR($A13="",NOT(ISNUMBER(Datos!D13)),NOT(ISNUMBER(Datos!D12))),"",Datos!D13/Datos!D12-1) | E13: =IF(OR($A13="",NOT(ISNUMBER(Datos!E13)),NOT(ISNUMBER(Datos!E12))),"",Datos!E13/Datos!E12-1) | F13: =IF($A13="","",COUNT(B13:E13)) | G13: =IF($A13="","",IF(F13>=MIN_BANCOS,AVERAGE(B13:E13),"")) | H13: =IF(OR($A13="",NOT(ISNUMBER(Datos!F13)),NOT(ISNUMBER(Datos!F12))),"",Datos!F13/Datos!F12-1) | I13: =IF($A13="","",IF(ISNUMBER(Datos!G13),Datos!G13,I12)) | J13: =IF($A13="","",IF(ISNUMBER(I12),LN(1+I12/100/12),0)) | K13: =IF(ISNUMBER(G13),LN(1+G13)-J13,"") | L13: =IF(ISNUMBER(H13),LN(1+H13)-J13,"") | M13: =IF(ISNUMBER(K13),1,0) | N13: =IF(M13=1,K13,0) | O13: =IF(ISNUMBER(L13),1,0) | P13: =IF(O13=1,L13,0) | Q13: =M13*O13 | R13: =SUM(Q5:Q12) | S13: =IF(OR($A13="",R13<MIN_OBS_ROLL),"",(SUMPRODUCT(Q5:Q12,N5:N12,P5:P12)/R13-SUMPRODUCT(Q5:Q12,N5:N12)/R13*SUMPRODUCT(Q5:Q12,P5:P12)/R13)*R13/(R13-1)) | T13: =SUM(O5:O12) | U13: =IF(OR($A13="",T13<MIN_OBS_ROLL),"",SUMPRODUCT(O5:O12,(P5:P12-SUMPRODUCT(O5:O12,P5:P12)/T13)^2)/(T13-1)) | V13: =IF(OR(S13="",U13=""),"",S13/U13) | W13: =IF(AND(ISNUMBER(K13),ISNUMBER(L13),ISNUMBER(V13)),K13-V13*L13,"") | X13: =IF(OR($A13="",NOT(ISNUMBER(Datos!H13)),NOT(ISNUMBER(Datos!H12))),"",LN(Datos!H13)-LN(Datos!H12)) | Y13: =IF(ISNUMBER(W13),1,0) | Z13: =IF(Y13=1,W13,0) | AA13: =IF(ISNUMBER(X13),1,0) | AB13: =IF(AA13=1,X13,0) | AC13: =Y13*AA13 | AD13: =SUM(AC5:AC12) | AE13: =IF(OR($A13="",AD13<MIN_OBS_ROLL),"",(SUMPRODUCT(AC5:AC12,Z5:Z12,AB5:AB12)/AD13-SUMPRODUCT(AC5:AC12,Z5:Z12)/AD13*SUMPRODUCT(AC5:AC12,AB5:AB12)/AD13)*AD13/(AD13-1)) | AF13: =SUM(AA5:AA12) | AG13: =IF(OR($A13="",AF13<MIN_OBS_ROLL),"",SUMPRODUCT(AA5:AA12,(AB5:AB12-SUMPRODUCT(AA5:AA12,AB5:AB12)/AF13)^2)/(AF13-1)) | AH13: =SUM(Y5:Y12) | AI13: =IF(OR($A13="",AH13<MIN_OBS_ROLL),"",SUMPRODUCT(Y5:Y12,Z5:Z12)/AH13) | AJ13: =IF(OR($A13="",AF13<MIN_OBS_ROLL),"",SUMPRODUCT(AA5:AA12,AB5:AB12)/AF13) | AK13: =IF(OR(AE13="",AG13=""),"",AE13/AG13) | AL13: =IF(OR(AI13="",AK13="",AJ13=""),"",AI13-AK13*AJ13) | AM13: =IF(AND(ISNUMBER(W13),ISNUMBER(X13),ISNUMBER(AK13),ISNUMBER(AL13)),W13-(AL13+AK13*X13),"") | AN13: =IF(ISNUMBER(AM13),1,0) | AO13: =IF(AN13=1,AM13,0) | AP13: =IF(SUM(AN11:AN13)=3,SUM(AO11:AO13),"") | AQ13: =IF(ISNUMBER(AP13),1,0) | AR13: =IF(AQ13=1,AP13,0) | AS13: =SUM(AQ$5:AQ13) | AT13: =IF(AS13>=MIN_OBS_Z,SUMPRODUCT(AQ$5:AQ13,AR$5:AR13)/AS13,"") | AU13: =IF(AS13>=MIN_OBS_Z,SQRT(SUMPRODUCT(AQ$5:AQ13,(AR$5:AR13-AT13)^2)/(AS13-1)),"") | AV13: =IF(AND(AQ13=1,ISNUMBER(AT13)),MAX(-Z_CLIP,MIN(Z_CLIP,(AR13-AT13)/AU13)),"") | AW13: =IF(ISNUMBER(AV13),-AV13,"") | AX13: =IF(ISNUMBER(AW13),1+AMPLITUD*TANH(AW13),"") | AY13: =IF($A13="","",IF(COUNT(AX11:AX13)>0,AVERAGE(AX11:AX13),"")) | AZ13: =IF(ISNUMBER(AY13),AY13-1,"") | BA13: =IF(AND(ISNUMBER(AZ12),ISNUMBER(W13)),AZ12*W_BANCOS*W13,"") | BB13: =IF(AND(ISNUMBER(AZ12),ISNUMBER(AZ11)),ABS(AZ12-AZ11)*W_BANCOS*COSTO,0) | BC13: =IF(ISNUMBER(BA13),BA13-BB13,"") | BD13: =IF(ISNUMBER(BC13),IF(A13<=FECHA_ERA,"A","B"),"") | BE13: =IF(BD13="A",BC13,"") | BF13: =IF(BD13="B",BC13,"") | BG13: =IF(AND(ISNUMBER(BC13),ISNUMBER(A13)),IF(A13>=INICIO_VIVO,1,0),0) | BH13: =IF(BG13=1,BC13,"") | BI13: =IF(ISNUMBER(AY13),ROW(),0) | BJ13: =IF(ISNUMBER(BC13),SUM(BC$5:BC13)*10000,NA()) | BK13: =IF(BG13=1,SUM(BH$5:BH13)*10000,NA()) | BL13: =IF(ISNUMBER(AY13),AY13,NA())
A14: =IF(Datos!A14="","",Datos!A14) | B14: =IF(OR($A14="",NOT(ISNUMBER(Datos!B14)),NOT(ISNUMBER(Datos!B13))),"",Datos!B14/Datos!B13-1) | C14: =IF(OR($A14="",NOT(ISNUMBER(Datos!C14)),NOT(ISNUMBER(Datos!C13))),"",Datos!C14/Datos!C13-1) | D14: =IF(OR($A14="",NOT(ISNUMBER(Datos!D14)),NOT(ISNUMBER(Datos!D13))),"",Datos!D14/Datos!D13-1) | E14: =IF(OR($A14="",NOT(ISNUMBER(Datos!E14)),NOT(ISNUMBER(Datos!E13))),"",Datos!E14/Datos!E13-1) | F14: =IF($A14="","",COUNT(B14:E14)) | G14: =IF($A14="","",IF(F14>=MIN_BANCOS,AVERAGE(B14:E14),"")) | H14: =IF(OR($A14="",NOT(ISNUMBER(Datos!F14)),NOT(ISNUMBER(Datos!F13))),"",Datos!F14/Datos!F13-1) | I14: =IF($A14="","",IF(ISNUMBER(Datos!G14),Datos!G14,I13)) | J14: =IF($A14="","",IF(ISNUMBER(I13),LN(1+I13/100/12),0)) | K14: =IF(ISNUMBER(G14),LN(1+G14)-J14,"") | L14: =IF(ISNUMBER(H14),LN(1+H14)-J14,"") | M14: =IF(ISNUMBER(K14),1,0) | N14: =IF(M14=1,K14,0) | O14: =IF(ISNUMBER(L14),1,0) | P14: =IF(O14=1,L14,0) | Q14: =M14*O14 | R14: =SUM(Q5:Q13) | S14: =IF(OR($A14="",R14<MIN_OBS_ROLL),"",(SUMPRODUCT(Q5:Q13,N5:N13,P5:P13)/R14-SUMPRODUCT(Q5:Q13,N5:N13)/R14*SUMPRODUCT(Q5:Q13,P5:P13)/R14)*R14/(R14-1)) | T14: =SUM(O5:O13) | U14: =IF(OR($A14="",T14<MIN_OBS_ROLL),"",SUMPRODUCT(O5:O13,(P5:P13-SUMPRODUCT(O5:O13,P5:P13)/T14)^2)/(T14-1)) | V14: =IF(OR(S14="",U14=""),"",S14/U14) | W14: =IF(AND(ISNUMBER(K14),ISNUMBER(L14),ISNUMBER(V14)),K14-V14*L14,"") | X14: =IF(OR($A14="",NOT(ISNUMBER(Datos!H14)),NOT(ISNUMBER(Datos!H13))),"",LN(Datos!H14)-LN(Datos!H13)) | Y14: =IF(ISNUMBER(W14),1,0) | Z14: =IF(Y14=1,W14,0) | AA14: =IF(ISNUMBER(X14),1,0) | AB14: =IF(AA14=1,X14,0) | AC14: =Y14*AA14 | AD14: =SUM(AC5:AC13) | AE14: =IF(OR($A14="",AD14<MIN_OBS_ROLL),"",(SUMPRODUCT(AC5:AC13,Z5:Z13,AB5:AB13)/AD14-SUMPRODUCT(AC5:AC13,Z5:Z13)/AD14*SUMPRODUCT(AC5:AC13,AB5:AB13)/AD14)*AD14/(AD14-1)) | AF14: =SUM(AA5:AA13) | AG14: =IF(OR($A14="",AF14<MIN_OBS_ROLL),"",SUMPRODUCT(AA5:AA13,(AB5:AB13-SUMPRODUCT(AA5:AA13,AB5:AB13)/AF14)^2)/(AF14-1)) | AH14: =SUM(Y5:Y13) | AI14: =IF(OR($A14="",AH14<MIN_OBS_ROLL),"",SUMPRODUCT(Y5:Y13,Z5:Z13)/AH14) | AJ14: =IF(OR($A14="",AF14<MIN_OBS_ROLL),"",SUMPRODUCT(AA5:AA13,AB5:AB13)/AF14) | AK14: =IF(OR(AE14="",AG14=""),"",AE14/AG14) | AL14: =IF(OR(AI14="",AK14="",AJ14=""),"",AI14-AK14*AJ14) | AM14: =IF(AND(ISNUMBER(W14),ISNUMBER(X14),ISNUMBER(AK14),ISNUMBER(AL14)),W14-(AL14+AK14*X14),"") | AN14: =IF(ISNUMBER(AM14),1,0) | AO14: =IF(AN14=1,AM14,0) | AP14: =IF(SUM(AN12:AN14)=3,SUM(AO12:AO14),"") | AQ14: =IF(ISNUMBER(AP14),1,0) | AR14: =IF(AQ14=1,AP14,0) | AS14: =SUM(AQ$5:AQ14) | AT14: =IF(AS14>=MIN_OBS_Z,SUMPRODUCT(AQ$5:AQ14,AR$5:AR14)/AS14,"") | AU14: =IF(AS14>=MIN_OBS_Z,SQRT(SUMPRODUCT(AQ$5:AQ14,(AR$5:AR14-AT14)^2)/(AS14-1)),"") | AV14: =IF(AND(AQ14=1,ISNUMBER(AT14)),MAX(-Z_CLIP,MIN(Z_CLIP,(AR14-AT14)/AU14)),"") | AW14: =IF(ISNUMBER(AV14),-AV14,"") | AX14: =IF(ISNUMBER(AW14),1+AMPLITUD*TANH(AW14),"") | AY14: =IF($A14="","",IF(COUNT(AX12:AX14)>0,AVERAGE(AX12:AX14),"")) | AZ14: =IF(ISNUMBER(AY14),AY14-1,"") | BA14: =IF(AND(ISNUMBER(AZ13),ISNUMBER(W14)),AZ13*W_BANCOS*W14,"") | BB14: =IF(AND(ISNUMBER(AZ13),ISNUMBER(AZ12)),ABS(AZ13-AZ12)*W_BANCOS*COSTO,0) | BC14: =IF(ISNUMBER(BA14),BA14-BB14,"") | BD14: =IF(ISNUMBER(BC14),IF(A14<=FECHA_ERA,"A","B"),"") | BE14: =IF(BD14="A",BC14,"") | BF14: =IF(BD14="B",BC14,"") | BG14: =IF(AND(ISNUMBER(BC14),ISNUMBER(A14)),IF(A14>=INICIO_VIVO,1,0),0) | BH14: =IF(BG14=1,BC14,"") | BI14: =IF(ISNUMBER(AY14),ROW(),0) | BJ14: =IF(ISNUMBER(BC14),SUM(BC$5:BC14)*10000,NA()) | BK14: =IF(BG14=1,SUM(BH$5:BH14)*10000,NA()) | BL14: =IF(ISNUMBER(AY14),AY14,NA())
A15: =IF(Datos!A15="","",Datos!A15) | B15: =IF(OR($A15="",NOT(ISNUMBER(Datos!B15)),NOT(ISNUMBER(Datos!B14))),"",Datos!B15/Datos!B14-1) | C15: =IF(OR($A15="",NOT(ISNUMBER(Datos!C15)),NOT(ISNUMBER(Datos!C14))),"",Datos!C15/Datos!C14-1) | D15: =IF(OR($A15="",NOT(ISNUMBER(Datos!D15)),NOT(ISNUMBER(Datos!D14))),"",Datos!D15/Datos!D14-1) | E15: =IF(OR($A15="",NOT(ISNUMBER(Datos!E15)),NOT(ISNUMBER(Datos!E14))),"",Datos!E15/Datos!E14-1) | F15: =IF($A15="","",COUNT(B15:E15)) | G15: =IF($A15="","",IF(F15>=MIN_BANCOS,AVERAGE(B15:E15),"")) | H15: =IF(OR($A15="",NOT(ISNUMBER(Datos!F15)),NOT(ISNUMBER(Datos!F14))),"",Datos!F15/Datos!F14-1) | I15: =IF($A15="","",IF(ISNUMBER(Datos!G15),Datos!G15,I14)) | J15: =IF($A15="","",IF(ISNUMBER(I14),LN(1+I14/100/12),0)) | K15: =IF(ISNUMBER(G15),LN(1+G15)-J15,"") | L15: =IF(ISNUMBER(H15),LN(1+H15)-J15,"") | M15: =IF(ISNUMBER(K15),1,0) | N15: =IF(M15=1,K15,0) | O15: =IF(ISNUMBER(L15),1,0) | P15: =IF(O15=1,L15,0) | Q15: =M15*O15 | R15: =SUM(Q5:Q14) | S15: =IF(OR($A15="",R15<MIN_OBS_ROLL),"",(SUMPRODUCT(Q5:Q14,N5:N14,P5:P14)/R15-SUMPRODUCT(Q5:Q14,N5:N14)/R15*SUMPRODUCT(Q5:Q14,P5:P14)/R15)*R15/(R15-1)) | T15: =SUM(O5:O14) | U15: =IF(OR($A15="",T15<MIN_OBS_ROLL),"",SUMPRODUCT(O5:O14,(P5:P14-SUMPRODUCT(O5:O14,P5:P14)/T15)^2)/(T15-1)) | V15: =IF(OR(S15="",U15=""),"",S15/U15) | W15: =IF(AND(ISNUMBER(K15),ISNUMBER(L15),ISNUMBER(V15)),K15-V15*L15,"") | X15: =IF(OR($A15="",NOT(ISNUMBER(Datos!H15)),NOT(ISNUMBER(Datos!H14))),"",LN(Datos!H15)-LN(Datos!H14)) | Y15: =IF(ISNUMBER(W15),1,0) | Z15: =IF(Y15=1,W15,0) | AA15: =IF(ISNUMBER(X15),1,0) | AB15: =IF(AA15=1,X15,0) | AC15: =Y15*AA15 | AD15: =SUM(AC5:AC14) | AE15: =IF(OR($A15="",AD15<MIN_OBS_ROLL),"",(SUMPRODUCT(AC5:AC14,Z5:Z14,AB5:AB14)/AD15-SUMPRODUCT(AC5:AC14,Z5:Z14)/AD15*SUMPRODUCT(AC5:AC14,AB5:AB14)/AD15)*AD15/(AD15-1)) | AF15: =SUM(AA5:AA14) | AG15: =IF(OR($A15="",AF15<MIN_OBS_ROLL),"",SUMPRODUCT(AA5:AA14,(AB5:AB14-SUMPRODUCT(AA5:AA14,AB5:AB14)/AF15)^2)/(AF15-1)) | AH15: =SUM(Y5:Y14) | AI15: =IF(OR($A15="",AH15<MIN_OBS_ROLL),"",SUMPRODUCT(Y5:Y14,Z5:Z14)/AH15) | AJ15: =IF(OR($A15="",AF15<MIN_OBS_ROLL),"",SUMPRODUCT(AA5:AA14,AB5:AB14)/AF15) | AK15: =IF(OR(AE15="",AG15=""),"",AE15/AG15) | AL15: =IF(OR(AI15="",AK15="",AJ15=""),"",AI15-AK15*AJ15) | AM15: =IF(AND(ISNUMBER(W15),ISNUMBER(X15),ISNUMBER(AK15),ISNUMBER(AL15)),W15-(AL15+AK15*X15),"") | AN15: =IF(ISNUMBER(AM15),1,0) | AO15: =IF(AN15=1,AM15,0) | AP15: =IF(SUM(AN13:AN15)=3,SUM(AO13:AO15),"") | AQ15: =IF(ISNUMBER(AP15),1,0) | AR15: =IF(AQ15=1,AP15,0) | AS15: =SUM(AQ$5:AQ15) | AT15: =IF(AS15>=MIN_OBS_Z,SUMPRODUCT(AQ$5:AQ15,AR$5:AR15)/AS15,"") | AU15: =IF(AS15>=MIN_OBS_Z,SQRT(SUMPRODUCT(AQ$5:AQ15,(AR$5:AR15-AT15)^2)/(AS15-1)),"") | AV15: =IF(AND(AQ15=1,ISNUMBER(AT15)),MAX(-Z_CLIP,MIN(Z_CLIP,(AR15-AT15)/AU15)),"") | AW15: =IF(ISNUMBER(AV15),-AV15,"") | AX15: =IF(ISNUMBER(AW15),1+AMPLITUD*TANH(AW15),"") | AY15: =IF($A15="","",IF(COUNT(AX13:AX15)>0,AVERAGE(AX13:AX15),"")) | AZ15: =IF(ISNUMBER(AY15),AY15-1,"") | BA15: =IF(AND(ISNUMBER(AZ14),ISNUMBER(W15)),AZ14*W_BANCOS*W15,"") | BB15: =IF(AND(ISNUMBER(AZ14),ISNUMBER(AZ13)),ABS(AZ14-AZ13)*W_BANCOS*COSTO,0) | BC15: =IF(ISNUMBER(BA15),BA15-BB15,"") | BD15: =IF(ISNUMBER(BC15),IF(A15<=FECHA_ERA,"A","B"),"") | BE15: =IF(BD15="A",BC15,"") | BF15: =IF(BD15="B",BC15,"") | BG15: =IF(AND(ISNUMBER(BC15),ISNUMBER(A15)),IF(A15>=INICIO_VIVO,1,0),0) | BH15: =IF(BG15=1,BC15,"") | BI15: =IF(ISNUMBER(AY15),ROW(),0) | BJ15: =IF(ISNUMBER(BC15),SUM(BC$5:BC15)*10000,NA()) | BK15: =IF(BG15=1,SUM(BH$5:BH15)*10000,NA()) | BL15: =IF(ISNUMBER(AY15),AY15,NA())
A16: =IF(Datos!A16="","",Datos!A16) | B16: =IF(OR($A16="",NOT(ISNUMBER(Datos!B16)),NOT(ISNUMBER(Datos!B15))),"",Datos!B16/Datos!B15-1) | C16: =IF(OR($A16="",NOT(ISNUMBER(Datos!C16)),NOT(ISNUMBER(Datos!C15))),"",Datos!C16/Datos!C15-1) | D16: =IF(OR($A16="",NOT(ISNUMBER(Datos!D16)),NOT(ISNUMBER(Datos!D15))),"",Datos!D16/Datos!D15-1) | E16: =IF(OR($A16="",NOT(ISNUMBER(Datos!E16)),NOT(ISNUMBER(Datos!E15))),"",Datos!E16/Datos!E15-1) | F16: =IF($A16="","",COUNT(B16:E16)) | G16: =IF($A16="","",IF(F16>=MIN_BANCOS,AVERAGE(B16:E16),"")) | H16: =IF(OR($A16="",NOT(ISNUMBER(Datos!F16)),NOT(ISNUMBER(Datos!F15))),"",Datos!F16/Datos!F15-1) | I16: =IF($A16="","",IF(ISNUMBER(Datos!G16),Datos!G16,I15)) | J16: =IF($A16="","",IF(ISNUMBER(I15),LN(1+I15/100/12),0)) | K16: =IF(ISNUMBER(G16),LN(1+G16)-J16,"") | L16: =IF(ISNUMBER(H16),LN(1+H16)-J16,"") | M16: =IF(ISNUMBER(K16),1,0) | N16: =IF(M16=1,K16,0) | O16: =IF(ISNUMBER(L16),1,0) | P16: =IF(O16=1,L16,0) | Q16: =M16*O16 | R16: =SUM(Q5:Q15) | S16: =IF(OR($A16="",R16<MIN_OBS_ROLL),"",(SUMPRODUCT(Q5:Q15,N5:N15,P5:P15)/R16-SUMPRODUCT(Q5:Q15,N5:N15)/R16*SUMPRODUCT(Q5:Q15,P5:P15)/R16)*R16/(R16-1)) | T16: =SUM(O5:O15) | U16: =IF(OR($A16="",T16<MIN_OBS_ROLL),"",SUMPRODUCT(O5:O15,(P5:P15-SUMPRODUCT(O5:O15,P5:P15)/T16)^2)/(T16-1)) | V16: =IF(OR(S16="",U16=""),"",S16/U16) | W16: =IF(AND(ISNUMBER(K16),ISNUMBER(L16),ISNUMBER(V16)),K16-V16*L16,"") | X16: =IF(OR($A16="",NOT(ISNUMBER(Datos!H16)),NOT(ISNUMBER(Datos!H15))),"",LN(Datos!H16)-LN(Datos!H15)) | Y16: =IF(ISNUMBER(W16),1,0) | Z16: =IF(Y16=1,W16,0) | AA16: =IF(ISNUMBER(X16),1,0) | AB16: =IF(AA16=1,X16,0) | AC16: =Y16*AA16 | AD16: =SUM(AC5:AC15) | AE16: =IF(OR($A16="",AD16<MIN_OBS_ROLL),"",(SUMPRODUCT(AC5:AC15,Z5:Z15,AB5:AB15)/AD16-SUMPRODUCT(AC5:AC15,Z5:Z15)/AD16*SUMPRODUCT(AC5:AC15,AB5:AB15)/AD16)*AD16/(AD16-1)) | AF16: =SUM(AA5:AA15) | AG16: =IF(OR($A16="",AF16<MIN_OBS_ROLL),"",SUMPRODUCT(AA5:AA15,(AB5:AB15-SUMPRODUCT(AA5:AA15,AB5:AB15)/AF16)^2)/(AF16-1)) | AH16: =SUM(Y5:Y15) | AI16: =IF(OR($A16="",AH16<MIN_OBS_ROLL),"",SUMPRODUCT(Y5:Y15,Z5:Z15)/AH16) | AJ16: =IF(OR($A16="",AF16<MIN_OBS_ROLL),"",SUMPRODUCT(AA5:AA15,AB5:AB15)/AF16) | AK16: =IF(OR(AE16="",AG16=""),"",AE16/AG16) | AL16: =IF(OR(AI16="",AK16="",AJ16=""),"",AI16-AK16*AJ16) | AM16: =IF(AND(ISNUMBER(W16),ISNUMBER(X16),ISNUMBER(AK16),ISNUMBER(AL16)),W16-(AL16+AK16*X16),"") | AN16: =IF(ISNUMBER(AM16),1,0) | AO16: =IF(AN16=1,AM16,0) | AP16: =IF(SUM(AN14:AN16)=3,SUM(AO14:AO16),"") | AQ16: =IF(ISNUMBER(AP16),1,0) | AR16: =IF(AQ16=1,AP16,0) | AS16: =SUM(AQ$5:AQ16) | AT16: =IF(AS16>=MIN_OBS_Z,SUMPRODUCT(AQ$5:AQ16,AR$5:AR16)/AS16,"") | AU16: =IF(AS16>=MIN_OBS_Z,SQRT(SUMPRODUCT(AQ$5:AQ16,(AR$5:AR16-AT16)^2)/(AS16-1)),"") | AV16: =IF(AND(AQ16=1,ISNUMBER(AT16)),MAX(-Z_CLIP,MIN(Z_CLIP,(AR16-AT16)/AU16)),"") | AW16: =IF(ISNUMBER(AV16),-AV16,"") | AX16: =IF(ISNUMBER(AW16),1+AMPLITUD*TANH(AW16),"") | AY16: =IF($A16="","",IF(COUNT(AX14:AX16)>0,AVERAGE(AX14:AX16),"")) | AZ16: =IF(ISNUMBER(AY16),AY16-1,"") | BA16: =IF(AND(ISNUMBER(AZ15),ISNUMBER(W16)),AZ15*W_BANCOS*W16,"") | BB16: =IF(AND(ISNUMBER(AZ15),ISNUMBER(AZ14)),ABS(AZ15-AZ14)*W_BANCOS*COSTO,0) | BC16: =IF(ISNUMBER(BA16),BA16-BB16,"") | BD16: =IF(ISNUMBER(BC16),IF(A16<=FECHA_ERA,"A","B"),"") | BE16: =IF(BD16="A",BC16,"") | BF16: =IF(BD16="B",BC16,"") | BG16: =IF(AND(ISNUMBER(BC16),ISNUMBER(A16)),IF(A16>=INICIO_VIVO,1,0),0) | BH16: =IF(BG16=1,BC16,"") | BI16: =IF(ISNUMBER(AY16),ROW(),0) | BJ16: =IF(ISNUMBER(BC16),SUM(BC$5:BC16)*10000,NA()) | BK16: =IF(BG16=1,SUM(BH$5:BH16)*10000,NA()) | BL16: =IF(ISNUMBER(AY16),AY16,NA())
